Workbook

Sheet Sheet1

Sheet Table
M2: Total Fields
B3: @EndUserText.label : 'GSTR2A Payment Block Data.'
B4: @AbapCatalog.enhancement.category : #EXTENSIBLE_ANY | M4: mandt
B5: @AbapCatalog.tableCategory : #TRANSPARENT | M5: custom1
B6: @AbapCatalog.deliveryClass : #A | M6: custom4
B7: @AbapCatalog.dataMaintenance : #RESTRICTED | M7: custom9
B8: define table zcy_t_2a_pay_blk { | M8: returnperiod
M9: locationgstin
B10: key mandt : mandt not null; | M10: documentnumber
B11: key custom1 : zcy_det_custom1 not null; | M11: documentdate
B12: key custom4 : zcy_det_custom4 not null; | M12: financialyear
B13: key custom9 : zcy_det_custom9 not null; | M13: fi_doc_value
B14: returnperiod : zcy_det_returnperiod; | M14: fi_tax_value
B15: locationgstin : zcy_det_locationgstin; | M15: fi_tax_code
B16: documentnumber : zcy_det_documentnumber; | M16: fi_tax_rate
B17: documentdate : bldat; | M17: status
B18: financialyear : zcy_det_financialyear; | M18: gst_part
B19: INCLUDE : ZCY_STR_2A_PAY_BLOCK_STATUS; | M19: vendor
B20: } | M20: mindk
M21: vendor_block_type
M22: payment_due_date
M23: clearing_no
M24: clearing_date
B25: @EndUserText.label : 'Status fields for GSTR2A based payment block program' | M25: expected_filing_date
B26: @AbapCatalog.enhancement.category : #EXTENSIBLE_ANY | M26: due_date_before_filing
B27: define structure zcy_str_2a_pay_block_status { | M27: cleared_before_filing
M28: grc_check_applicable
B29: @Semantics.amount.currencyCode : 'vbak.waerk' | M29: grc_checked_on
B30: fi_doc_value : dmbtr; | M30: grc_checked_at
B31: @Semantics.amount.currencyCode : 'vbak.waerk' | M31: grc_checked_by
B32: fi_tax_value : hwste; | M32: grc_score
B33: fi_tax_code : mwskz; | M33: gstr3b_score
B34: @Semantics.amount.currencyCode : 'vbak.waerk' | M34: grc_check_result
B35: fi_tax_rate : kbetr; | M35: grc_check_comment
B36: status : zcy_det_2a_pay_block_status; | M36: blocked_on
B37: gst_part : j_1ig_partner; | M37: blocked_at
B38: vendor : lifnr; | M38: blocked_by
B39: mindk : mindk; | M39: block_comment
B40: vendor_block_type : zcy_det_block_type; | M40: split_comp_code
... B106: last_checked_on : zcy_det_lc_date; | M106: remark
...

Sheet ZI_2A_PAY_BLOCK
C3: ZI_2A_PAY_BLOCK
C4: 2A Payment Block Interface
C6: @EndUserText.label: '2A Payment Block' | M6: custom1 | N6: =MATCH(M6,Table!$M$4:$M$135,0) -> 2
C7: @AccessControl.authorizationCheck: #NOT_REQUIRED | M7: custom4 | N7: =MATCH(M7,Table!$M$4:$M$135,0) -> 3
C8: define root view entity ZI_2A_PAY_BLOCK | M8: custom9 | N8: =MATCH(M8,Table!$M$4:$M$135,0) -> 4
C9: as select from zcy_t_2a_pay_blk | M9: returnperiod | N9: =MATCH(M9,Table!$M$4:$M$135,0) -> 5
C10: { | M10: locationgstin | N10: =MATCH(M10,Table!$M$4:$M$135,0) -> 6
C11: key custom1, | M11: documentnumber | N11: =MATCH(M11,Table!$M$4:$M$135,0) -> 7
C12: key custom4, | M12: documentdate | N12: =MATCH(M12,Table!$M$4:$M$135,0) -> 8
C13: key custom9, | M13: financialyear | N13: =MATCH(M13,Table!$M$4:$M$135,0) -> 9
M14: fi_doc_value | N14: =MATCH(M14,Table!$M$4:$M$135,0) -> 10
C15: returnperiod, | M15: fi_tax_value | N15: =MATCH(M15,Table!$M$4:$M$135,0) -> 11
C16: locationgstin, | M16: fi_tax_code | N16: =MATCH(M16,Table!$M$4:$M$135,0) -> 12
C17: documentnumber, | M17: fi_tax_rate | N17: =MATCH(M17,Table!$M$4:$M$135,0) -> 13
C18: documentdate, | M18: status | N18: =MATCH(M18,Table!$M$4:$M$135,0) -> 14
C19: financialyear, | M19: gst_part | N19: =MATCH(M19,Table!$M$4:$M$135,0) -> 15
M20: vendor | N20: =MATCH(M20,Table!$M$4:$M$135,0) -> 16
C21: fi_doc_value, | M21: mindk | N21: =MATCH(M21,Table!$M$4:$M$135,0) -> 17
C22: fi_tax_value, | M22: vendor_block_type | N22: =MATCH(M22,Table!$M$4:$M$135,0) -> 18
C23: fi_tax_code, | M23: payment_due_date | N23: =MATCH(M23,Table!$M$4:$M$135,0) -> 19
C24: fi_tax_rate, | M24: clearing_no | N24: =MATCH(M24,Table!$M$4:$M$135,0) -> 20
M25: clearing_date | N25: =MATCH(M25,Table!$M$4:$M$135,0) -> 21
C26: status, | M26: expected_filing_date | N26: =MATCH(M26,Table!$M$4:$M$135,0) -> 22
C27: gst_part, | M27: due_date_before_filing | N27: =MATCH(M27,Table!$M$4:$M$135,0) -> 23
C28: vendor, | M28: cleared_before_filing | N28: =MATCH(M28,Table!$M$4:$M$135,0) -> 24
C29: mindk, | M29: grc_check_applicable | N29: =MATCH(M29,Table!$M$4:$M$135,0) -> 25
C30: vendor_block_type, | M30: grc_checked_on | N30: =MATCH(M30,Table!$M$4:$M$135,0) -> 26
C31: payment_due_date, | M31: grc_checked_at | N31: =MATCH(M31,Table!$M$4:$M$135,0) -> 27
C32: clearing_no, | M32: grc_checked_by | N32: =MATCH(M32,Table!$M$4:$M$135,0) -> 28
C33: clearing_date, | M33: grc_score | N33: =MATCH(M33,Table!$M$4:$M$135,0) -> 29
C34: expected_filing_date, | M34: gstr3b_score | N34: =MATCH(M34,Table!$M$4:$M$135,0) -> 30
C35: due_date_before_filing, | M35: grc_check_result | N35: =MATCH(M35,Table!$M$4:$M$135,0) -> 31
C36: cleared_before_filing, | M36: grc_check_comment | N36: =MATCH(M36,Table!$M$4:$M$135,0) -> 32
M37: blocked_on | N37: =MATCH(M37,Table!$M$4:$M$135,0) -> 33
C38: grc_check_applicable, | M38: blocked_at | N38: =MATCH(M38,Table!$M$4:$M$135,0) -> 34
C39: grc_checked_on, | M39: blocked_by | N39: =MATCH(M39,Table!$M$4:$M$135,0) -> 35
C40: grc_checked_at, | M40: block_comment | N40: =MATCH(M40,Table!$M$4:$M$135,0) -> 36
C41: grc_checked_by, | M41: split_comp_code | N41: =MATCH(M41,Table!$M$4:$M$135,0) -> 37
C42: grc_score, | M42: split_gst_doc_num | N42: =MATCH(M42,Table!$M$4:$M$135,0) -> 38
C43: gstr3b_score, | M43: split_year | N43: =MATCH(M43,Table!$M$4:$M$135,0) -> 39
...
