Workbook

Sheet ls_data beforeProcess
E5: d
E6: CUSTOM9 | F6: 1000 | G6: =INDEX('ls_data afterProcess'!$F$7:$F$361,MATCH(E6,'ls_data afterProcess'!$E$7:$E$361,0)) -> 1000
E7: CUSTOM1 | F7: 5325000001 | G7: =INDEX('ls_data afterProcess'!$F$7:$F$361,MATCH(E7,'ls_data afterProcess'!$E$7:$E$361,0)) -> 5325000001
E8: CUSTOM4 | F8: 2026 | G8: =INDEX('ls_data afterProcess'!$F$7:$F$361,MATCH(E8,'ls_data afterProcess'!$E$7:$E$361,0)) -> 2026
E9: MTACCDOC2_BUKRS | G9: =INDEX('ls_data afterProcess'!$F$7:$F$361,MATCH(E9,'ls_data afterProcess'!$E$7:$E$361,0)) -> 0
E10: MTACCDOC2_BELNR | G10: =INDEX('ls_data afterProcess'!$F$7:$F$361,MATCH(E10,'ls_data afterProcess'!$E$7:$E$361,0)) -> 0
E11: MTACCDOC2_GJAHR | F11: 0 | G11: =INDEX('ls_data afterProcess'!$F$7:$F$361,MATCH(E11,'ls_data afterProcess'!$E$7:$E$361,0)) -> 0
E12: MTACCDOC3_BUKRS | G12: =INDEX('ls_data afterProcess'!$F$7:$F$361,MATCH(E12,'ls_data afterProcess'!$E$7:$E$361,0)) -> 0
E13: MTACCDOC3_BELNR | G13: =INDEX('ls_data afterProcess'!$F$7:$F$361,MATCH(E13,'ls_data afterProcess'!$E$7:$E$361,0)) -> 0
E14: MTACCDOC3_GJAHR | F14: 0 | G14: =INDEX('ls_data afterProcess'!$F$7:$F$361,MATCH(E14,'ls_data afterProcess'!$E$7:$E$361,0)) -> 0
E15: MTACCDOC4_BUKRS | G15: =INDEX('ls_data afterProcess'!$F$7:$F$361,MATCH(E15,'ls_data afterProcess'!$E$7:$E$361,0)) -> 0
E16: MTACCDOC4_BELNR | G16: =INDEX('ls_data afterProcess'!$F$7:$F$361,MATCH(E16,'ls_data afterProcess'!$E$7:$E$361,0)) -> 0
E17: MTACCDOC4_GJAHR | F17: 0 | G17: =INDEX('ls_data afterProcess'!$F$7:$F$361,MATCH(E17,'ls_data afterProcess'!$E$7:$E$361,0)) -> 0
E18: MTACCDOC5_BUKRS | G18: =INDEX('ls_data afterProcess'!$F$7:$F$361,MATCH(E18,'ls_data afterProcess'!$E$7:$E$361,0)) -> 0
E19: MTACCDOC5_BELNR | G19: =INDEX('ls_data afterProcess'!$F$7:$F$361,MATCH(E19,'ls_data afterProcess'!$E$7:$E$361,0)) -> 0
E20: MTACCDOC5_GJAHR | F20: 0 | G20: =INDEX('ls_data afterProcess'!$F$7:$F$361,MATCH(E20,'ls_data afterProcess'!$E$7:$E$361,0)) -> 0
E21: MTACCDOC6_BUKRS | G21: =INDEX('ls_data afterProcess'!$F$7:$F$361,MATCH(E21,'ls_data afterProcess'!$E$7:$E$361,0)) -> 0
E22: MTACCDOC6_BELNR | G22: =INDEX('ls_data afterProcess'!$F$7:$F$361,MATCH(E22,'ls_data afterProcess'!$E$7:$E$361,0)) -> 0
E23: MTACCDOC6_GJAHR | F23: 0 | G23: =INDEX('ls_data afterProcess'!$F$7:$F$361,MATCH(E23,'ls_data afterProcess'!$E$7:$E$361,0)) -> 0
E24: RETURNPERIOD | F24: 42025 | G24: =INDEX('ls_data afterProcess'!$F$7:$F$361,MATCH(E24,'ls_data afterProcess'!$E$7:$E$361,0)) -> 42025
E25: LOCATIONGSTIN | F25: 22AADCJ6739M1Z9 | G25: =INDEX('ls_data afterProcess'!$F$7:$F$361,MATCH(E25,'ls_data afterProcess'!$E$7:$E$361,0)) -> 22AADCJ6739M1Z9
E26: DOCUMENTNUMBER | F26: CPPL/24-25/4464 | G26: =INDEX('ls_data afterProcess'!$F$7:$F$361,MATCH(E26,'ls_data afterProcess'!$E$7:$E$361,0)) -> CPPL/24-25/4464
E27: SERIALNUMBER | G27: =INDEX('ls_data afterProcess'!$F$7:$F$361,MATCH(E27,'ls_data afterProcess'!$E$7:$E$361,0)) -> 0
E28: DOCUMENTDATE | F28: 20250107 | G28: =INDEX('ls_data afterProcess'!$F$7:$F$361,MATCH(E28,'ls_data afterProcess'!$E$7:$E$361,0)) -> 20250107
E29: BILLFROMGSTIN | F29: 22AAJCC5288Q1Z0 | G29: =INDEX('ls_data afterProcess'!$F$7:$F$361,MATCH(E29,'ls_data afterProcess'!$E$7:$E$361,0)) -> 22AAJCC5288Q1Z0
E30: FINANCIALYEAR | G30: =INDEX('ls_data afterProcess'!$F$7:$F$361,MATCH(E30,'ls_data afterProcess'!$E$7:$E$361,0)) -> 0
E31: MAPPERID | G31: =INDEX('ls_data afterProcess'!$F$7:$F$361,MATCH(E31,'ls_data afterProcess'!$E$7:$E$361,0)) -> 0
E32: SUPPLYTYPE | F32: P | G32: =INDEX('ls_data afterProcess'!$F$7:$F$361,MATCH(E32,'ls_data afterProcess'!$E$7:$E$361,0)) -> P
E33: PURPOSE | F33: OGST | G33: =INDEX('ls_data afterProcess'!$F$7:$F$361,MATCH(E33,'ls_data afterProcess'!$E$7:$E$361,0)) -> OGST
E34: LOCATIONNAME | F34: JSWPAINTSCHATTISGARH | G34: =INDEX('ls_data afterProcess'!$F$7:$F$361,MATCH(E34,'ls_data afterProcess'!$E$7:$E$361,0)) -> JSWPAINTSCHATTISGARH
E35: IRN | G35: =INDEX('ls_data afterProcess'!$F$7:$F$361,MATCH(E35,'ls_data afterProcess'!$E$7:$E$361,0)) -> 0
E36: LIABILITYDISCHARGERETURNPERIOD | G36: =INDEX('ls_data afterProcess'!$F$7:$F$361,MATCH(E36,'ls_data afterProcess'!$E$7:$E$361,0)) -> 0
E37: ITCCLAIMRETURNPERIOD | G37: =INDEX('ls_data afterProcess'!$F$7:$F$361,MATCH(E37,'ls_data afterProcess'!$E$7:$E$361,0)) -> 0
E38: DOCUMENTTYPE | F38: INV | G38: =INDEX('ls_data afterProcess'!$F$7:$F$361,MATCH(E38,'ls_data afterProcess'!$E$7:$E$361,0)) -> INV
E39: TRANSACTIONTYPE | F39: B2B | G39: =INDEX('ls_data afterProcess'!$F$7:$F$361,MATCH(E39,'ls_data afterProcess'!$E$7:$E$361,0)) -> B2B
E40: TAXPAYERTYPE | G40: =INDEX('ls_data afterProcess'!$F$7:$F$361,MATCH(E40,'ls_data afterProcess'!$E$7:$E$361,0)) -> 0
E41: TRANSACTIONNATURE | G41: =INDEX('ls_data afterProcess'!$F$7:$F$361,MATCH(E41,'ls_data afterProcess'!$E$7:$E$361,0)) -> 0
E42: DOCUMENTSERIESCODE | G42: =INDEX('ls_data afterProcess'!$F$7:$F$361,MATCH(E42,'ls_data afterProcess'!$E$7:$E$361,0)) -> 0
E43: BILLFROMLEGALNAME | G43: =INDEX('ls_data afterProcess'!$F$7:$F$361,MATCH(E43,'ls_data afterProcess'!$E$7:$E$361,0)) -> 0
E44: BILLFROMTRADENAME | G44: =INDEX('ls_data afterProcess'!$F$7:$F$361,MATCH(E44,'ls_data afterProcess'!$E$7:$E$361,0)) -> 0
...

Sheet ls_data afterProcess
E7: CUSTOM9 | F7: 1000 | G7: \TYPE=%_T00004S00000645O0000043936 | H7: C | I7: 4
E8: CUSTOM1 | F8: 5325000001 | G8: \TYPE=%_T00004S00000645O0000043984 | H8: C | I8: 10
E9: CUSTOM4 | F9: 2026 | G9: \TYPE=%_T00004S00000645O0000044032 | H9: C | I9: 4
E10: MTACCDOC2_BUKRS | G10: ZCY_DET_SPLIT_COMP | H10: C | I10: 4
E11: MTACCDOC2_BELNR | G11: ZCY_DET_SPLIT_GST_DOC | H11: C | I11: 10
E12: MTACCDOC2_GJAHR | F12: 0 | G12: ZCY_DET_SPLIT_YEAR | H12: N | I12: 4
E13: MTACCDOC3_BUKRS | G13: ZCY_DET_JV_COMP | H13: C | I13: 4
E14: MTACCDOC3_BELNR | G14: ZCY_DET_JV_DOC | H14: C | I14: 10
E15: MTACCDOC3_GJAHR | F15: 0 | G15: ZCY_DET_JV_YEAR | H15: N | I15: 4
E16: MTACCDOC4_BUKRS | G16: ZCY_DET_JV_REV_COMP | H16: C | I16: 4
E17: MTACCDOC4_BELNR | G17: ZCY_DET_JV_REV_DOC | H17: C | I17: 10
E18: MTACCDOC4_GJAHR | F18: 0 | G18: ZCY_DET_JV_REV_YEAR | H18: N | I18: 4
E19: MTACCDOC5_BUKRS | G19: ZCY_DET_DN_COMP | H19: C | I19: 4
E20: MTACCDOC5_BELNR | G20: ZCY_DET_DN_NUM | H20: C | I20: 10
E21: MTACCDOC5_GJAHR | F21: 0 | G21: ZCY_DET_DN_YEAR | H21: N | I21: 4
E22: MTACCDOC6_BUKRS | G22: ZCY_DET_DN_REV_COMP | H22: C | I22: 4
E23: MTACCDOC6_BELNR | G23: ZCY_DET_DN_REV_NUM | H23: C | I23: 10
E24: MTACCDOC6_GJAHR | F24: 0 | G24: ZCY_DET_DN_REV_YEAR | H24: N | I24: 4
E25: RETURNPERIOD | F25: 42025 | G25: ZCY_DET_RETURNPERIOD | H25: C | I25: 6
E26: LOCATIONGSTIN | F26: 22AADCJ6739M1Z9 | G26: ZCY_DET_LOCATIONGSTIN | H26: C | I26: 15
E27: DOCUMENTNUMBER | F27: CPPL/24-25/4464 | G27: ZCY_DET_DOCUMENTNUMBER | H27: C | I27: 16
E28: SERIALNUMBER | G28: ZCY_DET_SERIALNUMBER | H28: C | I28: 20
E29: DOCUMENTDATE | F29: 20250107 | G29: BLDAT | H29: D | I29: 8
E30: BILLFROMGSTIN | F30: 22AAJCC5288Q1Z0 | G30: ZCY_DET_BILLFROMGSTIN | H30: C | I30: 15
E31: FINANCIALYEAR | G31: ZCY_DET_FINANCIALYEAR | H31: C | I31: 6
E32: MAPPERID | G32: ZCY_DET_MAPPERID | H32: C | I32: 40
E33: SUPPLYTYPE | F33: P | G33: ZCY_DET_SUPPLYTYPE | H33: C | I33: 1
E34: PURPOSE | F34: OGST | G34: ZCY_DET_PURPOSE | H34: C | I34: 13
E35: LOCATIONNAME | F35: JSWPAINTSCHATTISGARH | G35: ZCY_DET_LOCATIONNAME | H35: C | I35: 40
E36: IRN | G36: ZCY_DET_IRN | H36: C | I36: 70
E37: LIABILITYDISCHARGERETURNPERIOD | G37: ZCY_DET_LIABILITYDISCHARGERETU | H37: C | I37: 6
E38: ITCCLAIMRETURNPERIOD | G38: ZCY_DET_ITCCLAIMRETURNPERIOD | H38: C | I38: 6
E39: DOCUMENTTYPE | F39: INV | G39: ZCY_DET_DOCUMENTTYPE | H39: C | I39: 3
E40: TRANSACTIONTYPE | F40: B2B | G40: ZCY_DET_TRANSACTIONTYPE | H40: C | I40: 6
E41: TAXPAYERTYPE | G41: ZCY_DET_TAXPAYERTYPE | H41: C | I41: 4
E42: TRANSACTIONNATURE | G42: ZCY_DET_TRANSACTIONNATURE | H42: C | I42: 3
E43: DOCUMENTSERIESCODE | G43: ZCY_DET_DOCUMENTSERIESCODE | H43: C | I43: 10
E44: BILLFROMLEGALNAME | G44: ZCY_DET_BILLFROMLEGALNAME | H44: C | I44: 40
E45: BILLFROMTRADENAME | G45: ZCY_DET_BILLFROMTRADENAME | H45: C | I45: 40
E46: BILLFROMVENDORCODE | G46: ZCY_DET_BILLFROMVENDORCODE | H46: C | I46: 40
...

Sheet Sheet2
D2: s
C3: 1 | D3: STATUS | F3: =INDEX('ls_data afterProcess'!$F$7:$F$361,MATCH(D3,'ls_data afterProcess'!$E$7:$E$361,0)) -> M
C4: 2 | D4: VENDORBLOCKTYPE | E4: S | F4: =INDEX('ls_data afterProcess'!$F$7:$F$361,MATCH(D4,'ls_data afterProcess'!$E$7:$E$361,0)) -> S
C5: 3 | D5: RECONCILIATIONSECTION | E5: PRONLY | F5: =INDEX('ls_data afterProcess'!$F$7:$F$361,MATCH(D5,'ls_data afterProcess'!$E$7:$E$361,0)) -> PRONLY
C6: 4 | D6: DUEDATEBEFOREFILING | F6: =INDEX('ls_data afterProcess'!$F$7:$F$361,MATCH(D6,'ls_data afterProcess'!$E$7:$E$361,0)) -> 0
C7: 5 | D7: CLEARINGDATE | E7: 0 | F7: =INDEX('ls_data afterProcess'!$F$7:$F$361,MATCH(D7,'ls_data afterProcess'!$E$7:$E$361,0)) -> 0 | H7: require data in | J7: ZCY_T_2A_RECSTAT
C8: 6 | D8: EXPECTEDFILINGDATE | E8: 0 | F8: =INDEX('ls_data afterProcess'!$F$7:$F$361,MATCH(D8,'ls_data afterProcess'!$E$7:$E$361,0)) -> 0 | H8: check data | J8: v_usr_name
C9: 7 | D9: P_PBF | E9: X | F9: =INDEX('ls_data afterProcess'!$F$7:$F$361,MATCH(D9,'ls_data afterProcess'!$E$7:$E$361,0)) -> X
C10: 8 | D10: QBLOCK | F10: =INDEX('ls_data afterProcess'!$F$7:$F$361,MATCH(D10,'ls_data afterProcess'!$E$7:$E$361,0)) -> 0
C11: 9 | D11: MINDK | E11: 1 | F11: =INDEX('ls_data afterProcess'!$F$7:$F$361,MATCH(D11,'ls_data afterProcess'!$E$7:$E$361,0)) -> 1
D12: DEBITNOTEPOSTEDON | E12: 0 | F12: =INDEX('ls_data afterProcess'!$F$7:$F$361,MATCH(D12,'ls_data afterProcess'!$E$7:$E$361,0)) -> 0
D13: DEBITNOTEPOSTEDAT | E13: 0 | F13: =INDEX('ls_data afterProcess'!$F$7:$F$361,MATCH(D13,'ls_data afterProcess'!$E$7:$E$361,0)) -> 0
D14: DEBITNOTEPOSTEDBY | F14: =INDEX('ls_data afterProcess'!$F$7:$F$361,MATCH(D14,'ls_data afterProcess'!$E$7:$E$361,0)) -> 0
D15: CUSTOM9 | E15: 1000 | F15: =INDEX('ls_data afterProcess'!$F$7:$F$361,MATCH(D15,'ls_data afterProcess'!$E$7:$E$361,0)) -> 1000
D16: CUSTOM1 | E16: 5325000001 | F16: =INDEX('ls_data afterProcess'!$F$7:$F$361,MATCH(D16,'ls_data afterProcess'!$E$7:$E$361,0)) -> 5325000001
D17: CUSTOM4 | E17: 2026 | F17: =INDEX('ls_data afterProcess'!$F$7:$F$361,MATCH(D17,'ls_data afterProcess'!$E$7:$E$361,0)) -> 2026
D18: RETURNPERIOD | E18: 42025 | F18: =INDEX('ls_data afterProcess'!$F$7:$F$361,MATCH(D18,'ls_data afterProcess'!$E$7:$E$361,0)) -> 42025
D19: LOCATIONGSTIN | E19: 22AADCJ6739M1Z9 | F19: =INDEX('ls_data afterProcess'!$F$7:$F$361,MATCH(D19,'ls_data afterProcess'!$E$7:$E$361,0)) -> 22AADCJ6739M1Z9
D20: DOCUMENTNUMBER | E20: CPPL/24-25/4464 | F20: =INDEX('ls_data afterProcess'!$F$7:$F$361,MATCH(D20,'ls_data afterProcess'!$E$7:$E$361,0)) -> CPPL/24-25/4464
D21: DOCUMENTDATE | E21: 20250107 | F21: =INDEX('ls_data afterProcess'!$F$7:$F$361,MATCH(D21,'ls_data afterProcess'!$E$7:$E$361,0)) -> 20250107
D22: BILLFROMGSTIN | E22: 22AAJCC5288Q1Z0 | F22: =INDEX('ls_data afterProcess'!$F$7:$F$361,MATCH(D22,'ls_data afterProcess'!$E$7:$E$361,0)) -> 22AAJCC5288Q1Z0
D23: SUPPLYTYPE | E23: P | F23: =INDEX('ls_data afterProcess'!$F$7:$F$361,MATCH(D23,'ls_data afterProcess'!$E$7:$E$361,0)) -> P
D24: PURPOSE | E24: OGST | F24: =INDEX('ls_data afterProcess'!$F$7:$F$361,MATCH(D24,'ls_data afterProcess'!$E$7:$E$361,0)) -> OGST
D25: LOCATIONNAME | E25: JSWPAINTSCHATTISGARH | F25: =INDEX('ls_data afterProcess'!$F$7:$F$361,MATCH(D25,'ls_data afterProcess'!$E$7:$E$361,0)) -> JSWPAINTSCHATTISGARH
D26: DOCUMENTTYPE | E26: INV | F26: =INDEX('ls_data afterProcess'!$F$7:$F$361,MATCH(D26,'ls_data afterProcess'!$E$7:$E$361,0)) -> INV
D27: TRANSACTIONTYPE | E27: B2B | F27: =INDEX('ls_data afterProcess'!$F$7:$F$361,MATCH(D27,'ls_data afterProcess'!$E$7:$E$361,0)) -> B2B
D28: BILLTOGSTIN | E28: 22AADCJ6739M1Z9 | F28: =INDEX('ls_data afterProcess'!$F$7:$F$361,MATCH(D28,'ls_data afterProcess'!$E$7:$E$361,0)) -> 22AADCJ6739M1Z9
D29: BILLTOLEGALNAME | E29: CHEMPLAST PRODUCTS PRIVATE LIMITED | F29: =INDEX('ls_data afterProcess'!$F$7:$F$361,MATCH(D29,'ls_data afterProcess'!$E$7:$E$361,0)) -> CHEMPLAST PRODUCTS PRIVATE LIMITED
D30: BILLTOTRADENAME | E30: CHEMPLAST PRODUCTS PRIVATE LIMITED | F30: =INDEX('ls_data afterProcess'!$F$7:$F$361,MATCH(D30,'ls_data afterProcess'!$E$7:$E$361,0)) -> CHEMPLAST PRODUCTS PRIVATE LIMITED
D31: POS | E31: 22 | F31: =INDEX('ls_data afterProcess'!$F$7:$F$361,MATCH(D31,'ls_data afterProcess'!$E$7:$E$361,0)) -> 22
D32: DOCUMENTVALUE | E32: 102053.96 | F32: =INDEX('ls_data afterProcess'!$F$7:$F$361,MATCH(D32,'ls_data afterProcess'!$E$7:$E$361,0)) -> 102053.96
D33: REVERSECHARGE | E33: N | F33: =INDEX('ls_data afterProcess'!$F$7:$F$361,MATCH(D33,'ls_data afterProcess'!$E$7:$E$361,0)) -> N
D34: CUSTOM2 | E34: 20250406 | F34: =INDEX('ls_data afterProcess'!$F$7:$F$361,MATCH(D34,'ls_data afterProcess'!$E$7:$E$361,0)) -> 20250406
D35: CUSTOM3 | E35: 5095255 | F35: =INDEX('ls_data afterProcess'!$F$7:$F$361,MATCH(D35,'ls_data afterProcess'!$E$7:$E$361,0)) -> 5095255
D36: CUSTOM5 | E36: 10047474 | F36: =INDEX('ls_data afterProcess'!$F$7:$F$361,MATCH(D36,'ls_data afterProcess'!$E$7:$E$361,0)) -> 10047474
D37: CUSTOM6 | E37: 2242 | F37: =INDEX('ls_data afterProcess'!$F$7:$F$361,MATCH(D37,'ls_data afterProcess'!$E$7:$E$361,0)) -> 2242
D38: CUSTOM7 | E38: RE | F38: =INDEX('ls_data afterProcess'!$F$7:$F$361,MATCH(D38,'ls_data afterProcess'!$E$7:$E$361,0)) -> RE
D39: CUSTOM8 | E39: PTCPPO1X25A000091 | F39: =INDEX('ls_data afterProcess'!$F$7:$F$361,MATCH(D39,'ls_data afterProcess'!$E$7:$E$361,0)) -> PTCPPO1X25A000091
D40: PUSHSTATUS | E40: ACT | F40: =INDEX('ls_data afterProcess'!$F$7:$F$361,MATCH(D40,'ls_data afterProcess'!$E$7:$E$361,0)) -> ACT
D41: GSTACTION | E41: N | F41: =INDEX('ls_data afterProcess'!$F$7:$F$361,MATCH(D41,'ls_data afterProcess'!$E$7:$E$361,0)) -> N
...

Sheet Analysing Lines
N5: Outcom From Process
D6: => | E6: METHOD process. | N6: 1 | O6: cs_data-status = mcs_doc_status-debit_note_posted.
N7: 2 | O7: ev_date = cs_data-debitnotepostedon | T7: ev_date = sy-datlo.
E8: => | F8: process_unprocessed( | N8: 3 | O8: ev_time = cs_data-debitnotepostedat | T8: ev_time = sy-timlo.
F9: CHANGING | N9: 4 | O9: ev_user = DATA(lv_debit) | T9: SELECT SINGLE name_text
F10: cs_data = cs_data | T10: FROM v_usr_name
F11: ). | T11: WHERE bname = @sy-uname
T12: INTO @DATA(lv_name).
F13: => | G13: process_daf(
G14: CHANGING | T14: ev_user = COND string(
G15: cs_data = cs_data | T15: WHEN lv_name IS NOT INITIAL
G16: ). | T16: THEN |{ sy-uname } - { lv_name }|
T17: ELSE sy-uname
G18: => | H18: process_daf_open( | T18: ).
H19: CHANGING
H20: cs_data = cs_data
H21: ).
H23: => | I23: DATA(lv_blocked) = block_open_document(
I24: CHANGING
I25: cs_data = cs_data
I26: ).
I29: => | J29: WHEN mcs_vendor_block_type-split.
J31: post_debit_note(
J32: CHANGING
J33: cs_data = cs_data
J34: RECEIVING
J35: rv_posted = DATA(lv_dn_posted)
J36: ).
J38: IF lv_dn_posted = abap_true.
J40: cs_data-status = mcs_doc_status-debit_note_posted.
J42: get_log(
J43: IMPORTING
J44: ev_date = cs_data-debitnotepostedon
J45: ev_time = cs_data-debitnotepostedat
... J50: cs_data-message = 'Document processed successfully'.
J52: => | K52: METHOD get_log.
K54: ev_date = sy-datlo.
K55: ev_time = sy-timlo.
K57: SELECT SINGLE name_text
K58: FROM v_usr_name
...

Sheet ToDos
E4: DATA(ls_data) = CORRESPONDING zpb_i_2a_pay_block( <data> ).
E6: lo_processor->process(
E7: CHANGING
E8: cs_data = ls_data ).
E10: " MODIFY ENTITIES ...
E11: ENDLOOP.
E14: 1 | F14: Need to add lines before modifying
I16: <data>-status = ls_data-status.
I17: <data>-message = ls_data-message.
I18: <data>-releasecomment = ls_data-releasecomment.
I19: <data>-releasedon = ls_data-releasedon.
I20: <data>-releasedat = ls_data-releasedat.
I21: <data>-releasedby = ls_data-releasedby.
I23: <data>-jvrevcompcode = ls_data-jvrevcompcode.
I24: <data>-jvrevdocnum = ls_data-jvrevdocnum.
I25: <data>-jvrevyear = ls_data-jvrevyear.
I26: <data>-jvrevcomment = ls_data-jvrevcomment.
I27: <data>-jvreversedon = ls_data-jvreversedon.
I28: <data>-jvreversedat = ls_data-jvreversedat.
... I31: <data>-splityear = ls_data-splityear.
