Workbook

Sheet ZJS_TEST_INTERFACE_DATA
A2: d | B2: d | C2: Object | D2: Type | E2: Category | F2: Github Object | G2: Github Type | H2: Version
A4: D | B4: OK | C4: =LEFT(F4,FIND(".",F4)-1) -> 53cdfaffcabea4b42116c2d6119be2ht | D4: {=INDEX('Not Req'!$E$4:$E$71,MATCH(MID(F4,FIND(".",F4)+1,LEN(F4)-FIND(".",F4)+1),'Not Req'!$D$4:$D$71,0))} -> Authorization Defaults (TADIR) | E4: =INDEX('Not Req'!$F$4:$F$71,MATCH(MID(F4,FIND(".",F4)+1,LEN(F4)-FIND(".",F4)+1),'Not Req'!$D$4:$D$71,0)) -> 1. Authorizations | F4: 53cdfaffcabea4b42116c2d6119be2ht.sush.xml | G4: UPDATED ON 02-FEB-26 | H4: 3 months ago
A5: D | B5: OK | C5: =LEFT(F5,FIND(".",F5)-1) -> f648cfa16bf0425c8346aa270e7d64ht | D5: {=INDEX('Not Req'!$E$4:$E$71,MATCH(MID(F5,FIND(".",F5)+1,LEN(F5)-FIND(".",F5)+1),'Not Req'!$D$4:$D$71,0))} -> Authorization Defaults (TADIR) | E5: =INDEX('Not Req'!$F$4:$F$71,MATCH(MID(F5,FIND(".",F5)+1,LEN(F5)-FIND(".",F5)+1),'Not Req'!$D$4:$D$71,0)) -> 1. Authorizations | F5: f648cfa16bf0425c8346aa270e7d64ht.sush.xml | G5: UPDATED ON 02-FEB-26 | H5: 3 months ago
A6: D | B6: OK | C6: =LEFT(F6,FIND(".",F6)-1) -> zjs_api_company_names_o2 | D6: {=INDEX('Not Req'!$E$4:$E$71,MATCH(MID(F6,FIND(".",F6)+1,LEN(F6)-FIND(".",F6)+1),'Not Req'!$D$4:$D$71,0))} -> Service Binding | E6: =INDEX('Not Req'!$F$4:$F$71,MATCH(MID(F6,FIND(".",F6)+1,LEN(F6)-FIND(".",F6)+1),'Not Req'!$D$4:$D$71,0)) -> 2. Business Services | F6: zjs_api_company_names_o2.srvb.xml | G6: UPDATED ON 02-FEB-26 | H6: 3 months ago
A7: D | B7: OK | C7: =LEFT(F7,FIND(".",F7)-1) -> zjs_api_company_names_o2_iwsg | D7: {=INDEX('Not Req'!$E$4:$E$71,MATCH(MID(F7,FIND(".",F7)+1,LEN(F7)-FIND(".",F7)+1),'Not Req'!$D$4:$D$71,0))} -> Inbound Service | E7: =INDEX('Not Req'!$F$4:$F$71,MATCH(MID(F7,FIND(".",F7)+1,LEN(F7)-FIND(".",F7)+1),'Not Req'!$D$4:$D$71,0)) -> 3. Cloud Communication Management | F7: zjs_api_company_names_o2_iwsg.sco2.xml | G7: UPDATED ON 02-FEB-26 | H7: 3 months ago
A8: D | B8: OK | C8: =LEFT(F8,FIND(".",F8)-1) -> zjs_c_dmocname | D8: {=INDEX('Not Req'!$E$4:$E$71,MATCH(MID(F8,FIND(".",F8)+1,LEN(F8)-FIND(".",F8)+1),'Not Req'!$D$4:$D$71,0))} -> BDEF | E8: =INDEX('Not Req'!$F$4:$F$71,MATCH(MID(F8,FIND(".",F8)+1,LEN(F8)-FIND(".",F8)+1),'Not Req'!$D$4:$D$71,0)) -> 4. CDS | F8: zjs_c_dmocname.bdef.asbdef | G8: UPDATED ON 02-FEB-26 | H8: 3 months ago
A9: D | B9: OK | C9: =LEFT(F9,FIND(".",F9)-1) -> zjs_i_dmocname | D9: {=INDEX('Not Req'!$E$4:$E$71,MATCH(MID(F9,FIND(".",F9)+1,LEN(F9)-FIND(".",F9)+1),'Not Req'!$D$4:$D$71,0))} -> BDEF | E9: =INDEX('Not Req'!$F$4:$F$71,MATCH(MID(F9,FIND(".",F9)+1,LEN(F9)-FIND(".",F9)+1),'Not Req'!$D$4:$D$71,0)) -> 4. CDS | F9: zjs_i_dmocname.bdef.asbdef | G9: UPDATED ON 02-FEB-26 | H9: 3 months ago
A10: D | B10: OK | C10: =LEFT(F10,FIND(".",F10)-1) -> zjs_c_dmocname | D10: {=INDEX('Not Req'!$E$4:$E$71,MATCH(MID(F10,FIND(".",F10)+1,LEN(F10)-FIND(".",F10)+1),'Not Req'!$D$4:$D$71,0))} -> Data Definition | E10: =INDEX('Not Req'!$F$4:$F$71,MATCH(MID(F10,FIND(".",F10)+1,LEN(F10)-FIND(".",F10)+1),'Not Req'!$D$4:$D$71,0)) -> 4. CDS | F10: zjs_c_dmocname.ddls.asddls | G10: UPDATED ON 02-FEB-26 | H10: 3 months ago
A11: D | B11: OK | C11: =LEFT(F11,FIND(".",F11)-1) -> zjs_i_dmocname | D11: {=INDEX('Not Req'!$E$4:$E$71,MATCH(MID(F11,FIND(".",F11)+1,LEN(F11)-FIND(".",F11)+1),'Not Req'!$D$4:$D$71,0))} -> Data Definition | E11: =INDEX('Not Req'!$F$4:$F$71,MATCH(MID(F11,FIND(".",F11)+1,LEN(F11)-FIND(".",F11)+1),'Not Req'!$D$4:$D$71,0)) -> 4. CDS | F11: zjs_i_dmocname.ddls.asddls | G11: UPDATED ON 02-FEB-26 | H11: 3 months ago
A12: D | B12: OK | C12: =LEFT(F12,FIND(".",F12)-1) -> zjs_dmo_cname | D12: {=INDEX('Not Req'!$E$4:$E$71,MATCH(MID(F12,FIND(".",F12)+1,LEN(F12)-FIND(".",F12)+1),'Not Req'!$D$4:$D$71,0))} -> Table | E12: =INDEX('Not Req'!$F$4:$F$71,MATCH(MID(F12,FIND(".",F12)+1,LEN(F12)-FIND(".",F12)+1),'Not Req'!$D$4:$D$71,0)) -> 5. Dictionary | F12: zjs_dmo_cname.tabl.xml | G12: UPDATED ON 02-FEB-26 | H12: 3 months ago
A13: D | B13: OK | C13: =LEFT(F13,FIND(".",F13)-1) -> zbp_js_demo_company_name | D13: {=INDEX('Not Req'!$E$4:$E$71,MATCH(MID(F13,FIND(".",F13)+1,LEN(F13)-FIND(".",F13)+1),'Not Req'!$D$4:$D$71,0))} -> Classes | E13: =INDEX('Not Req'!$F$4:$F$71,MATCH(MID(F13,FIND(".",F13)+1,LEN(F13)-FIND(".",F13)+1),'Not Req'!$D$4:$D$71,0)) -> 7. Source Code Library | F13: zbp_js_demo_company_name.clas.abap | G13: Updated 16-Mar-26 | H13: 2 months ago
A14: D | B14: OK | C14: =LEFT(F14,FIND(".",F14)-1) -> zcl_js_demo_rebuild_intf_data | D14: {=INDEX('Not Req'!$E$4:$E$71,MATCH(MID(F14,FIND(".",F14)+1,LEN(F14)-FIND(".",F14)+1),'Not Req'!$D$4:$D$71,0))} -> Classes | E14: =INDEX('Not Req'!$F$4:$F$71,MATCH(MID(F14,FIND(".",F14)+1,LEN(F14)-FIND(".",F14)+1),'Not Req'!$D$4:$D$71,0)) -> 7. Source Code Library | F14: zcl_js_demo_rebuild_intf_data.clas.abap | G14: Updated 16-Mar-26 | H14: 2 months ago
A15: D | B15: OK | C15: =LEFT(F15,FIND(".",F15)-1) -> zbp_js_demo_company_name | D15: {=INDEX('Not Req'!$E$4:$E$71,MATCH(MID(F15,FIND(".",F15)+1,LEN(F15)-FIND(".",F15)+1),'Not Req'!$D$4:$D$71,0))} -> Classes Local | E15: =INDEX('Not Req'!$F$4:$F$71,MATCH(MID(F15,FIND(".",F15)+1,LEN(F15)-FIND(".",F15)+1),'Not Req'!$D$4:$D$71,0)) -> 7. Source Code Library | F15: zbp_js_demo_company_name.clas.locals_imp.abap | G15: UPDATED ON 02-FEB-26 | H15: 3 months ago
... A24: D | B24: OK | C24: =LEFT(F24,FIND(".",F24)-1) -> package | D24: {=INDEX('Not Req'!$E$4:$E$71,MATCH(MID(F24,FIND(".",F24)+1,LEN(F24)-FIND(".",F24)+1),'Not Req'!$D$4:$D$71,0))} -> Description : Package | E24: =INDEX('Not Req'!$F$4:$F$71,MATCH(MID(F24,FIND(".",F24)+1,LEN(F24)-FIND(".",F24)+1),'Not Req'!$D$4:$D$71,0)) -> 99. Descriptions | F24: package.devc.xml | G24: UPDATED ON 02-FEB-26 | H24: 3 months ago

Sheet ZJS_DEMO_CDS_TYPE
A2: d | B2: d | C2: Object | D2: Type | E2: Category | F2: Github Object | G2: Github Type | H2: Version
A4: D | B4: OK | C4: =LEFT(F4,FIND(".",F4)-1) -> zjs_c_etypeprojection | D4: {=INDEX('Not Req'!$E$4:$E$71,MATCH(MID(F4,FIND(".",F4)+1,LEN(F4)-FIND(".",F4)+1),'Not Req'!$D$4:$D$71,0))} -> Data Definition | E4: =INDEX('Not Req'!$F$4:$F$71,MATCH(MID(F4,FIND(".",F4)+1,LEN(F4)-FIND(".",F4)+1),'Not Req'!$D$4:$D$71,0)) -> 4. CDS | F4: zjs_c_etypeprojection.ddls.asddls | G4: UPDATED ON 02-FEB-26 | H4: 3 months ago
A5: D | B5: OK | C5: =LEFT(F5,FIND(".",F5)-1) -> zjs_e_etypeexternalentity | D5: {=INDEX('Not Req'!$E$4:$E$71,MATCH(MID(F5,FIND(".",F5)+1,LEN(F5)-FIND(".",F5)+1),'Not Req'!$D$4:$D$71,0))} -> Data Definition | E5: =INDEX('Not Req'!$F$4:$F$71,MATCH(MID(F5,FIND(".",F5)+1,LEN(F5)-FIND(".",F5)+1),'Not Req'!$D$4:$D$71,0)) -> 4. CDS | F5: zjs_e_etypeexternalentity.ddls.asddls | G5: UPDATED ON 02-FEB-26 | H5: 3 months ago
A6: D | B6: OK | C6: =LEFT(F6,FIND(".",F6)-1) -> zjs_f_etypetablefunction | D6: {=INDEX('Not Req'!$E$4:$E$71,MATCH(MID(F6,FIND(".",F6)+1,LEN(F6)-FIND(".",F6)+1),'Not Req'!$D$4:$D$71,0))} -> Data Definition | E6: =INDEX('Not Req'!$F$4:$F$71,MATCH(MID(F6,FIND(".",F6)+1,LEN(F6)-FIND(".",F6)+1),'Not Req'!$D$4:$D$71,0)) -> 4. CDS | F6: zjs_f_etypetablefunction.ddls.asddls | G6: UPDATED ON 02-FEB-26 | H6: 3 months ago
A7: D | B7: OK | C7: =LEFT(F7,FIND(".",F7)-1) -> zjs_i_etypeclassicview | D7: {=INDEX('Not Req'!$E$4:$E$71,MATCH(MID(F7,FIND(".",F7)+1,LEN(F7)-FIND(".",F7)+1),'Not Req'!$D$4:$D$71,0))} -> Data Definition | E7: =INDEX('Not Req'!$F$4:$F$71,MATCH(MID(F7,FIND(".",F7)+1,LEN(F7)-FIND(".",F7)+1),'Not Req'!$D$4:$D$71,0)) -> 4. CDS | F7: zjs_i_etypeclassicview.ddls.asddls | G7: UPDATED ON 02-FEB-26 | H7: 3 months ago
A8: D | B8: OK | C8: =LEFT(F8,FIND(".",F8)-1) -> zjs_i_etypecustomentity | D8: {=INDEX('Not Req'!$E$4:$E$71,MATCH(MID(F8,FIND(".",F8)+1,LEN(F8)-FIND(".",F8)+1),'Not Req'!$D$4:$D$71,0))} -> Data Definition | E8: =INDEX('Not Req'!$F$4:$F$71,MATCH(MID(F8,FIND(".",F8)+1,LEN(F8)-FIND(".",F8)+1),'Not Req'!$D$4:$D$71,0)) -> 4. CDS | F8: zjs_i_etypecustomentity.ddls.asddls | G8: UPDATED ON 02-FEB-26 | H8: 3 months ago
A9: D | B9: OK | C9: =LEFT(F9,FIND(".",F9)-1) -> zjs_i_etypehierarchy | D9: {=INDEX('Not Req'!$E$4:$E$71,MATCH(MID(F9,FIND(".",F9)+1,LEN(F9)-FIND(".",F9)+1),'Not Req'!$D$4:$D$71,0))} -> Data Definition | E9: =INDEX('Not Req'!$F$4:$F$71,MATCH(MID(F9,FIND(".",F9)+1,LEN(F9)-FIND(".",F9)+1),'Not Req'!$D$4:$D$71,0)) -> 4. CDS | F9: zjs_i_etypehierarchy.ddls.asddls | G9: UPDATED ON 02-FEB-26 | H9: 3 months ago
A10: D | B10: OK | C10: =LEFT(F10,FIND(".",F10)-1) -> zjs_i_etypeviewentity | D10: {=INDEX('Not Req'!$E$4:$E$71,MATCH(MID(F10,FIND(".",F10)+1,LEN(F10)-FIND(".",F10)+1),'Not Req'!$D$4:$D$71,0))} -> Data Definition | E10: =INDEX('Not Req'!$F$4:$F$71,MATCH(MID(F10,FIND(".",F10)+1,LEN(F10)-FIND(".",F10)+1),'Not Req'!$D$4:$D$71,0)) -> 4. CDS | F10: zjs_i_etypeviewentity.ddls.asddls | G10: UPDATED ON 02-FEB-26 | H10: 3 months ago
A11: D | B11: OK | C11: =LEFT(F11,FIND(".",F11)-1) -> zjs_s_etypeabstractentity | D11: {=INDEX('Not Req'!$E$4:$E$71,MATCH(MID(F11,FIND(".",F11)+1,LEN(F11)-FIND(".",F11)+1),'Not Req'!$D$4:$D$71,0))} -> Data Definition | E11: =INDEX('Not Req'!$F$4:$F$71,MATCH(MID(F11,FIND(".",F11)+1,LEN(F11)-FIND(".",F11)+1),'Not Req'!$D$4:$D$71,0)) -> 4. CDS | F11: zjs_s_etypeabstractentity.ddls.asddls | G11: UPDATED ON 02-FEB-26 | H11: 3 months ago
A12: D | B12: OK | C12: =LEFT(F12,FIND(".",F12)-1) -> zjs_t_etypeassociation | D12: {=INDEX('Not Req'!$E$4:$E$71,MATCH(MID(F12,FIND(".",F12)+1,LEN(F12)-FIND(".",F12)+1),'Not Req'!$D$4:$D$71,0))} -> Data Definition | E12: =INDEX('Not Req'!$F$4:$F$71,MATCH(MID(F12,FIND(".",F12)+1,LEN(F12)-FIND(".",F12)+1),'Not Req'!$D$4:$D$71,0)) -> 4. CDS | F12: zjs_t_etypeassociation.ddls.asddls | G12: UPDATED ON 02-FEB-26 | H12: 3 months ago
A13: D | B13: OK | C13: =LEFT(F13,FIND(".",F13)-1) -> zjs_t_etypetableentity | D13: {=INDEX('Not Req'!$E$4:$E$71,MATCH(MID(F13,FIND(".",F13)+1,LEN(F13)-FIND(".",F13)+1),'Not Req'!$D$4:$D$71,0))} -> Data Definition | E13: =INDEX('Not Req'!$F$4:$F$71,MATCH(MID(F13,FIND(".",F13)+1,LEN(F13)-FIND(".",F13)+1),'Not Req'!$D$4:$D$71,0)) -> 4. CDS | F13: zjs_t_etypetableentity.ddls.asddls | G13: UPDATED ON 02-FEB-26 | H13: 3 months ago
A14: D | B14: OK | C14: =LEFT(F14,FIND(".",F14)-1) -> zcl_js_demo_etpye_tfunc | D14: {=INDEX('Not Req'!$E$4:$E$71,MATCH(MID(F14,FIND(".",F14)+1,LEN(F14)-FIND(".",F14)+1),'Not Req'!$D$4:$D$71,0))} -> Classes | E14: =INDEX('Not Req'!$F$4:$F$71,MATCH(MID(F14,FIND(".",F14)+1,LEN(F14)-FIND(".",F14)+1),'Not Req'!$D$4:$D$71,0)) -> 7. Source Code Library | F14: zcl_js_demo_etpye_tfunc.clas.abap | G14: Updated 16-Mar-26 | H14: 2 months ago
A15: D | B15: OK | C15: =LEFT(F15,FIND(".",F15)-1) -> zcl_js_demo_etype_query | D15: {=INDEX('Not Req'!$E$4:$E$71,MATCH(MID(F15,FIND(".",F15)+1,LEN(F15)-FIND(".",F15)+1),'Not Req'!$D$4:$D$71,0))} -> Classes | E15: =INDEX('Not Req'!$F$4:$F$71,MATCH(MID(F15,FIND(".",F15)+1,LEN(F15)-FIND(".",F15)+1),'Not Req'!$D$4:$D$71,0)) -> 7. Source Code Library | F15: zcl_js_demo_etype_query.clas.abap | G15: Updated 16-Mar-26 | H15: 2 months ago
... A38: D | B38: OK | C38: =LEFT(F38,FIND(".",F38)-1) -> package | D38: {=INDEX('Not Req'!$E$4:$E$71,MATCH(MID(F38,FIND(".",F38)+1,LEN(F38)-FIND(".",F38)+1),'Not Req'!$D$4:$D$71,0))} -> Description : Package | E38: =INDEX('Not Req'!$F$4:$F$71,MATCH(MID(F38,FIND(".",F38)+1,LEN(F38)-FIND(".",F38)+1),'Not Req'!$D$4:$D$71,0)) -> 99. Descriptions | F38: package.devc.xml | G38: UPDATED ON 02-FEB-26 | H38: 3 months ago

Sheet ZJS_CORE_DATA_SERVICE
A2: d | B2: d | C2: Object | D2: Type | E2: Category | F2: Github Object | G2: Github Type | H2: Version
A4: D | B4: OK | C4: =LEFT(F4,FIND(".",F4)-1) -> zjs_b_dmoauthbase | D4: {=INDEX('Not Req'!$E$4:$E$71,MATCH(MID(F4,FIND(".",F4)+1,LEN(F4)-FIND(".",F4)+1),'Not Req'!$D$4:$D$71,0))} -> Access Control | E4: =INDEX('Not Req'!$F$4:$F$71,MATCH(MID(F4,FIND(".",F4)+1,LEN(F4)-FIND(".",F4)+1),'Not Req'!$D$4:$D$71,0)) -> 4. CDS | F4: zjs_b_dmoauthbase.dcls.asdcls | G4: UPDATED ON 02-FEB-26 | H4: 3 months ago
A5: D | B5: OK | C5: =LEFT(F5,FIND(".",F5)-1) -> zjs_i_dmoauthbase | D5: {=INDEX('Not Req'!$E$4:$E$71,MATCH(MID(F5,FIND(".",F5)+1,LEN(F5)-FIND(".",F5)+1),'Not Req'!$D$4:$D$71,0))} -> Access Control | E5: =INDEX('Not Req'!$F$4:$F$71,MATCH(MID(F5,FIND(".",F5)+1,LEN(F5)-FIND(".",F5)+1),'Not Req'!$D$4:$D$71,0)) -> 4. CDS | F5: zjs_i_dmoauthbase.dcls.asdcls | G5: UPDATED ON 02-FEB-26 | H5: 3 months ago
A6: D | B6: OK | C6: =LEFT(F6,FIND(".",F6)-1) -> zjs_i_dmomaterial | D6: {=INDEX('Not Req'!$E$4:$E$71,MATCH(MID(F6,FIND(".",F6)+1,LEN(F6)-FIND(".",F6)+1),'Not Req'!$D$4:$D$71,0))} -> Access Control | E6: =INDEX('Not Req'!$F$4:$F$71,MATCH(MID(F6,FIND(".",F6)+1,LEN(F6)-FIND(".",F6)+1),'Not Req'!$D$4:$D$71,0)) -> 4. CDS | F6: zjs_i_dmomaterial.dcls.asdcls | G6: UPDATED ON 02-FEB-26 | H6: 3 months ago
A7: D | B7: OK | C7: =LEFT(F7,FIND(".",F7)-1) -> zjs_democdsinvoicestatus | D7: {=INDEX('Not Req'!$E$4:$E$71,MATCH(MID(F7,FIND(".",F7)+1,LEN(F7)-FIND(".",F7)+1),'Not Req'!$D$4:$D$71,0))} -> CDS Types | E7: =INDEX('Not Req'!$F$4:$F$71,MATCH(MID(F7,FIND(".",F7)+1,LEN(F7)-FIND(".",F7)+1),'Not Req'!$D$4:$D$71,0)) -> 4. CDS | F7: zjs_democdsinvoicestatus.drty.acds | G7: UPDATED ON 02-FEB-26 | H7: 3 months ago
A8: D | B8: OK | C8: =LEFT(F8,FIND(".",F8)-1) -> zjs_democdsinvoicestatusenum | D8: {=INDEX('Not Req'!$E$4:$E$71,MATCH(MID(F8,FIND(".",F8)+1,LEN(F8)-FIND(".",F8)+1),'Not Req'!$D$4:$D$71,0))} -> CDS Types | E8: =INDEX('Not Req'!$F$4:$F$71,MATCH(MID(F8,FIND(".",F8)+1,LEN(F8)-FIND(".",F8)+1),'Not Req'!$D$4:$D$71,0)) -> 4. CDS | F8: zjs_democdsinvoicestatusenum.drty.acds | G8: UPDATED ON 02-FEB-26 | H8: 3 months ago
A9: D | B9: OK | C9: =LEFT(F9,FIND(".",F9)-1) -> zjs_b_dmoauthbase | D9: {=INDEX('Not Req'!$E$4:$E$71,MATCH(MID(F9,FIND(".",F9)+1,LEN(F9)-FIND(".",F9)+1),'Not Req'!$D$4:$D$71,0))} -> Data Definition | E9: =INDEX('Not Req'!$F$4:$F$71,MATCH(MID(F9,FIND(".",F9)+1,LEN(F9)-FIND(".",F9)+1),'Not Req'!$D$4:$D$71,0)) -> 4. CDS | F9: zjs_b_dmoauthbase.ddls.asddls | G9: UPDATED ON 02-FEB-26 | H9: 3 months ago
A10: D | B10: OK | C10: =LEFT(F10,FIND(".",F10)-1) -> zjs_b_dmoteamview | D10: {=INDEX('Not Req'!$E$4:$E$71,MATCH(MID(F10,FIND(".",F10)+1,LEN(F10)-FIND(".",F10)+1),'Not Req'!$D$4:$D$71,0))} -> Data Definition | E10: =INDEX('Not Req'!$F$4:$F$71,MATCH(MID(F10,FIND(".",F10)+1,LEN(F10)-FIND(".",F10)+1),'Not Req'!$D$4:$D$71,0)) -> 4. CDS | F10: zjs_b_dmoteamview.ddls.asddls | G10: UPDATED ON 02-FEB-26 | H10: 3 months ago
A11: D | B11: OK | C11: =LEFT(F11,FIND(".",F11)-1) -> zjs_c_dmodicountcast | D11: {=INDEX('Not Req'!$E$4:$E$71,MATCH(MID(F11,FIND(".",F11)+1,LEN(F11)-FIND(".",F11)+1),'Not Req'!$D$4:$D$71,0))} -> Data Definition | E11: =INDEX('Not Req'!$F$4:$F$71,MATCH(MID(F11,FIND(".",F11)+1,LEN(F11)-FIND(".",F11)+1),'Not Req'!$D$4:$D$71,0)) -> 4. CDS | F11: zjs_c_dmodicountcast.ddls.asddls | G11: UPDATED ON 02-FEB-26 | H11: 3 months ago
A12: D | B12: OK | C12: =LEFT(F12,FIND(".",F12)-1) -> zjs_c_dmodiscountextension | D12: {=INDEX('Not Req'!$E$4:$E$71,MATCH(MID(F12,FIND(".",F12)+1,LEN(F12)-FIND(".",F12)+1),'Not Req'!$D$4:$D$71,0))} -> Data Definition | E12: =INDEX('Not Req'!$F$4:$F$71,MATCH(MID(F12,FIND(".",F12)+1,LEN(F12)-FIND(".",F12)+1),'Not Req'!$D$4:$D$71,0)) -> 4. CDS | F12: zjs_c_dmodiscountextension.ddls.asddls | G12: UPDATED ON 02-FEB-26 | H12: 3 months ago
A13: D | B13: OK | C13: =LEFT(F13,FIND(".",F13)-1) -> zjs_c_dmoinvoicesession | D13: {=INDEX('Not Req'!$E$4:$E$71,MATCH(MID(F13,FIND(".",F13)+1,LEN(F13)-FIND(".",F13)+1),'Not Req'!$D$4:$D$71,0))} -> Data Definition | E13: =INDEX('Not Req'!$F$4:$F$71,MATCH(MID(F13,FIND(".",F13)+1,LEN(F13)-FIND(".",F13)+1),'Not Req'!$D$4:$D$71,0)) -> 4. CDS | F13: zjs_c_dmoinvoicesession.ddls.asddls | G13: UPDATED ON 02-FEB-26 | H13: 3 months ago
A14: D | B14: OK | C14: =LEFT(F14,FIND(".",F14)-1) -> zjs_c_dmoinvoicesubstring | D14: {=INDEX('Not Req'!$E$4:$E$71,MATCH(MID(F14,FIND(".",F14)+1,LEN(F14)-FIND(".",F14)+1),'Not Req'!$D$4:$D$71,0))} -> Data Definition | E14: =INDEX('Not Req'!$F$4:$F$71,MATCH(MID(F14,FIND(".",F14)+1,LEN(F14)-FIND(".",F14)+1),'Not Req'!$D$4:$D$71,0)) -> 4. CDS | F14: zjs_c_dmoinvoicesubstring.ddls.asddls | G14: UPDATED ON 02-FEB-26 | H14: 3 months ago
A15: D | B15: OK | C15: =LEFT(F15,FIND(".",F15)-1) -> zjs_c_dmomaterialconversion | D15: {=INDEX('Not Req'!$E$4:$E$71,MATCH(MID(F15,FIND(".",F15)+1,LEN(F15)-FIND(".",F15)+1),'Not Req'!$D$4:$D$71,0))} -> Data Definition | E15: =INDEX('Not Req'!$F$4:$F$71,MATCH(MID(F15,FIND(".",F15)+1,LEN(F15)-FIND(".",F15)+1),'Not Req'!$D$4:$D$71,0)) -> 4. CDS | F15: zjs_c_dmomaterialconversion.ddls.asddls | G15: UPDATED ON 02-FEB-26 | H15: 3 months ago
... A139: D | B139: OK | C139: =LEFT(F139,FIND(".",F139)-1) -> zrf_matnr | D139: {=INDEX('Not Req'!$E$4:$E$71,MATCH(MID(F139,FIND(".",F139)+1,LEN(F139)-FIND(".",F139)+1),'Not Req'!$D$4:$D$71,0))} -> Description : Authorization Field | E139: =INDEX('Not Req'!$F$4:$F$71,MATCH(MID(F139,FIND(".",F139)+1,LEN(F139)-FIND(".",F139)+1),'Not Req'!$D$4:$D$71,0)) -> 99. Descriptions | F139: zrf_matnr.sia5.xml | G139: UPDATED ON 02-FEB-26 | H139: 3 months ago

Sheet ZJS_12_RAP_SALES
A2: d | B2: d | C2: Object | D2: Type | E2: Category | F2: Github Object | G2: Github Type | H2: Version
A4: D | B4: OK | C4: =LEFT(F4,FIND(".",F4)-1) -> e7ce711363fc64354a944ad5568ef6ht | D4: {=INDEX('Not Req'!$E$4:$E$71,MATCH(MID(F4,FIND(".",F4)+1,LEN(F4)-FIND(".",F4)+1),'Not Req'!$D$4:$D$71,0))} -> Authorization Defaults (TADIR) | E4: =INDEX('Not Req'!$F$4:$F$71,MATCH(MID(F4,FIND(".",F4)+1,LEN(F4)-FIND(".",F4)+1),'Not Req'!$D$4:$D$71,0)) -> 1. Authorizations | F4: e7ce711363fc64354a944ad5568ef6ht.sush.xml | G4: UPDATED ON 02-FEB-26 | H4: 3 months ago
A5: D | B5: OK | C5: =LEFT(F5,FIND(".",F5)-1) -> zjs_ui_globalsale_o4 | D5: {=INDEX('Not Req'!$E$4:$E$71,MATCH(MID(F5,FIND(".",F5)+1,LEN(F5)-FIND(".",F5)+1),'Not Req'!$D$4:$D$71,0))} -> Service Binding | E5: =INDEX('Not Req'!$F$4:$F$71,MATCH(MID(F5,FIND(".",F5)+1,LEN(F5)-FIND(".",F5)+1),'Not Req'!$D$4:$D$71,0)) -> 2. Business Services | F5: zjs_ui_globalsale_o4.srvb.xml | G5: UPDATED ON 02-FEB-26 | H5: 3 months ago
A6: D | B6: OK | C6: =LEFT(F6,FIND(".",F6)-1) -> zjs_ui_globalsale_o4 | D6: {=INDEX('Not Req'!$E$4:$E$71,MATCH(MID(F6,FIND(".",F6)+1,LEN(F6)-FIND(".",F6)+1),'Not Req'!$D$4:$D$71,0))} -> Service Definition | E6: =INDEX('Not Req'!$F$4:$F$71,MATCH(MID(F6,FIND(".",F6)+1,LEN(F6)-FIND(".",F6)+1),'Not Req'!$D$4:$D$71,0)) -> 2. Business Services | F6: zjs_ui_globalsale_o4.srvd.srvdsrv | G6: UPDATED ON 02-FEB-26 | H6: 3 months ago
A7: D | B7: OK | C7: =LEFT(F7,FIND(".",F7)-1) -> zjs_ui_globalsale_o4_0001_g4ba | D7: {=INDEX('Not Req'!$E$4:$E$71,MATCH(MID(F7,FIND(".",F7)+1,LEN(F7)-FIND(".",F7)+1),'Not Req'!$D$4:$D$71,0))} -> Inbound Service | E7: =INDEX('Not Req'!$F$4:$F$71,MATCH(MID(F7,FIND(".",F7)+1,LEN(F7)-FIND(".",F7)+1),'Not Req'!$D$4:$D$71,0)) -> 3. Cloud Communication Management | F7: zjs_ui_globalsale_o4_0001_g4ba.sco2.xml | G7: UPDATED ON 02-FEB-26 | H7: 3 months ago
A8: D | B8: OK | C8: =LEFT(F8,FIND(".",F8)-1) -> zjs_c_sainfo | D8: {=INDEX('Not Req'!$E$4:$E$71,MATCH(MID(F8,FIND(".",F8)+1,LEN(F8)-FIND(".",F8)+1),'Not Req'!$D$4:$D$71,0))} -> Access Control | E8: =INDEX('Not Req'!$F$4:$F$71,MATCH(MID(F8,FIND(".",F8)+1,LEN(F8)-FIND(".",F8)+1),'Not Req'!$D$4:$D$71,0)) -> 4. CDS | F8: zjs_c_sainfo.dcls.asdcls | G8: UPDATED ON 02-FEB-26 | H8: 3 months ago
A9: D | B9: OK | C9: =LEFT(F9,FIND(".",F9)-1) -> zjs_c_sasale | D9: {=INDEX('Not Req'!$E$4:$E$71,MATCH(MID(F9,FIND(".",F9)+1,LEN(F9)-FIND(".",F9)+1),'Not Req'!$D$4:$D$71,0))} -> Access Control | E9: =INDEX('Not Req'!$F$4:$F$71,MATCH(MID(F9,FIND(".",F9)+1,LEN(F9)-FIND(".",F9)+1),'Not Req'!$D$4:$D$71,0)) -> 4. CDS | F9: zjs_c_sasale.dcls.asdcls | G9: UPDATED ON 02-FEB-26 | H9: 3 months ago
A10: D | B10: OK | C10: =LEFT(F10,FIND(".",F10)-1) -> zjs_c_saseller | D10: {=INDEX('Not Req'!$E$4:$E$71,MATCH(MID(F10,FIND(".",F10)+1,LEN(F10)-FIND(".",F10)+1),'Not Req'!$D$4:$D$71,0))} -> Access Control | E10: =INDEX('Not Req'!$F$4:$F$71,MATCH(MID(F10,FIND(".",F10)+1,LEN(F10)-FIND(".",F10)+1),'Not Req'!$D$4:$D$71,0)) -> 4. CDS | F10: zjs_c_saseller.dcls.asdcls | G10: UPDATED ON 02-FEB-26 | H10: 3 months ago
A11: D | B11: OK | C11: =LEFT(F11,FIND(".",F11)-1) -> zjs_c_sasold | D11: {=INDEX('Not Req'!$E$4:$E$71,MATCH(MID(F11,FIND(".",F11)+1,LEN(F11)-FIND(".",F11)+1),'Not Req'!$D$4:$D$71,0))} -> Access Control | E11: =INDEX('Not Req'!$F$4:$F$71,MATCH(MID(F11,FIND(".",F11)+1,LEN(F11)-FIND(".",F11)+1),'Not Req'!$D$4:$D$71,0)) -> 4. CDS | F11: zjs_c_sasold.dcls.asdcls | G11: UPDATED ON 02-FEB-26 | H11: 3 months ago
A12: D | B12: OK | C12: =LEFT(F12,FIND(".",F12)-1) -> zjs_r_sainfo | D12: {=INDEX('Not Req'!$E$4:$E$71,MATCH(MID(F12,FIND(".",F12)+1,LEN(F12)-FIND(".",F12)+1),'Not Req'!$D$4:$D$71,0))} -> Access Control | E12: =INDEX('Not Req'!$F$4:$F$71,MATCH(MID(F12,FIND(".",F12)+1,LEN(F12)-FIND(".",F12)+1),'Not Req'!$D$4:$D$71,0)) -> 4. CDS | F12: zjs_r_sainfo.dcls.asdcls | G12: UPDATED ON 02-FEB-26 | H12: 3 months ago
A13: D | B13: OK | C13: =LEFT(F13,FIND(".",F13)-1) -> zjs_r_sasale | D13: {=INDEX('Not Req'!$E$4:$E$71,MATCH(MID(F13,FIND(".",F13)+1,LEN(F13)-FIND(".",F13)+1),'Not Req'!$D$4:$D$71,0))} -> Access Control | E13: =INDEX('Not Req'!$F$4:$F$71,MATCH(MID(F13,FIND(".",F13)+1,LEN(F13)-FIND(".",F13)+1),'Not Req'!$D$4:$D$71,0)) -> 4. CDS | F13: zjs_r_sasale.dcls.asdcls | G13: UPDATED ON 02-FEB-26 | H13: 3 months ago
A14: D | B14: OK | C14: =LEFT(F14,FIND(".",F14)-1) -> zjs_r_saseller | D14: {=INDEX('Not Req'!$E$4:$E$71,MATCH(MID(F14,FIND(".",F14)+1,LEN(F14)-FIND(".",F14)+1),'Not Req'!$D$4:$D$71,0))} -> Access Control | E14: =INDEX('Not Req'!$F$4:$F$71,MATCH(MID(F14,FIND(".",F14)+1,LEN(F14)-FIND(".",F14)+1),'Not Req'!$D$4:$D$71,0)) -> 4. CDS | F14: zjs_r_saseller.dcls.asdcls | G14: UPDATED ON 02-FEB-26 | H14: 3 months ago
A15: D | B15: OK | C15: =LEFT(F15,FIND(".",F15)-1) -> zjs_r_sasold | D15: {=INDEX('Not Req'!$E$4:$E$71,MATCH(MID(F15,FIND(".",F15)+1,LEN(F15)-FIND(".",F15)+1),'Not Req'!$D$4:$D$71,0))} -> Access Control | E15: =INDEX('Not Req'!$F$4:$F$71,MATCH(MID(F15,FIND(".",F15)+1,LEN(F15)-FIND(".",F15)+1),'Not Req'!$D$4:$D$71,0)) -> 4. CDS | F15: zjs_r_sasold.dcls.asdcls | G15: UPDATED ON 02-FEB-26 | H15: 3 months ago
... A69: D | B69: OK | C69: =LEFT(F69,FIND(".",F69)-1) -> zjs_bp_r_sasale | D69: {=INDEX('Not Req'!$E$4:$E$71,MATCH(MID(F69,FIND(".",F69)+1,LEN(F69)-FIND(".",F69)+1),'Not Req'!$D$4:$D$71,0))} -> Classes Local | E69: =INDEX('Not Req'!$F$4:$F$71,MATCH(MID(F69,FIND(".",F69)+1,LEN(F69)-FIND(".",F69)+1),'Not Req'!$D$4:$D$71,0)) -> 7. Source Code Library | F69: zjs_bp_r_sasale.clas.locals_imp.abap | G69: UPDATED ON 02-FEB-26 | H69: 3 months ago
A70: D | C70: =LEFT(F70,FIND(".",F70)-1) -> zjs_c_sainfo | D70: {=INDEX('Not Req'!$E$4:$E$71,MATCH(MID(F70,FIND(".",F70)+1,LEN(F70)-FIND(".",F70)+1),'Not Req'!$D$4:$D$71,0))} -> BaseInfo : Data Definition | E70: =INDEX('Not Req'!$F$4:$F$71,MATCH(MID(F70,FIND(".",F70)+1,LEN(F70)-FIND(".",F70)+1),'Not Req'!$D$4:$D$71,0)) -> 98. Base Info | F70: zjs_c_sainfo.ddls.baseinfo | G70: UPDATED ON 02-FEB-26 | H70: 3 months ago
A71: D | C71: =LEFT(F71,FIND(".",F71)-1) -> zjs_c_sasale | D71: {=INDEX('Not Req'!$E$4:$E$71,MATCH(MID(F71,FIND(".",F71)+1,LEN(F71)-FIND(".",F71)+1),'Not Req'!$D$4:$D$71,0))} -> BaseInfo : Data Definition | E71: =INDEX('Not Req'!$F$4:$F$71,MATCH(MID(F71,FIND(".",F71)+1,LEN(F71)-FIND(".",F71)+1),'Not Req'!$D$4:$D$71,0)) -> 98. Base Info | F71: zjs_c_sasale.ddls.baseinfo | G71: UPDATED ON 02-FEB-26 | H71: 3 months ago
A72: D | C72: =LEFT(F72,FIND(".",F72)-1) -> zjs_c_saseller | D72: {=INDEX('Not Req'!$E$4:$E$71,MATCH(MID(F72,FIND(".",F72)+1,LEN(F72)-FIND(".",F72)+1),'Not Req'!$D$4:$D$71,0))} -> BaseInfo : Data Definition | E72: =INDEX('Not Req'!$F$4:$F$71,MATCH(MID(F72,FIND(".",F72)+1,LEN(F72)-FIND(".",F72)+1),'Not Req'!$D$4:$D$71,0)) -> 98. Base Info | F72: zjs_c_saseller.ddls.baseinfo | G72: UPDATED ON 02-FEB-26 | H72: 3 months ago
A73: D | C73: =LEFT(F73,FIND(".",F73)-1) -> zjs_c_sasold | D73: {=INDEX('Not Req'!$E$4:$E$71,MATCH(MID(F73,FIND(".",F73)+1,LEN(F73)-FIND(".",F73)+1),'Not Req'!$D$4:$D$71,0))} -> BaseInfo : Data Definition | E73: =INDEX('Not Req'!$F$4:$F$71,MATCH(MID(F73,FIND(".",F73)+1,LEN(F73)-FIND(".",F73)+1),'Not Req'!$D$4:$D$71,0)) -> 98. Base Info | F73: zjs_c_sasold.ddls.baseinfo | G73: UPDATED ON 02-FEB-26 | H73: 3 months ago
A74: D | C74: =LEFT(F74,FIND(".",F74)-1) -> zjs_i_samaterialvh | D74: {=INDEX('Not Req'!$E$4:$E$71,MATCH(MID(F74,FIND(".",F74)+1,LEN(F74)-FIND(".",F74)+1),'Not Req'!$D$4:$D$71,0))} -> BaseInfo : Data Definition | E74: =INDEX('Not Req'!$F$4:$F$71,MATCH(MID(F74,FIND(".",F74)+1,LEN(F74)-FIND(".",F74)+1),'Not Req'!$D$4:$D$71,0)) -> 98. Base Info | F74: zjs_i_samaterialvh.ddls.baseinfo | G74: UPDATED ON 02-FEB-26 | H74: 3 months ago
A75: D | C75: =LEFT(F75,FIND(".",F75)-1) -> zjs_r_sainfo | D75: {=INDEX('Not Req'!$E$4:$E$71,MATCH(MID(F75,FIND(".",F75)+1,LEN(F75)-FIND(".",F75)+1),'Not Req'!$D$4:$D$71,0))} -> BaseInfo : Data Definition | E75: =INDEX('Not Req'!$F$4:$F$71,MATCH(MID(F75,FIND(".",F75)+1,LEN(F75)-FIND(".",F75)+1),'Not Req'!$D$4:$D$71,0)) -> 98. Base Info | F75: zjs_r_sainfo.ddls.baseinfo | G75: UPDATED ON 02-FEB-26 | H75: 3 months ago
A76: D | C76: =LEFT(F76,FIND(".",F76)-1) -> zjs_r_sasale | D76: {=INDEX('Not Req'!$E$4:$E$71,MATCH(MID(F76,FIND(".",F76)+1,LEN(F76)-FIND(".",F76)+1),'Not Req'!$D$4:$D$71,0))} -> BaseInfo : Data Definition | E76: =INDEX('Not Req'!$F$4:$F$71,MATCH(MID(F76,FIND(".",F76)+1,LEN(F76)-FIND(".",F76)+1),'Not Req'!$D$4:$D$71,0)) -> 98. Base Info | F76: zjs_r_sasale.ddls.baseinfo | G76: UPDATED ON 02-FEB-26 | H76: 3 months ago
A77: D | C77: =LEFT(F77,FIND(".",F77)-1) -> zjs_r_saseller | D77: {=INDEX('Not Req'!$E$4:$E$71,MATCH(MID(F77,FIND(".",F77)+1,LEN(F77)-FIND(".",F77)+1),'Not Req'!$D$4:$D$71,0))} -> BaseInfo : Data Definition | E77: =INDEX('Not Req'!$F$4:$F$71,MATCH(MID(F77,FIND(".",F77)+1,LEN(F77)-FIND(".",F77)+1),'Not Req'!$D$4:$D$71,0)) -> 98. Base Info | F77: zjs_r_saseller.ddls.baseinfo | G77: UPDATED ON 02-FEB-26 | H77: 3 months ago
A78: D | C78: =LEFT(F78,FIND(".",F78)-1) -> zjs_r_sasold | D78: {=INDEX('Not Req'!$E$4:$E$71,MATCH(MID(F78,FIND(".",F78)+1,LEN(F78)-FIND(".",F78)+1),'Not Req'!$D$4:$D$71,0))} -> BaseInfo : Data Definition | E78: =INDEX('Not Req'!$F$4:$F$71,MATCH(MID(F78,FIND(".",F78)+1,LEN(F78)-FIND(".",F78)+1),'Not Req'!$D$4:$D$71,0)) -> 98. Base Info | F78: zjs_r_sasold.ddls.baseinfo | G78: UPDATED ON 02-FEB-26 | H78: 3 months ago
A79: D | C79: =LEFT(F79,FIND(".",F79)-1) -> zjs_s_sainfo | D79: {=INDEX('Not Req'!$E$4:$E$71,MATCH(MID(F79,FIND(".",F79)+1,LEN(F79)-FIND(".",F79)+1),'Not Req'!$D$4:$D$71,0))} -> BaseInfo : Data Definition | E79: =INDEX('Not Req'!$F$4:$F$71,MATCH(MID(F79,FIND(".",F79)+1,LEN(F79)-FIND(".",F79)+1),'Not Req'!$D$4:$D$71,0)) -> 98. Base Info | F79: zjs_s_sainfo.ddls.baseinfo | G79: UPDATED ON 02-FEB-26 | H79: 3 months ago
A80: D | C80: =LEFT(F80,FIND(".",F80)-1) -> zjs_s_sasale | D80: {=INDEX('Not Req'!$E$4:$E$71,MATCH(MID(F80,FIND(".",F80)+1,LEN(F80)-FIND(".",F80)+1),'Not Req'!$D$4:$D$71,0))} -> BaseInfo : Data Definition | E80: =INDEX('Not Req'!$F$4:$F$71,MATCH(MID(F80,FIND(".",F80)+1,LEN(F80)-FIND(".",F80)+1),'Not Req'!$D$4:$D$71,0)) -> 98. Base Info | F80: zjs_s_sasale.ddls.baseinfo | G80: UPDATED ON 02-FEB-26 | H80: 3 months ago
A81: D | C81: =LEFT(F81,FIND(".",F81)-1) -> zjs_s_saseller | D81: {=INDEX('Not Req'!$E$4:$E$71,MATCH(MID(F81,FIND(".",F81)+1,LEN(F81)-FIND(".",F81)+1),'Not Req'!$D$4:$D$71,0))} -> BaseInfo : Data Definition | E81: =INDEX('Not Req'!$F$4:$F$71,MATCH(MID(F81,FIND(".",F81)+1,LEN(F81)-FIND(".",F81)+1),'Not Req'!$D$4:$D$71,0)) -> 98. Base Info | F81: zjs_s_saseller.ddls.baseinfo | G81: UPDATED ON 02-FEB-26 | H81: 3 months ago
... A117: D | C117: =LEFT(F117,FIND(".",F117)-1) -> zjs_globalsale | D117: {=INDEX('Not Req'!$E$4:$E$71,MATCH(MID(F117,FIND(".",F117)+1,LEN(F117)-FIND(".",F117)+1),'Not Req'!$D$4:$D$71,0))} -> #N/A | E117: =INDEX('Not Req'!$F$4:$F$71,MATCH(MID(F117,FIND(".",F117)+1,LEN(F117)-FIND(".",F117)+1),'Not Req'!$D$4:$D$71,0)) -> #N/A | F117: zjs_globalsale.ront.json | G117: UPDATED ON 02-FEB-26 | H117: 3 months ago

Sheet ZJS_11_RAP_CUSTOM_ACTION
A2: d | B2: d | C2: Object | D2: Type | E2: Category | F2: Github Object | G2: Github Type | H2: Version
A4: D | B4: OK | C4: =LEFT(F4,FIND(".",F4)-1) -> 054eb8e77fe0d2fb2e9f8e06b34faeht | D4: {=INDEX('Not Req'!$E$4:$E$71,MATCH(MID(F4,FIND(".",F4)+1,LEN(F4)-FIND(".",F4)+1),'Not Req'!$D$4:$D$71,0))} -> Authorization Defaults (TADIR) | E4: =INDEX('Not Req'!$F$4:$F$71,MATCH(MID(F4,FIND(".",F4)+1,LEN(F4)-FIND(".",F4)+1),'Not Req'!$D$4:$D$71,0)) -> 1. Authorizations | F4: 054eb8e77fe0d2fb2e9f8e06b34faeht.sush.xml | G4: UPDATED ON 02-FEB-26 | H4: 3 months ago
A5: D | B5: OK | C5: =LEFT(F5,FIND(".",F5)-1) -> 81ec0b0855ed7dace8b1158851d483ht | D5: {=INDEX('Not Req'!$E$4:$E$71,MATCH(MID(F5,FIND(".",F5)+1,LEN(F5)-FIND(".",F5)+1),'Not Req'!$D$4:$D$71,0))} -> Authorization Defaults (TADIR) | E5: =INDEX('Not Req'!$F$4:$F$71,MATCH(MID(F5,FIND(".",F5)+1,LEN(F5)-FIND(".",F5)+1),'Not Req'!$D$4:$D$71,0)) -> 1. Authorizations | F5: 81ec0b0855ed7dace8b1158851d483ht.sush.xml | G5: UPDATED ON 02-FEB-26 | H5: 3 months ago
A6: D | B6: OK | C6: =LEFT(F6,FIND(".",F6)-1) -> zjs_custom_action | D6: {=INDEX('Not Req'!$E$4:$E$71,MATCH(MID(F6,FIND(".",F6)+1,LEN(F6)-FIND(".",F6)+1),'Not Req'!$D$4:$D$71,0))} -> Service Definition | E6: =INDEX('Not Req'!$F$4:$F$71,MATCH(MID(F6,FIND(".",F6)+1,LEN(F6)-FIND(".",F6)+1),'Not Req'!$D$4:$D$71,0)) -> 2. Business Services | F6: zjs_custom_action.srvd.srvdsrv | G6: UPDATED ON 02-FEB-26 | H6: 3 months ago
A7: D | B7: OK | C7: =LEFT(F7,FIND(".",F7)-1) -> zjs_ui_custom_action_o2 | D7: {=INDEX('Not Req'!$E$4:$E$71,MATCH(MID(F7,FIND(".",F7)+1,LEN(F7)-FIND(".",F7)+1),'Not Req'!$D$4:$D$71,0))} -> Service Binding | E7: =INDEX('Not Req'!$F$4:$F$71,MATCH(MID(F7,FIND(".",F7)+1,LEN(F7)-FIND(".",F7)+1),'Not Req'!$D$4:$D$71,0)) -> 2. Business Services | F7: zjs_ui_custom_action_o2.srvb.xml | G7: UPDATED ON 02-FEB-26 | H7: 3 months ago
A8: D | B8: OK | C8: =LEFT(F8,FIND(".",F8)-1) -> zjs_ui_custom_action_o2_iwsg | D8: {=INDEX('Not Req'!$E$4:$E$71,MATCH(MID(F8,FIND(".",F8)+1,LEN(F8)-FIND(".",F8)+1),'Not Req'!$D$4:$D$71,0))} -> Inbound Service | E8: =INDEX('Not Req'!$F$4:$F$71,MATCH(MID(F8,FIND(".",F8)+1,LEN(F8)-FIND(".",F8)+1),'Not Req'!$D$4:$D$71,0)) -> 3. Cloud Communication Management | F8: zjs_ui_custom_action_o2_iwsg.sco2.xml | G8: UPDATED ON 02-FEB-26 | H8: 3 months ago
A9: D | B9: OK | C9: =LEFT(F9,FIND(".",F9)-1) -> zjs_r_cusactentitytp | D9: {=INDEX('Not Req'!$E$4:$E$71,MATCH(MID(F9,FIND(".",F9)+1,LEN(F9)-FIND(".",F9)+1),'Not Req'!$D$4:$D$71,0))} -> BDEF | E9: =INDEX('Not Req'!$F$4:$F$71,MATCH(MID(F9,FIND(".",F9)+1,LEN(F9)-FIND(".",F9)+1),'Not Req'!$D$4:$D$71,0)) -> 4. CDS | F9: zjs_r_cusactentitytp.bdef.asbdef | G9: UPDATED ON 02-FEB-26 | H9: 3 months ago
A10: D | B10: OK | C10: =LEFT(F10,FIND(".",F10)-1) -> zjs_r_cusactentitytp | D10: {=INDEX('Not Req'!$E$4:$E$71,MATCH(MID(F10,FIND(".",F10)+1,LEN(F10)-FIND(".",F10)+1),'Not Req'!$D$4:$D$71,0))} -> Data Definition | E10: =INDEX('Not Req'!$F$4:$F$71,MATCH(MID(F10,FIND(".",F10)+1,LEN(F10)-FIND(".",F10)+1),'Not Req'!$D$4:$D$71,0)) -> 4. CDS | F10: zjs_r_cusactentitytp.ddls.asddls | G10: UPDATED ON 02-FEB-26 | H10: 3 months ago
A11: D | B11: OK | C11: =LEFT(F11,FIND(".",F11)-1) -> zjs_dmo_cstat | D11: {=INDEX('Not Req'!$E$4:$E$71,MATCH(MID(F11,FIND(".",F11)+1,LEN(F11)-FIND(".",F11)+1),'Not Req'!$D$4:$D$71,0))} -> Table | E11: =INDEX('Not Req'!$F$4:$F$71,MATCH(MID(F11,FIND(".",F11)+1,LEN(F11)-FIND(".",F11)+1),'Not Req'!$D$4:$D$71,0)) -> 5. Dictionary | F11: zjs_dmo_cstat.tabl.xml | G11: UPDATED ON 02-FEB-26 | H11: 3 months ago
A12: D | B12: OK | C12: =LEFT(F12,FIND(".",F12)-1) -> zbp_js_demo_custom_action | D12: {=INDEX('Not Req'!$E$4:$E$71,MATCH(MID(F12,FIND(".",F12)+1,LEN(F12)-FIND(".",F12)+1),'Not Req'!$D$4:$D$71,0))} -> Classes | E12: =INDEX('Not Req'!$F$4:$F$71,MATCH(MID(F12,FIND(".",F12)+1,LEN(F12)-FIND(".",F12)+1),'Not Req'!$D$4:$D$71,0)) -> 7. Source Code Library | F12: zbp_js_demo_custom_action.clas.abap | G12: Updated 16-Mar-26 | H12: 2 months ago
A13: D | B13: OK | C13: =LEFT(F13,FIND(".",F13)-1) -> zbp_js_demo_custom_action | D13: {=INDEX('Not Req'!$E$4:$E$71,MATCH(MID(F13,FIND(".",F13)+1,LEN(F13)-FIND(".",F13)+1),'Not Req'!$D$4:$D$71,0))} -> Classes Local | E13: =INDEX('Not Req'!$F$4:$F$71,MATCH(MID(F13,FIND(".",F13)+1,LEN(F13)-FIND(".",F13)+1),'Not Req'!$D$4:$D$71,0)) -> 7. Source Code Library | F13: zbp_js_demo_custom_action.clas.locals_imp.abap | G13: UPDATED ON 02-FEB-26 | H13: 3 months ago
A14: D | B14: OK | C14: =LEFT(F14,FIND(".",F14)-1) -> zcl_js_demo_custom_action_qry | D14: {=INDEX('Not Req'!$E$4:$E$71,MATCH(MID(F14,FIND(".",F14)+1,LEN(F14)-FIND(".",F14)+1),'Not Req'!$D$4:$D$71,0))} -> Classes | E14: =INDEX('Not Req'!$F$4:$F$71,MATCH(MID(F14,FIND(".",F14)+1,LEN(F14)-FIND(".",F14)+1),'Not Req'!$D$4:$D$71,0)) -> 7. Source Code Library | F14: zcl_js_demo_custom_action_qry.clas.abap | G14: Updated 16-Mar-26 | H14: 2 months ago
A15: D | B15: OK | C15: =LEFT(F15,FIND(".",F15)-1) -> zjs_r_cusactentitytp | D15: {=INDEX('Not Req'!$E$4:$E$71,MATCH(MID(F15,FIND(".",F15)+1,LEN(F15)-FIND(".",F15)+1),'Not Req'!$D$4:$D$71,0))} -> BaseInfo : Data Definition | E15: =INDEX('Not Req'!$F$4:$F$71,MATCH(MID(F15,FIND(".",F15)+1,LEN(F15)-FIND(".",F15)+1),'Not Req'!$D$4:$D$71,0)) -> 98. Base Info | F15: zjs_r_cusactentitytp.ddls.baseinfo | G15: UPDATED ON 02-FEB-26 | H15: 3 months ago
... A21: D | B21: OK | C21: =LEFT(F21,FIND(".",F21)-1) -> zjs_r_cusactentitytp | D21: {=INDEX('Not Req'!$E$4:$E$71,MATCH(MID(F21,FIND(".",F21)+1,LEN(F21)-FIND(".",F21)+1),'Not Req'!$D$4:$D$71,0))} -> Description : Data Definition | E21: =INDEX('Not Req'!$F$4:$F$71,MATCH(MID(F21,FIND(".",F21)+1,LEN(F21)-FIND(".",F21)+1),'Not Req'!$D$4:$D$71,0)) -> 99. Descriptions | F21: zjs_r_cusactentitytp.ddls.xml | G21: UPDATED ON 02-FEB-26 | H21: 3 months ago

Sheet ZJS_10_RAP_TREE
A2: d | B2: d | C2: Object | D2: Type | E2: Category | F2: Github Object | G2: Github Type | H2: Version
A4: D | B4: OK | C4: =LEFT(F4,FIND(".",F4)-1) -> 03cee98b070e44773f34d25bf0e8a4ht | D4: {=INDEX('Not Req'!$E$4:$E$71,MATCH(MID(F4,FIND(".",F4)+1,LEN(F4)-FIND(".",F4)+1),'Not Req'!$D$4:$D$71,0))} -> Authorization Defaults (TADIR) | E4: =INDEX('Not Req'!$F$4:$F$71,MATCH(MID(F4,FIND(".",F4)+1,LEN(F4)-FIND(".",F4)+1),'Not Req'!$D$4:$D$71,0)) -> 1. Authorizations | F4: 03cee98b070e44773f34d25bf0e8a4ht.sush.xml | G4: UPDATED ON 02-FEB-26 | H4: 3 months ago
A5: D | B5: OK | C5: =LEFT(F5,FIND(".",F5)-1) -> zjs_demo_tree_team | D5: {=INDEX('Not Req'!$E$4:$E$71,MATCH(MID(F5,FIND(".",F5)+1,LEN(F5)-FIND(".",F5)+1),'Not Req'!$D$4:$D$71,0))} -> Service Definition | E5: =INDEX('Not Req'!$F$4:$F$71,MATCH(MID(F5,FIND(".",F5)+1,LEN(F5)-FIND(".",F5)+1),'Not Req'!$D$4:$D$71,0)) -> 2. Business Services | F5: zjs_demo_tree_team.srvd.srvdsrv | G5: UPDATED ON 02-FEB-26 | H5: 3 months ago
A6: D | B6: OK | C6: =LEFT(F6,FIND(".",F6)-1) -> zjs_ui_demo_tree_team_o4 | D6: {=INDEX('Not Req'!$E$4:$E$71,MATCH(MID(F6,FIND(".",F6)+1,LEN(F6)-FIND(".",F6)+1),'Not Req'!$D$4:$D$71,0))} -> Service Binding | E6: =INDEX('Not Req'!$F$4:$F$71,MATCH(MID(F6,FIND(".",F6)+1,LEN(F6)-FIND(".",F6)+1),'Not Req'!$D$4:$D$71,0)) -> 2. Business Services | F6: zjs_ui_demo_tree_team_o4.srvb.xml | G6: UPDATED ON 02-FEB-26 | H6: 3 months ago
A7: D | B7: OK | C7: =LEFT(F7,FIND(".",F7)-1) -> zjs_ui_demo_tree_team_o4_0001_g4ba | D7: {=INDEX('Not Req'!$E$4:$E$71,MATCH(MID(F7,FIND(".",F7)+1,LEN(F7)-FIND(".",F7)+1),'Not Req'!$D$4:$D$71,0))} -> Inbound Service | E7: =INDEX('Not Req'!$F$4:$F$71,MATCH(MID(F7,FIND(".",F7)+1,LEN(F7)-FIND(".",F7)+1),'Not Req'!$D$4:$D$71,0)) -> 3. Cloud Communication Management | F7: zjs_ui_demo_tree_team_o4_0001_g4ba.sco2.xml | G7: UPDATED ON 02-FEB-26 | H7: 3 months ago
A8: D | B8: OK | C8: =LEFT(F8,FIND(".",F8)-1) -> zjs_c_dmotreeteam | D8: {=INDEX('Not Req'!$E$4:$E$71,MATCH(MID(F8,FIND(".",F8)+1,LEN(F8)-FIND(".",F8)+1),'Not Req'!$D$4:$D$71,0))} -> BDEF | E8: =INDEX('Not Req'!$F$4:$F$71,MATCH(MID(F8,FIND(".",F8)+1,LEN(F8)-FIND(".",F8)+1),'Not Req'!$D$4:$D$71,0)) -> 4. CDS | F8: zjs_c_dmotreeteam.bdef.asbdef | G8: UPDATED ON 02-FEB-26 | H8: 3 months ago
A9: D | B9: OK | C9: =LEFT(F9,FIND(".",F9)-1) -> zjs_c_dmotreeteam | D9: {=INDEX('Not Req'!$E$4:$E$71,MATCH(MID(F9,FIND(".",F9)+1,LEN(F9)-FIND(".",F9)+1),'Not Req'!$D$4:$D$71,0))} -> Data Definition | E9: =INDEX('Not Req'!$F$4:$F$71,MATCH(MID(F9,FIND(".",F9)+1,LEN(F9)-FIND(".",F9)+1),'Not Req'!$D$4:$D$71,0)) -> 4. CDS | F9: zjs_c_dmotreeteam.ddls.asddls | G9: UPDATED ON 02-FEB-26 | H9: 3 months ago
A10: D | B10: OK | C10: =LEFT(F10,FIND(".",F10)-1) -> zjs_c_dmotreeteam | D10: {=INDEX('Not Req'!$E$4:$E$71,MATCH(MID(F10,FIND(".",F10)+1,LEN(F10)-FIND(".",F10)+1),'Not Req'!$D$4:$D$71,0))} -> Metadata | E10: =INDEX('Not Req'!$F$4:$F$71,MATCH(MID(F10,FIND(".",F10)+1,LEN(F10)-FIND(".",F10)+1),'Not Req'!$D$4:$D$71,0)) -> 4. CDS | F10: zjs_c_dmotreeteam.ddlx.asddlxs | G10: UPDATED ON 02-FEB-26 | H10: 3 months ago
A11: D | B11: OK | C11: =LEFT(F11,FIND(".",F11)-1) -> zjs_i_dmotreeteamhr | D11: {=INDEX('Not Req'!$E$4:$E$71,MATCH(MID(F11,FIND(".",F11)+1,LEN(F11)-FIND(".",F11)+1),'Not Req'!$D$4:$D$71,0))} -> Data Definition | E11: =INDEX('Not Req'!$F$4:$F$71,MATCH(MID(F11,FIND(".",F11)+1,LEN(F11)-FIND(".",F11)+1),'Not Req'!$D$4:$D$71,0)) -> 4. CDS | F11: zjs_i_dmotreeteamhr.ddls.asddls | G11: UPDATED ON 02-FEB-26 | H11: 3 months ago
A12: D | B12: OK | C12: =LEFT(F12,FIND(".",F12)-1) -> zjs_r_dmotreeteam | D12: {=INDEX('Not Req'!$E$4:$E$71,MATCH(MID(F12,FIND(".",F12)+1,LEN(F12)-FIND(".",F12)+1),'Not Req'!$D$4:$D$71,0))} -> BDEF | E12: =INDEX('Not Req'!$F$4:$F$71,MATCH(MID(F12,FIND(".",F12)+1,LEN(F12)-FIND(".",F12)+1),'Not Req'!$D$4:$D$71,0)) -> 4. CDS | F12: zjs_r_dmotreeteam.bdef.asbdef | G12: UPDATED ON 02-FEB-26 | H12: 3 months ago
A13: D | B13: OK | C13: =LEFT(F13,FIND(".",F13)-1) -> zjs_r_dmotreeteam | D13: {=INDEX('Not Req'!$E$4:$E$71,MATCH(MID(F13,FIND(".",F13)+1,LEN(F13)-FIND(".",F13)+1),'Not Req'!$D$4:$D$71,0))} -> Data Definition | E13: =INDEX('Not Req'!$F$4:$F$71,MATCH(MID(F13,FIND(".",F13)+1,LEN(F13)-FIND(".",F13)+1),'Not Req'!$D$4:$D$71,0)) -> 4. CDS | F13: zjs_r_dmotreeteam.ddls.asddls | G13: UPDATED ON 02-FEB-26 | H13: 3 months ago
A14: D | B14: OK | C14: =LEFT(F14,FIND(".",F14)-1) -> zjs_dmo_team_d | D14: {=INDEX('Not Req'!$E$4:$E$71,MATCH(MID(F14,FIND(".",F14)+1,LEN(F14)-FIND(".",F14)+1),'Not Req'!$D$4:$D$71,0))} -> Table | E14: =INDEX('Not Req'!$F$4:$F$71,MATCH(MID(F14,FIND(".",F14)+1,LEN(F14)-FIND(".",F14)+1),'Not Req'!$D$4:$D$71,0)) -> 5. Dictionary | F14: zjs_dmo_team_d.tabl.xml | G14: UPDATED ON 02-FEB-26 | H14: 3 months ago
A15: D | B15: OK | C15: =LEFT(F15,FIND(".",F15)-1) -> zbp_js_demo_tree_team | D15: {=INDEX('Not Req'!$E$4:$E$71,MATCH(MID(F15,FIND(".",F15)+1,LEN(F15)-FIND(".",F15)+1),'Not Req'!$D$4:$D$71,0))} -> Classes | E15: =INDEX('Not Req'!$F$4:$F$71,MATCH(MID(F15,FIND(".",F15)+1,LEN(F15)-FIND(".",F15)+1),'Not Req'!$D$4:$D$71,0)) -> 7. Source Code Library | F15: zbp_js_demo_tree_team.clas.abap | G15: Updated 16-Mar-26 | H15: 2 months ago
... A30: D | B30: OK | C30: =LEFT(F30,FIND(".",F30)-1) -> zjs_r_dmotreeteam | D30: {=INDEX('Not Req'!$E$4:$E$71,MATCH(MID(F30,FIND(".",F30)+1,LEN(F30)-FIND(".",F30)+1),'Not Req'!$D$4:$D$71,0))} -> Description : Data Definition | E30: =INDEX('Not Req'!$F$4:$F$71,MATCH(MID(F30,FIND(".",F30)+1,LEN(F30)-FIND(".",F30)+1),'Not Req'!$D$4:$D$71,0)) -> 99. Descriptions | F30: zjs_r_dmotreeteam.ddls.xml | G30: UPDATED ON 02-FEB-26 | H30: 3 months ago

Sheet ZJS_09_RAP_PATTERN_CDS
A2: d | B2: d | C2: Object | D2: Type | E2: Category | F2: Github Object | G2: Github Type | H2: Version
A4: D | B4: OK | C4: =LEFT(F4,FIND(".",F4)-1) -> 5d8914eb3ed982b15fb404c39f15c6ht | D4: {=INDEX('Not Req'!$E$4:$E$71,MATCH(MID(F4,FIND(".",F4)+1,LEN(F4)-FIND(".",F4)+1),'Not Req'!$D$4:$D$71,0))} -> Authorization Defaults (TADIR) | E4: =INDEX('Not Req'!$F$4:$F$71,MATCH(MID(F4,FIND(".",F4)+1,LEN(F4)-FIND(".",F4)+1),'Not Req'!$D$4:$D$71,0)) -> 1. Authorizations | F4: 5d8914eb3ed982b15fb404c39f15c6ht.sush.xml | G4: UPDATED ON 02-FEB-26 | H4: 3 months ago
A5: D | B5: OK | C5: =LEFT(F5,FIND(".",F5)-1) -> zjs_demo_pattern_cds | D5: {=INDEX('Not Req'!$E$4:$E$71,MATCH(MID(F5,FIND(".",F5)+1,LEN(F5)-FIND(".",F5)+1),'Not Req'!$D$4:$D$71,0))} -> Service Definition | E5: =INDEX('Not Req'!$F$4:$F$71,MATCH(MID(F5,FIND(".",F5)+1,LEN(F5)-FIND(".",F5)+1),'Not Req'!$D$4:$D$71,0)) -> 2. Business Services | F5: zjs_demo_pattern_cds.srvd.srvdsrv | G5: UPDATED ON 02-FEB-26 | H5: 3 months ago
A6: D | B6: OK | C6: =LEFT(F6,FIND(".",F6)-1) -> zjs_ui_demo_pattern_cds_o4 | D6: {=INDEX('Not Req'!$E$4:$E$71,MATCH(MID(F6,FIND(".",F6)+1,LEN(F6)-FIND(".",F6)+1),'Not Req'!$D$4:$D$71,0))} -> Service Binding | E6: =INDEX('Not Req'!$F$4:$F$71,MATCH(MID(F6,FIND(".",F6)+1,LEN(F6)-FIND(".",F6)+1),'Not Req'!$D$4:$D$71,0)) -> 2. Business Services | F6: zjs_ui_demo_pattern_cds_o4.srvb.xml | G6: UPDATED ON 02-FEB-26 | H6: 3 months ago
A7: D | B7: OK | C7: =LEFT(F7,FIND(".",F7)-1) -> zjs_ui_demo_pattern_cds_o4_0001_g4ba | D7: {=INDEX('Not Req'!$E$4:$E$71,MATCH(MID(F7,FIND(".",F7)+1,LEN(F7)-FIND(".",F7)+1),'Not Req'!$D$4:$D$71,0))} -> Inbound Service | E7: =INDEX('Not Req'!$F$4:$F$71,MATCH(MID(F7,FIND(".",F7)+1,LEN(F7)-FIND(".",F7)+1),'Not Req'!$D$4:$D$71,0)) -> 3. Cloud Communication Management | F7: zjs_ui_demo_pattern_cds_o4_0001_g4ba.sco2.xml | G7: UPDATED ON 02-FEB-26 | H7: 3 months ago
A8: D | B8: OK | C8: =LEFT(F8,FIND(".",F8)-1) -> zjs_c_cdspatterninvoice | D8: {=INDEX('Not Req'!$E$4:$E$71,MATCH(MID(F8,FIND(".",F8)+1,LEN(F8)-FIND(".",F8)+1),'Not Req'!$D$4:$D$71,0))} -> BDEF | E8: =INDEX('Not Req'!$F$4:$F$71,MATCH(MID(F8,FIND(".",F8)+1,LEN(F8)-FIND(".",F8)+1),'Not Req'!$D$4:$D$71,0)) -> 4. CDS | F8: zjs_c_cdspatterninvoice.bdef.asbdef | G8: UPDATED ON 02-FEB-26 | H8: 3 months ago
A9: D | B9: OK | C9: =LEFT(F9,FIND(".",F9)-1) -> zjs_c_cdspatterninvoice | D9: {=INDEX('Not Req'!$E$4:$E$71,MATCH(MID(F9,FIND(".",F9)+1,LEN(F9)-FIND(".",F9)+1),'Not Req'!$D$4:$D$71,0))} -> Data Definition | E9: =INDEX('Not Req'!$F$4:$F$71,MATCH(MID(F9,FIND(".",F9)+1,LEN(F9)-FIND(".",F9)+1),'Not Req'!$D$4:$D$71,0)) -> 4. CDS | F9: zjs_c_cdspatterninvoice.ddls.asddls | G9: UPDATED ON 02-FEB-26 | H9: 3 months ago
A10: D | B10: OK | C10: =LEFT(F10,FIND(".",F10)-1) -> zjs_c_cdspatterninvoice | D10: {=INDEX('Not Req'!$E$4:$E$71,MATCH(MID(F10,FIND(".",F10)+1,LEN(F10)-FIND(".",F10)+1),'Not Req'!$D$4:$D$71,0))} -> Metadata | E10: =INDEX('Not Req'!$F$4:$F$71,MATCH(MID(F10,FIND(".",F10)+1,LEN(F10)-FIND(".",F10)+1),'Not Req'!$D$4:$D$71,0)) -> 4. CDS | F10: zjs_c_cdspatterninvoice.ddlx.asddlxs | G10: UPDATED ON 02-FEB-26 | H10: 3 months ago
A11: D | B11: OK | C11: =LEFT(F11,FIND(".",F11)-1) -> zjs_c_cdspatternposition | D11: {=INDEX('Not Req'!$E$4:$E$71,MATCH(MID(F11,FIND(".",F11)+1,LEN(F11)-FIND(".",F11)+1),'Not Req'!$D$4:$D$71,0))} -> Data Definition | E11: =INDEX('Not Req'!$F$4:$F$71,MATCH(MID(F11,FIND(".",F11)+1,LEN(F11)-FIND(".",F11)+1),'Not Req'!$D$4:$D$71,0)) -> 4. CDS | F11: zjs_c_cdspatternposition.ddls.asddls | G11: UPDATED ON 02-FEB-26 | H11: 3 months ago
A12: D | B12: OK | C12: =LEFT(F12,FIND(".",F12)-1) -> zjs_c_cdspatternposition | D12: {=INDEX('Not Req'!$E$4:$E$71,MATCH(MID(F12,FIND(".",F12)+1,LEN(F12)-FIND(".",F12)+1),'Not Req'!$D$4:$D$71,0))} -> Metadata | E12: =INDEX('Not Req'!$F$4:$F$71,MATCH(MID(F12,FIND(".",F12)+1,LEN(F12)-FIND(".",F12)+1),'Not Req'!$D$4:$D$71,0)) -> 4. CDS | F12: zjs_c_cdspatternposition.ddlx.asddlxs | G12: UPDATED ON 02-FEB-26 | H12: 3 months ago
A13: D | B13: OK | C13: =LEFT(F13,FIND(".",F13)-1) -> zjs_t_cdspatterninvoice | D13: {=INDEX('Not Req'!$E$4:$E$71,MATCH(MID(F13,FIND(".",F13)+1,LEN(F13)-FIND(".",F13)+1),'Not Req'!$D$4:$D$71,0))} -> BDEF | E13: =INDEX('Not Req'!$F$4:$F$71,MATCH(MID(F13,FIND(".",F13)+1,LEN(F13)-FIND(".",F13)+1),'Not Req'!$D$4:$D$71,0)) -> 4. CDS | F13: zjs_t_cdspatterninvoice.bdef.asbdef | G13: UPDATED ON 02-FEB-26 | H13: 3 months ago
A14: D | B14: OK | C14: =LEFT(F14,FIND(".",F14)-1) -> zjs_t_cdspatterninvoice | D14: {=INDEX('Not Req'!$E$4:$E$71,MATCH(MID(F14,FIND(".",F14)+1,LEN(F14)-FIND(".",F14)+1),'Not Req'!$D$4:$D$71,0))} -> Data Definition | E14: =INDEX('Not Req'!$F$4:$F$71,MATCH(MID(F14,FIND(".",F14)+1,LEN(F14)-FIND(".",F14)+1),'Not Req'!$D$4:$D$71,0)) -> 4. CDS | F14: zjs_t_cdspatterninvoice.ddls.asddls | G14: UPDATED ON 02-FEB-26 | H14: 3 months ago
A15: D | B15: OK | C15: =LEFT(F15,FIND(".",F15)-1) -> zjs_t_cdspatternposition | D15: {=INDEX('Not Req'!$E$4:$E$71,MATCH(MID(F15,FIND(".",F15)+1,LEN(F15)-FIND(".",F15)+1),'Not Req'!$D$4:$D$71,0))} -> Data Definition | E15: =INDEX('Not Req'!$F$4:$F$71,MATCH(MID(F15,FIND(".",F15)+1,LEN(F15)-FIND(".",F15)+1),'Not Req'!$D$4:$D$71,0)) -> 4. CDS | F15: zjs_t_cdspatternposition.ddls.asddls | G15: UPDATED ON 02-FEB-26 | H15: 3 months ago
... A34: D | B34: OK | C34: =LEFT(F34,FIND(".",F34)-1) -> zjs_t_cdspatternposition | D34: {=INDEX('Not Req'!$E$4:$E$71,MATCH(MID(F34,FIND(".",F34)+1,LEN(F34)-FIND(".",F34)+1),'Not Req'!$D$4:$D$71,0))} -> Description : Data Definition | E34: =INDEX('Not Req'!$F$4:$F$71,MATCH(MID(F34,FIND(".",F34)+1,LEN(F34)-FIND(".",F34)+1),'Not Req'!$D$4:$D$71,0)) -> 99. Descriptions | F34: zjs_t_cdspatternposition.ddls.xml | G34: UPDATED ON 02-FEB-26 | H34: 3 months ago

Sheet ZJS_09_RAP_PATTERN_API
A2: d | B2: d | C2: Object | D2: Type | E2: Category | F2: Github Object | G2: Github Type | H2: Version
A4: D | B4: OK | C4: =LEFT(F4,FIND(".",F4)-1) -> 5ed994ae4fae30b6406c5a3621a7b3ht | D4: {=INDEX('Not Req'!$E$4:$E$71,MATCH(MID(F4,FIND(".",F4)+1,LEN(F4)-FIND(".",F4)+1),'Not Req'!$D$4:$D$71,0))} -> Authorization Defaults (TADIR) | E4: =INDEX('Not Req'!$F$4:$F$71,MATCH(MID(F4,FIND(".",F4)+1,LEN(F4)-FIND(".",F4)+1),'Not Req'!$D$4:$D$71,0)) -> 1. Authorizations | F4: 5ed994ae4fae30b6406c5a3621a7b3ht.sush.xml | G4: UPDATED ON 02-FEB-26 | H4: 3 months ago
A5: D | B5: OK | C5: =LEFT(F5,FIND(".",F5)-1) -> 7d403d38fb13b39a2c4a63ab3dee0fht | D5: {=INDEX('Not Req'!$E$4:$E$71,MATCH(MID(F5,FIND(".",F5)+1,LEN(F5)-FIND(".",F5)+1),'Not Req'!$D$4:$D$71,0))} -> Authorization Defaults (TADIR) | E5: =INDEX('Not Req'!$F$4:$F$71,MATCH(MID(F5,FIND(".",F5)+1,LEN(F5)-FIND(".",F5)+1),'Not Req'!$D$4:$D$71,0)) -> 1. Authorizations | F5: 7d403d38fb13b39a2c4a63ab3dee0fht.sush.xml | G5: UPDATED ON 02-FEB-26 | H5: 3 months ago
A6: D | B6: OK | C6: =LEFT(F6,FIND(".",F6)-1) -> zjs_api_location_endp_o2 | D6: {=INDEX('Not Req'!$E$4:$E$71,MATCH(MID(F6,FIND(".",F6)+1,LEN(F6)-FIND(".",F6)+1),'Not Req'!$D$4:$D$71,0))} -> Service Binding | E6: =INDEX('Not Req'!$F$4:$F$71,MATCH(MID(F6,FIND(".",F6)+1,LEN(F6)-FIND(".",F6)+1),'Not Req'!$D$4:$D$71,0)) -> 2. Business Services | F6: zjs_api_location_endp_o2.srvb.xml | G6: UPDATED ON 02-FEB-26 | H6: 3 months ago
A7: D | B7: OK | C7: =LEFT(F7,FIND(".",F7)-1) -> zjs_api_location_endpoint | D7: {=INDEX('Not Req'!$E$4:$E$71,MATCH(MID(F7,FIND(".",F7)+1,LEN(F7)-FIND(".",F7)+1),'Not Req'!$D$4:$D$71,0))} -> Service Definition | E7: =INDEX('Not Req'!$F$4:$F$71,MATCH(MID(F7,FIND(".",F7)+1,LEN(F7)-FIND(".",F7)+1),'Not Req'!$D$4:$D$71,0)) -> 2. Business Services | F7: zjs_api_location_endpoint.srvd.srvdsrv | G7: UPDATED ON 02-FEB-26 | H7: 3 months ago
A8: D | B8: OK | C8: =LEFT(F8,FIND(".",F8)-1) -> zjs_api_location_endp_o2_iwsg | D8: {=INDEX('Not Req'!$E$4:$E$71,MATCH(MID(F8,FIND(".",F8)+1,LEN(F8)-FIND(".",F8)+1),'Not Req'!$D$4:$D$71,0))} -> Inbound Service | E8: =INDEX('Not Req'!$F$4:$F$71,MATCH(MID(F8,FIND(".",F8)+1,LEN(F8)-FIND(".",F8)+1),'Not Req'!$D$4:$D$71,0)) -> 3. Cloud Communication Management | F8: zjs_api_location_endp_o2_iwsg.sco2.xml | G8: UPDATED ON 02-FEB-26 | H8: 3 months ago
A9: D | B9: OK | C9: =LEFT(F9,FIND(".",F9)-1) -> zjs_r_apilocation | D9: {=INDEX('Not Req'!$E$4:$E$71,MATCH(MID(F9,FIND(".",F9)+1,LEN(F9)-FIND(".",F9)+1),'Not Req'!$D$4:$D$71,0))} -> BDEF | E9: =INDEX('Not Req'!$F$4:$F$71,MATCH(MID(F9,FIND(".",F9)+1,LEN(F9)-FIND(".",F9)+1),'Not Req'!$D$4:$D$71,0)) -> 4. CDS | F9: zjs_r_apilocation.bdef.asbdef | G9: UPDATED ON 02-FEB-26 | H9: 3 months ago
A10: D | B10: OK | C10: =LEFT(F10,FIND(".",F10)-1) -> zjs_r_apilocation | D10: {=INDEX('Not Req'!$E$4:$E$71,MATCH(MID(F10,FIND(".",F10)+1,LEN(F10)-FIND(".",F10)+1),'Not Req'!$D$4:$D$71,0))} -> Data Definition | E10: =INDEX('Not Req'!$F$4:$F$71,MATCH(MID(F10,FIND(".",F10)+1,LEN(F10)-FIND(".",F10)+1),'Not Req'!$D$4:$D$71,0)) -> 4. CDS | F10: zjs_r_apilocation.ddls.asddls | G10: UPDATED ON 02-FEB-26 | H10: 3 months ago
A11: D | B11: OK | C11: =LEFT(F11,FIND(".",F11)-1) -> zjs_api_target | D11: {=INDEX('Not Req'!$E$4:$E$71,MATCH(MID(F11,FIND(".",F11)+1,LEN(F11)-FIND(".",F11)+1),'Not Req'!$D$4:$D$71,0))} -> Table | E11: =INDEX('Not Req'!$F$4:$F$71,MATCH(MID(F11,FIND(".",F11)+1,LEN(F11)-FIND(".",F11)+1),'Not Req'!$D$4:$D$71,0)) -> 5. Dictionary | F11: zjs_api_target.tabl.xml | G11: UPDATED ON 02-FEB-26 | H11: 3 months ago
A12: D | B12: OK | C12: =LEFT(F12,FIND(".",F12)-1) -> zbp_js_api_location | D12: {=INDEX('Not Req'!$E$4:$E$71,MATCH(MID(F12,FIND(".",F12)+1,LEN(F12)-FIND(".",F12)+1),'Not Req'!$D$4:$D$71,0))} -> Classes | E12: =INDEX('Not Req'!$F$4:$F$71,MATCH(MID(F12,FIND(".",F12)+1,LEN(F12)-FIND(".",F12)+1),'Not Req'!$D$4:$D$71,0)) -> 7. Source Code Library | F12: zbp_js_api_location.clas.abap | G12: Updated 16-Mar-26 | H12: 2 months ago
A13: D | B13: OK | C13: =LEFT(F13,FIND(".",F13)-1) -> zbp_js_api_location | D13: {=INDEX('Not Req'!$E$4:$E$71,MATCH(MID(F13,FIND(".",F13)+1,LEN(F13)-FIND(".",F13)+1),'Not Req'!$D$4:$D$71,0))} -> Classes Local | E13: =INDEX('Not Req'!$F$4:$F$71,MATCH(MID(F13,FIND(".",F13)+1,LEN(F13)-FIND(".",F13)+1),'Not Req'!$D$4:$D$71,0)) -> 7. Source Code Library | F13: zbp_js_api_location.clas.locals_imp.abap | G13: UPDATED ON 02-FEB-26 | H13: 3 months ago
A14: D | B14: OK | C14: =LEFT(F14,FIND(".",F14)-1) -> zcl_js_api_target | D14: {=INDEX('Not Req'!$E$4:$E$71,MATCH(MID(F14,FIND(".",F14)+1,LEN(F14)-FIND(".",F14)+1),'Not Req'!$D$4:$D$71,0))} -> Classes | E14: =INDEX('Not Req'!$F$4:$F$71,MATCH(MID(F14,FIND(".",F14)+1,LEN(F14)-FIND(".",F14)+1),'Not Req'!$D$4:$D$71,0)) -> 7. Source Code Library | F14: zcl_js_api_target.clas.abap | G14: Updated 16-Mar-26 | H14: 2 months ago
A15: D | B15: OK | C15: =LEFT(F15,FIND(".",F15)-1) -> zjs_r_apilocation | D15: {=INDEX('Not Req'!$E$4:$E$71,MATCH(MID(F15,FIND(".",F15)+1,LEN(F15)-FIND(".",F15)+1),'Not Req'!$D$4:$D$71,0))} -> BaseInfo : Data Definition | E15: =INDEX('Not Req'!$F$4:$F$71,MATCH(MID(F15,FIND(".",F15)+1,LEN(F15)-FIND(".",F15)+1),'Not Req'!$D$4:$D$71,0)) -> 98. Base Info | F15: zjs_r_apilocation.ddls.baseinfo | G15: UPDATED ON 02-FEB-26 | H15: 3 months ago
... A21: D | B21: OK | C21: =LEFT(F21,FIND(".",F21)-1) -> zjs_r_apilocation | D21: {=INDEX('Not Req'!$E$4:$E$71,MATCH(MID(F21,FIND(".",F21)+1,LEN(F21)-FIND(".",F21)+1),'Not Req'!$D$4:$D$71,0))} -> Description : Data Definition | E21: =INDEX('Not Req'!$F$4:$F$71,MATCH(MID(F21,FIND(".",F21)+1,LEN(F21)-FIND(".",F21)+1),'Not Req'!$D$4:$D$71,0)) -> 99. Descriptions | F21: zjs_r_apilocation.ddls.xml | G21: UPDATED ON 02-FEB-26 | H21: 3 months ago

Sheet ZJS_09_RAP_PATTERN_CUSTOM
A2: d | B2: d | C2: Object | D2: Type | E2: Category | F2: Github Object | G2: Github Type | H2: Version
A4: D | B4: OK | C4: =LEFT(F4,FIND(".",F4)-1) -> 2a6e0a4e80cd9ddbec9175325dbe71ht | D4: {=INDEX('Not Req'!$E$4:$E$71,MATCH(MID(F4,FIND(".",F4)+1,LEN(F4)-FIND(".",F4)+1),'Not Req'!$D$4:$D$71,0))} -> Authorization Defaults (TADIR) | E4: =INDEX('Not Req'!$F$4:$F$71,MATCH(MID(F4,FIND(".",F4)+1,LEN(F4)-FIND(".",F4)+1),'Not Req'!$D$4:$D$71,0)) -> 1. Authorizations | F4: 2a6e0a4e80cd9ddbec9175325dbe71ht.sush.xml | G4: UPDATED ON 02-FEB-26 | H4: 3 months ago
A5: D | B5: OK | C5: =LEFT(F5,FIND(".",F5)-1) -> 2b71dbe296db14ddca698f77f6332eht | D5: {=INDEX('Not Req'!$E$4:$E$71,MATCH(MID(F5,FIND(".",F5)+1,LEN(F5)-FIND(".",F5)+1),'Not Req'!$D$4:$D$71,0))} -> Authorization Defaults (TADIR) | E5: =INDEX('Not Req'!$F$4:$F$71,MATCH(MID(F5,FIND(".",F5)+1,LEN(F5)-FIND(".",F5)+1),'Not Req'!$D$4:$D$71,0)) -> 1. Authorizations | F5: 2b71dbe296db14ddca698f77f6332eht.sush.xml | G5: UPDATED ON 02-FEB-26 | H5: 3 months ago
A6: D | B6: OK | C6: =LEFT(F6,FIND(".",F6)-1) -> eb3ab26380a1c48a15e0dd9f2a3f97ht | D6: {=INDEX('Not Req'!$E$4:$E$71,MATCH(MID(F6,FIND(".",F6)+1,LEN(F6)-FIND(".",F6)+1),'Not Req'!$D$4:$D$71,0))} -> Authorization Defaults (TADIR) | E6: =INDEX('Not Req'!$F$4:$F$71,MATCH(MID(F6,FIND(".",F6)+1,LEN(F6)-FIND(".",F6)+1),'Not Req'!$D$4:$D$71,0)) -> 1. Authorizations | F6: eb3ab26380a1c48a15e0dd9f2a3f97ht.sush.xml | G6: UPDATED ON 02-FEB-26 | H6: 3 months ago
A7: D | B7: OK | C7: =LEFT(F7,FIND(".",F7)-1) -> zjs_dcp_swc | D7: {=INDEX('Not Req'!$E$4:$E$71,MATCH(MID(F7,FIND(".",F7)+1,LEN(F7)-FIND(".",F7)+1),'Not Req'!$D$4:$D$71,0))} -> Service Definition | E7: =INDEX('Not Req'!$F$4:$F$71,MATCH(MID(F7,FIND(".",F7)+1,LEN(F7)-FIND(".",F7)+1),'Not Req'!$D$4:$D$71,0)) -> 2. Business Services | F7: zjs_dcp_swc.srvd.srvdsrv | G7: UPDATED ON 02-FEB-26 | H7: 3 months ago
A8: D | B8: OK | C8: =LEFT(F8,FIND(".",F8)-1) -> zjs_ui_dcp_swc_o2 | D8: {=INDEX('Not Req'!$E$4:$E$71,MATCH(MID(F8,FIND(".",F8)+1,LEN(F8)-FIND(".",F8)+1),'Not Req'!$D$4:$D$71,0))} -> Service Binding | E8: =INDEX('Not Req'!$F$4:$F$71,MATCH(MID(F8,FIND(".",F8)+1,LEN(F8)-FIND(".",F8)+1),'Not Req'!$D$4:$D$71,0)) -> 2. Business Services | F8: zjs_ui_dcp_swc_o2.srvb.xml | G8: UPDATED ON 02-FEB-26 | H8: 3 months ago
A9: D | B9: OK | C9: =LEFT(F9,FIND(".",F9)-1) -> zjs_ui_dcp_swc_o4 | D9: {=INDEX('Not Req'!$E$4:$E$71,MATCH(MID(F9,FIND(".",F9)+1,LEN(F9)-FIND(".",F9)+1),'Not Req'!$D$4:$D$71,0))} -> Service Binding | E9: =INDEX('Not Req'!$F$4:$F$71,MATCH(MID(F9,FIND(".",F9)+1,LEN(F9)-FIND(".",F9)+1),'Not Req'!$D$4:$D$71,0)) -> 2. Business Services | F9: zjs_ui_dcp_swc_o4.srvb.xml | G9: UPDATED ON 02-FEB-26 | H9: 3 months ago
A10: D | B10: OK | C10: =LEFT(F10,FIND(".",F10)-1) -> zjs_ui_dcp_swc_o2_iwsg | D10: {=INDEX('Not Req'!$E$4:$E$71,MATCH(MID(F10,FIND(".",F10)+1,LEN(F10)-FIND(".",F10)+1),'Not Req'!$D$4:$D$71,0))} -> Inbound Service | E10: =INDEX('Not Req'!$F$4:$F$71,MATCH(MID(F10,FIND(".",F10)+1,LEN(F10)-FIND(".",F10)+1),'Not Req'!$D$4:$D$71,0)) -> 3. Cloud Communication Management | F10: zjs_ui_dcp_swc_o2_iwsg.sco2.xml | G10: UPDATED ON 02-FEB-26 | H10: 3 months ago
A11: D | B11: OK | C11: =LEFT(F11,FIND(".",F11)-1) -> zjs_ui_dcp_swc_o4_0001_g4ba | D11: {=INDEX('Not Req'!$E$4:$E$71,MATCH(MID(F11,FIND(".",F11)+1,LEN(F11)-FIND(".",F11)+1),'Not Req'!$D$4:$D$71,0))} -> Inbound Service | E11: =INDEX('Not Req'!$F$4:$F$71,MATCH(MID(F11,FIND(".",F11)+1,LEN(F11)-FIND(".",F11)+1),'Not Req'!$D$4:$D$71,0)) -> 3. Cloud Communication Management | F11: zjs_ui_dcp_swc_o4_0001_g4ba.sco2.xml | G11: UPDATED ON 02-FEB-26 | H11: 3 months ago
A12: D | B12: OK | C12: =LEFT(F12,FIND(".",F12)-1) -> zjs_i_cpstagingvh | D12: {=INDEX('Not Req'!$E$4:$E$71,MATCH(MID(F12,FIND(".",F12)+1,LEN(F12)-FIND(".",F12)+1),'Not Req'!$D$4:$D$71,0))} -> Data Definition | E12: =INDEX('Not Req'!$F$4:$F$71,MATCH(MID(F12,FIND(".",F12)+1,LEN(F12)-FIND(".",F12)+1),'Not Req'!$D$4:$D$71,0)) -> 4. CDS | F12: zjs_i_cpstagingvh.ddls.asddls | G12: UPDATED ON 02-FEB-26 | H12: 3 months ago
A13: D | B13: OK | C13: =LEFT(F13,FIND(".",F13)-1) -> zjs_i_dcpapplicationvh | D13: {=INDEX('Not Req'!$E$4:$E$71,MATCH(MID(F13,FIND(".",F13)+1,LEN(F13)-FIND(".",F13)+1),'Not Req'!$D$4:$D$71,0))} -> Data Definition | E13: =INDEX('Not Req'!$F$4:$F$71,MATCH(MID(F13,FIND(".",F13)+1,LEN(F13)-FIND(".",F13)+1),'Not Req'!$D$4:$D$71,0)) -> 4. CDS | F13: zjs_i_dcpapplicationvh.ddls.asddls | G13: UPDATED ON 02-FEB-26 | H13: 3 months ago
A14: D | B14: OK | C14: =LEFT(F14,FIND(".",F14)-1) -> zjs_i_dcpteamvh | D14: {=INDEX('Not Req'!$E$4:$E$71,MATCH(MID(F14,FIND(".",F14)+1,LEN(F14)-FIND(".",F14)+1),'Not Req'!$D$4:$D$71,0))} -> Data Definition | E14: =INDEX('Not Req'!$F$4:$F$71,MATCH(MID(F14,FIND(".",F14)+1,LEN(F14)-FIND(".",F14)+1),'Not Req'!$D$4:$D$71,0)) -> 4. CDS | F14: zjs_i_dcpteamvh.ddls.asddls | G14: UPDATED ON 02-FEB-26 | H14: 3 months ago
A15: D | B15: OK | C15: =LEFT(F15,FIND(".",F15)-1) -> zjs_r_dcpsoftwarecomponent | D15: {=INDEX('Not Req'!$E$4:$E$71,MATCH(MID(F15,FIND(".",F15)+1,LEN(F15)-FIND(".",F15)+1),'Not Req'!$D$4:$D$71,0))} -> BDEF | E15: =INDEX('Not Req'!$F$4:$F$71,MATCH(MID(F15,FIND(".",F15)+1,LEN(F15)-FIND(".",F15)+1),'Not Req'!$D$4:$D$71,0)) -> 4. CDS | F15: zjs_r_dcpsoftwarecomponent.bdef.asbdef | G15: UPDATED ON 02-FEB-26 | H15: 3 months ago
... A43: D | B43: OK | C43: =LEFT(F43,FIND(".",F43)-1) -> zjs_r_dcpsoftwarecomponent | D43: {=INDEX('Not Req'!$E$4:$E$71,MATCH(MID(F43,FIND(".",F43)+1,LEN(F43)-FIND(".",F43)+1),'Not Req'!$D$4:$D$71,0))} -> Description : Data Definition | E43: =INDEX('Not Req'!$F$4:$F$71,MATCH(MID(F43,FIND(".",F43)+1,LEN(F43)-FIND(".",F43)+1),'Not Req'!$D$4:$D$71,0)) -> 99. Descriptions | F43: zjs_r_dcpsoftwarecomponent.ddls.xml | G43: UPDATED ON 02-FEB-26 | H43: 3 months ago

Sheet ZJS_09_RAP_PATTERN_REPORT
A2: d | B2: d | C2: Object | D2: Type | E2: Category | F2: Github Object | G2: Github Type | H2: Version
A4: D | B4: OK | C4: =LEFT(F4,FIND(".",F4)-1) -> a318ec063e2b8d8e656eadc8082fd2ht | D4: {=INDEX('Not Req'!$E$4:$E$71,MATCH(MID(F4,FIND(".",F4)+1,LEN(F4)-FIND(".",F4)+1),'Not Req'!$D$4:$D$71,0))} -> Authorization Defaults (TADIR) | E4: =INDEX('Not Req'!$F$4:$F$71,MATCH(MID(F4,FIND(".",F4)+1,LEN(F4)-FIND(".",F4)+1),'Not Req'!$D$4:$D$71,0)) -> 1. Authorizations | F4: a318ec063e2b8d8e656eadc8082fd2ht.sush.xml | G4: UPDATED ON 02-FEB-26 | H4: 3 months ago | N4: {=_xlfn.UNIQUE(C4:C20)} -> a318ec063e2b8d8e656eadc8082fd2ht
A5: D | B5: OK | C5: =LEFT(F5,FIND(".",F5)-1) -> zjs_demo_drp_currency | D5: {=INDEX('Not Req'!$E$4:$E$71,MATCH(MID(F5,FIND(".",F5)+1,LEN(F5)-FIND(".",F5)+1),'Not Req'!$D$4:$D$71,0))} -> Service Definition | E5: =INDEX('Not Req'!$F$4:$F$71,MATCH(MID(F5,FIND(".",F5)+1,LEN(F5)-FIND(".",F5)+1),'Not Req'!$D$4:$D$71,0)) -> 2. Business Services | F5: zjs_demo_drp_currency.srvd.srvdsrv | G5: UPDATED ON 02-FEB-26 | H5: 3 months ago | N5: zjs_demo_drp_currency
A6: D | B6: OK | C6: =LEFT(F6,FIND(".",F6)-1) -> zjs_ui_demo_drp_currency_o4 | D6: {=INDEX('Not Req'!$E$4:$E$71,MATCH(MID(F6,FIND(".",F6)+1,LEN(F6)-FIND(".",F6)+1),'Not Req'!$D$4:$D$71,0))} -> Service Binding | E6: =INDEX('Not Req'!$F$4:$F$71,MATCH(MID(F6,FIND(".",F6)+1,LEN(F6)-FIND(".",F6)+1),'Not Req'!$D$4:$D$71,0)) -> 2. Business Services | F6: zjs_ui_demo_drp_currency_o4.srvb.xml | G6: UPDATED ON 02-FEB-26 | H6: 3 months ago | N6: zjs_ui_demo_drp_currency_o4
A7: D | B7: OK | C7: =LEFT(F7,FIND(".",F7)-1) -> zjs_ui_demo_drp_currency_o4_0001_g4ba | D7: {=INDEX('Not Req'!$E$4:$E$71,MATCH(MID(F7,FIND(".",F7)+1,LEN(F7)-FIND(".",F7)+1),'Not Req'!$D$4:$D$71,0))} -> Inbound Service | E7: =INDEX('Not Req'!$F$4:$F$71,MATCH(MID(F7,FIND(".",F7)+1,LEN(F7)-FIND(".",F7)+1),'Not Req'!$D$4:$D$71,0)) -> 3. Cloud Communication Management | F7: zjs_ui_demo_drp_currency_o4_0001_g4ba.sco2.xml | G7: UPDATED ON 02-FEB-26 | H7: 3 months ago | N7: zjs_ui_demo_drp_currency_o4_0001_g4ba
A8: D | B8: OK | C8: =LEFT(F8,FIND(".",F8)-1) -> zjs_b_drpadditionalcurrency | D8: {=INDEX('Not Req'!$E$4:$E$71,MATCH(MID(F8,FIND(".",F8)+1,LEN(F8)-FIND(".",F8)+1),'Not Req'!$D$4:$D$71,0))} -> Data Definition | E8: =INDEX('Not Req'!$F$4:$F$71,MATCH(MID(F8,FIND(".",F8)+1,LEN(F8)-FIND(".",F8)+1),'Not Req'!$D$4:$D$71,0)) -> 4. CDS | F8: zjs_b_drpadditionalcurrency.ddls.asddls | G8: UPDATED ON 02-FEB-26 | H8: 3 months ago | N8: zjs_b_drpadditionalcurrency
A9: D | B9: OK | C9: =LEFT(F9,FIND(".",F9)-1) -> zjs_b_drpcurrencycountry | D9: {=INDEX('Not Req'!$E$4:$E$71,MATCH(MID(F9,FIND(".",F9)+1,LEN(F9)-FIND(".",F9)+1),'Not Req'!$D$4:$D$71,0))} -> Data Definition | E9: =INDEX('Not Req'!$F$4:$F$71,MATCH(MID(F9,FIND(".",F9)+1,LEN(F9)-FIND(".",F9)+1),'Not Req'!$D$4:$D$71,0)) -> 4. CDS | F9: zjs_b_drpcurrencycountry.ddls.asddls | G9: UPDATED ON 02-FEB-26 | H9: 3 months ago | N9: zjs_b_drpcurrencycountry
