Workbook

Sheet RAP Sales
B2: d | C2: Object | D2: Type | E2: Category | F2: Github Object | G2: Github Type | H2: Version
B4: 1 | C4: =LEFT(F4,FIND(".",F4)-1) -> package | D4: {=INDEX('Not Req'!$E$4:$E$72,MATCH(MID(F4,FIND(".",F4)+1,LEN(F4)-FIND(".",F4)+1),'Not Req'!$D$4:$D$72,0))} -> Description : Package | E4: =INDEX('Not Req'!$F$4:$F$72,MATCH(MID(F4,FIND(".",F4)+1,LEN(F4)-FIND(".",F4)+1),'Not Req'!$D$4:$D$72,0)) -> 0. Package | F4: package.devc.xml | G4: Sales configuration | H4: 3 weeks ago | N4: {=_xlfn.UNIQUE(C4:C21)} -> package
C5: =LEFT(F5,FIND(".",F5)-1) -> zbs_demo_sa_amount | D5: {=INDEX('Not Req'!$E$4:$E$72,MATCH(MID(F5,FIND(".",F5)+1,LEN(F5)-FIND(".",F5)+1),'Not Req'!$D$4:$D$72,0))} -> Data Element | E5: =INDEX('Not Req'!$F$4:$F$72,MATCH(MID(F5,FIND(".",F5)+1,LEN(F5)-FIND(".",F5)+1),'Not Req'!$D$4:$D$72,0)) -> 1. Dictionary | F5: zbs_demo_sa_amount.dtel.xml | G5: Sale App Creation | H5: 2 weeks ago | N5: zbs_demo_sa_amount
C6: =LEFT(F6,FIND(".",F6)-1) -> zbs_demo_sa_comment | D6: {=INDEX('Not Req'!$E$4:$E$72,MATCH(MID(F6,FIND(".",F6)+1,LEN(F6)-FIND(".",F6)+1),'Not Req'!$D$4:$D$72,0))} -> Data Element | E6: =INDEX('Not Req'!$F$4:$F$72,MATCH(MID(F6,FIND(".",F6)+1,LEN(F6)-FIND(".",F6)+1),'Not Req'!$D$4:$D$72,0)) -> 1. Dictionary | F6: zbs_demo_sa_comment.dtel.xml | G6: Sale App Creation | H6: 2 weeks ago | N6: zbs_demo_sa_comment
C7: =LEFT(F7,FIND(".",F7)-1) -> zbs_demo_sa_currency | D7: {=INDEX('Not Req'!$E$4:$E$72,MATCH(MID(F7,FIND(".",F7)+1,LEN(F7)-FIND(".",F7)+1),'Not Req'!$D$4:$D$72,0))} -> Data Element | E7: =INDEX('Not Req'!$F$4:$F$72,MATCH(MID(F7,FIND(".",F7)+1,LEN(F7)-FIND(".",F7)+1),'Not Req'!$D$4:$D$72,0)) -> 1. Dictionary | F7: zbs_demo_sa_currency.dtel.xml | G7: Sale App Creation | H7: 2 weeks ago | N7: zbs_demo_sa_currency
C8: =LEFT(F8,FIND(".",F8)-1) -> zbs_demo_sa_date | D8: {=INDEX('Not Req'!$E$4:$E$72,MATCH(MID(F8,FIND(".",F8)+1,LEN(F8)-FIND(".",F8)+1),'Not Req'!$D$4:$D$72,0))} -> Data Element | E8: =INDEX('Not Req'!$F$4:$F$72,MATCH(MID(F8,FIND(".",F8)+1,LEN(F8)-FIND(".",F8)+1),'Not Req'!$D$4:$D$72,0)) -> 1. Dictionary | F8: zbs_demo_sa_date.dtel.xml | G8: Sale App Creation | H8: 2 weeks ago | N8: zbs_demo_sa_date
C9: =LEFT(F9,FIND(".",F9)-1) -> zbs_demo_sa_material | D9: {=INDEX('Not Req'!$E$4:$E$72,MATCH(MID(F9,FIND(".",F9)+1,LEN(F9)-FIND(".",F9)+1),'Not Req'!$D$4:$D$72,0))} -> Data Element | E9: =INDEX('Not Req'!$F$4:$F$72,MATCH(MID(F9,FIND(".",F9)+1,LEN(F9)-FIND(".",F9)+1),'Not Req'!$D$4:$D$72,0)) -> 1. Dictionary | F9: zbs_demo_sa_material.dtel.xml | G9: Sale App Creation | H9: 2 weeks ago | N9: zbs_demo_sa_material
C10: =LEFT(F10,FIND(".",F10)-1) -> zbs_demo_sa_partner | D10: {=INDEX('Not Req'!$E$4:$E$72,MATCH(MID(F10,FIND(".",F10)+1,LEN(F10)-FIND(".",F10)+1),'Not Req'!$D$4:$D$72,0))} -> Data Element | E10: =INDEX('Not Req'!$F$4:$F$72,MATCH(MID(F10,FIND(".",F10)+1,LEN(F10)-FIND(".",F10)+1),'Not Req'!$D$4:$D$72,0)) -> 1. Dictionary | F10: zbs_demo_sa_partner.dtel.xml | G10: Sale App Creation | H10: 2 weeks ago | N10: zbs_demo_sa_partner
C11: =LEFT(F11,FIND(".",F11)-1) -> zbs_demo_sa_quantity | D11: {=INDEX('Not Req'!$E$4:$E$72,MATCH(MID(F11,FIND(".",F11)+1,LEN(F11)-FIND(".",F11)+1),'Not Req'!$D$4:$D$72,0))} -> Data Element | E11: =INDEX('Not Req'!$F$4:$F$72,MATCH(MID(F11,FIND(".",F11)+1,LEN(F11)-FIND(".",F11)+1),'Not Req'!$D$4:$D$72,0)) -> 1. Dictionary | F11: zbs_demo_sa_quantity.dtel.xml | G11: Sale App Creation | H11: 2 weeks ago | N11: zbs_demo_sa_quantity
C12: =LEFT(F12,FIND(".",F12)-1) -> zbs_demo_sa_quota | D12: {=INDEX('Not Req'!$E$4:$E$72,MATCH(MID(F12,FIND(".",F12)+1,LEN(F12)-FIND(".",F12)+1),'Not Req'!$D$4:$D$72,0))} -> Data Element | E12: =INDEX('Not Req'!$F$4:$F$72,MATCH(MID(F12,FIND(".",F12)+1,LEN(F12)-FIND(".",F12)+1),'Not Req'!$D$4:$D$72,0)) -> 1. Dictionary | F12: zbs_demo_sa_quota.dtel.xml | G12: Sale App Creation | H12: 2 weeks ago | N12: zbs_demo_sa_quota
C13: =LEFT(F13,FIND(".",F13)-1) -> zbs_demo_sa_text | D13: {=INDEX('Not Req'!$E$4:$E$72,MATCH(MID(F13,FIND(".",F13)+1,LEN(F13)-FIND(".",F13)+1),'Not Req'!$D$4:$D$72,0))} -> Data Element | E13: =INDEX('Not Req'!$F$4:$F$72,MATCH(MID(F13,FIND(".",F13)+1,LEN(F13)-FIND(".",F13)+1),'Not Req'!$D$4:$D$72,0)) -> 1. Dictionary | F13: zbs_demo_sa_text.dtel.xml | G13: Sale App Creation | H13: 2 weeks ago | N13: zbs_demo_sa_text
C14: =LEFT(F14,FIND(".",F14)-1) -> zbs_demo_sa_unit | D14: {=INDEX('Not Req'!$E$4:$E$72,MATCH(MID(F14,FIND(".",F14)+1,LEN(F14)-FIND(".",F14)+1),'Not Req'!$D$4:$D$72,0))} -> Data Element | E14: =INDEX('Not Req'!$F$4:$F$72,MATCH(MID(F14,FIND(".",F14)+1,LEN(F14)-FIND(".",F14)+1),'Not Req'!$D$4:$D$72,0)) -> 1. Dictionary | F14: zbs_demo_sa_unit.dtel.xml | G14: Sale App Creation | H14: 2 weeks ago | N14: zbs_demo_sa_unit
C15: =LEFT(F15,FIND(".",F15)-1) -> zbs_demo_sa_user | D15: {=INDEX('Not Req'!$E$4:$E$72,MATCH(MID(F15,FIND(".",F15)+1,LEN(F15)-FIND(".",F15)+1),'Not Req'!$D$4:$D$72,0))} -> Data Element | E15: =INDEX('Not Req'!$F$4:$F$72,MATCH(MID(F15,FIND(".",F15)+1,LEN(F15)-FIND(".",F15)+1),'Not Req'!$D$4:$D$72,0)) -> 1. Dictionary | F15: zbs_demo_sa_user.dtel.xml | G15: Sale App Creation | H15: 2 weeks ago | N15: zbs_demo_sa_user
C16: =LEFT(F16,FIND(".",F16)-1) -> zbs_demo_sa_amount | D16: {=INDEX('Not Req'!$E$4:$E$72,MATCH(MID(F16,FIND(".",F16)+1,LEN(F16)-FIND(".",F16)+1),'Not Req'!$D$4:$D$72,0))} -> Domain | E16: =INDEX('Not Req'!$F$4:$F$72,MATCH(MID(F16,FIND(".",F16)+1,LEN(F16)-FIND(".",F16)+1),'Not Req'!$D$4:$D$72,0)) -> 1. Dictionary | F16: zbs_demo_sa_amount.doma.xml | G16: Sale App Creation | H16: 2 weeks ago
C17: =LEFT(F17,FIND(".",F17)-1) -> zbs_demo_sa_comment | D17: {=INDEX('Not Req'!$E$4:$E$72,MATCH(MID(F17,FIND(".",F17)+1,LEN(F17)-FIND(".",F17)+1),'Not Req'!$D$4:$D$72,0))} -> Domain | E17: =INDEX('Not Req'!$F$4:$F$72,MATCH(MID(F17,FIND(".",F17)+1,LEN(F17)-FIND(".",F17)+1),'Not Req'!$D$4:$D$72,0)) -> 1. Dictionary | F17: zbs_demo_sa_comment.doma.xml | G17: Sale App Creation | H17: 2 weeks ago
C18: =LEFT(F18,FIND(".",F18)-1) -> zbs_demo_sa_currency | D18: {=INDEX('Not Req'!$E$4:$E$72,MATCH(MID(F18,FIND(".",F18)+1,LEN(F18)-FIND(".",F18)+1),'Not Req'!$D$4:$D$72,0))} -> Domain | E18: =INDEX('Not Req'!$F$4:$F$72,MATCH(MID(F18,FIND(".",F18)+1,LEN(F18)-FIND(".",F18)+1),'Not Req'!$D$4:$D$72,0)) -> 1. Dictionary | F18: zbs_demo_sa_currency.doma.xml | G18: Sale App Creation | H18: 2 weeks ago
C19: =LEFT(F19,FIND(".",F19)-1) -> zbs_demo_sa_date | D19: {=INDEX('Not Req'!$E$4:$E$72,MATCH(MID(F19,FIND(".",F19)+1,LEN(F19)-FIND(".",F19)+1),'Not Req'!$D$4:$D$72,0))} -> Domain | E19: =INDEX('Not Req'!$F$4:$F$72,MATCH(MID(F19,FIND(".",F19)+1,LEN(F19)-FIND(".",F19)+1),'Not Req'!$D$4:$D$72,0)) -> 1. Dictionary | F19: zbs_demo_sa_date.doma.xml | G19: Sale App Creation | H19: 2 weeks ago
C20: =LEFT(F20,FIND(".",F20)-1) -> zbs_demo_sa_material | D20: {=INDEX('Not Req'!$E$4:$E$72,MATCH(MID(F20,FIND(".",F20)+1,LEN(F20)-FIND(".",F20)+1),'Not Req'!$D$4:$D$72,0))} -> Domain | E20: =INDEX('Not Req'!$F$4:$F$72,MATCH(MID(F20,FIND(".",F20)+1,LEN(F20)-FIND(".",F20)+1),'Not Req'!$D$4:$D$72,0)) -> 1. Dictionary | F20: zbs_demo_sa_material.doma.xml | G20: Sale App Creation | H20: 2 weeks ago
C21: =LEFT(F21,FIND(".",F21)-1) -> zbs_demo_sa_partner | D21: {=INDEX('Not Req'!$E$4:$E$72,MATCH(MID(F21,FIND(".",F21)+1,LEN(F21)-FIND(".",F21)+1),'Not Req'!$D$4:$D$72,0))} -> Domain | E21: =INDEX('Not Req'!$F$4:$F$72,MATCH(MID(F21,FIND(".",F21)+1,LEN(F21)-FIND(".",F21)+1),'Not Req'!$D$4:$D$72,0)) -> 1. Dictionary | F21: zbs_demo_sa_partner.doma.xml | G21: Sale App Creation | H21: 2 weeks ago
C22: =LEFT(F22,FIND(".",F22)-1) -> zbs_demo_sa_quantity | D22: {=INDEX('Not Req'!$E$4:$E$72,MATCH(MID(F22,FIND(".",F22)+1,LEN(F22)-FIND(".",F22)+1),'Not Req'!$D$4:$D$72,0))} -> Domain | E22: =INDEX('Not Req'!$F$4:$F$72,MATCH(MID(F22,FIND(".",F22)+1,LEN(F22)-FIND(".",F22)+1),'Not Req'!$D$4:$D$72,0)) -> 1. Dictionary | F22: zbs_demo_sa_quantity.doma.xml | G22: Sale App Creation | H22: 2 weeks ago
C23: =LEFT(F23,FIND(".",F23)-1) -> zbs_demo_sa_quota | D23: {=INDEX('Not Req'!$E$4:$E$72,MATCH(MID(F23,FIND(".",F23)+1,LEN(F23)-FIND(".",F23)+1),'Not Req'!$D$4:$D$72,0))} -> Domain | E23: =INDEX('Not Req'!$F$4:$F$72,MATCH(MID(F23,FIND(".",F23)+1,LEN(F23)-FIND(".",F23)+1),'Not Req'!$D$4:$D$72,0)) -> 1. Dictionary | F23: zbs_demo_sa_quota.doma.xml | G23: Sale App Creation | H23: 2 weeks ago
C24: =LEFT(F24,FIND(".",F24)-1) -> zbs_demo_sa_text | D24: {=INDEX('Not Req'!$E$4:$E$72,MATCH(MID(F24,FIND(".",F24)+1,LEN(F24)-FIND(".",F24)+1),'Not Req'!$D$4:$D$72,0))} -> Domain | E24: =INDEX('Not Req'!$F$4:$F$72,MATCH(MID(F24,FIND(".",F24)+1,LEN(F24)-FIND(".",F24)+1),'Not Req'!$D$4:$D$72,0)) -> 1. Dictionary | F24: zbs_demo_sa_text.doma.xml | G24: Sale App Creation | H24: 2 weeks ago
C25: =LEFT(F25,FIND(".",F25)-1) -> zbs_demo_sa_unit | D25: {=INDEX('Not Req'!$E$4:$E$72,MATCH(MID(F25,FIND(".",F25)+1,LEN(F25)-FIND(".",F25)+1),'Not Req'!$D$4:$D$72,0))} -> Domain | E25: =INDEX('Not Req'!$F$4:$F$72,MATCH(MID(F25,FIND(".",F25)+1,LEN(F25)-FIND(".",F25)+1),'Not Req'!$D$4:$D$72,0)) -> 1. Dictionary | F25: zbs_demo_sa_unit.doma.xml | G25: Sale App Creation | H25: 2 weeks ago
C26: =LEFT(F26,FIND(".",F26)-1) -> zbs_demo_sa_user | D26: {=INDEX('Not Req'!$E$4:$E$72,MATCH(MID(F26,FIND(".",F26)+1,LEN(F26)-FIND(".",F26)+1),'Not Req'!$D$4:$D$72,0))} -> Domain | E26: =INDEX('Not Req'!$F$4:$F$72,MATCH(MID(F26,FIND(".",F26)+1,LEN(F26)-FIND(".",F26)+1),'Not Req'!$D$4:$D$72,0)) -> 1. Dictionary | F26: zbs_demo_sa_user.doma.xml | G26: Sale App Creation | H26: 2 weeks ago
C27: =LEFT(F27,FIND(".",F27)-1) -> zbs_sainfo | D27: {=INDEX('Not Req'!$E$4:$E$72,MATCH(MID(F27,FIND(".",F27)+1,LEN(F27)-FIND(".",F27)+1),'Not Req'!$D$4:$D$72,0))} -> Table | E27: =INDEX('Not Req'!$F$4:$F$72,MATCH(MID(F27,FIND(".",F27)+1,LEN(F27)-FIND(".",F27)+1),'Not Req'!$D$4:$D$72,0)) -> 1. Dictionary | F27: zbs_sainfo.tabl.xml | G27: Sale App Creation | H27: 2 weeks ago
... C118: =LEFT(F118,FIND(".",F118)-1) -> zbs_globalsale | D118: {=INDEX('Not Req'!$E$4:$E$72,MATCH(MID(F118,FIND(".",F118)+1,LEN(F118)-FIND(".",F118)+1),'Not Req'!$D$4:$D$72,0))} -> #N/A | E118: =INDEX('Not Req'!$F$4:$F$72,MATCH(MID(F118,FIND(".",F118)+1,LEN(F118)-FIND(".",F118)+1),'Not Req'!$D$4:$D$72,0)) -> #N/A | F118: zbs_globalsale.nont.json | G118: Sale App Creation | H118: 2 weeks ago
A119: d | B119: d | C119: =LEFT(F119,FIND(".",F119)-1) -> zbs_globalsale | D119: {=INDEX('Not Req'!$E$4:$E$72,MATCH(MID(F119,FIND(".",F119)+1,LEN(F119)-FIND(".",F119)+1),'Not Req'!$D$4:$D$72,0))} -> #N/A | E119: =INDEX('Not Req'!$F$4:$F$72,MATCH(MID(F119,FIND(".",F119)+1,LEN(F119)-FIND(".",F119)+1),'Not Req'!$D$4:$D$72,0)) -> #N/A | F119: zbs_globalsale.ront.json | G119: Sale App Creation | H119: 2 weeks ago

Sheet CUSTOM ACTION
B2: d | C2: Object | D2: Type | E2: Category | F2: Github Object | G2: Github Type | H2: Version
B4: 1 | C4: =LEFT(F4,FIND(".",F4)-1) -> package | D4: {=INDEX('Not Req'!$E$4:$E$72,MATCH(MID(F4,FIND(".",F4)+1,LEN(F4)-FIND(".",F4)+1),'Not Req'!$D$4:$D$72,0))} -> Description : Package | E4: =INDEX('Not Req'!$F$4:$F$72,MATCH(MID(F4,FIND(".",F4)+1,LEN(F4)-FIND(".",F4)+1),'Not Req'!$D$4:$D$72,0)) -> 0. Package | F4: package.devc.xml | G4: CDS Pattern | H4: 2 months ago | N4: {=_xlfn.UNIQUE(C4:C21)} -> package
C5: =LEFT(F5,FIND(".",F5)-1) -> zbs_dmo_cstat | D5: {=INDEX('Not Req'!$E$4:$E$72,MATCH(MID(F5,FIND(".",F5)+1,LEN(F5)-FIND(".",F5)+1),'Not Req'!$D$4:$D$72,0))} -> Table | E5: =INDEX('Not Req'!$F$4:$F$72,MATCH(MID(F5,FIND(".",F5)+1,LEN(F5)-FIND(".",F5)+1),'Not Req'!$D$4:$D$72,0)) -> 1. Dictionary | F5: zbs_dmo_cstat.tabl.xml | G5: Custom Action | H5: 6 months ago | N5: zbs_dmo_cstat
C6: =LEFT(F6,FIND(".",F6)-1) -> zbs_r_cusactentitytp | D6: {=INDEX('Not Req'!$E$4:$E$72,MATCH(MID(F6,FIND(".",F6)+1,LEN(F6)-FIND(".",F6)+1),'Not Req'!$D$4:$D$72,0))} -> BDEF | E6: =INDEX('Not Req'!$F$4:$F$72,MATCH(MID(F6,FIND(".",F6)+1,LEN(F6)-FIND(".",F6)+1),'Not Req'!$D$4:$D$72,0)) -> 2. CDS | F6: zbs_r_cusactentitytp.bdef.asbdef | G6: Custom Action | H6: 6 months ago | N6: zbs_r_cusactentitytp
C7: =LEFT(F7,FIND(".",F7)-1) -> zbs_r_cusactentitytp | D7: {=INDEX('Not Req'!$E$4:$E$72,MATCH(MID(F7,FIND(".",F7)+1,LEN(F7)-FIND(".",F7)+1),'Not Req'!$D$4:$D$72,0))} -> Data Definition | E7: =INDEX('Not Req'!$F$4:$F$72,MATCH(MID(F7,FIND(".",F7)+1,LEN(F7)-FIND(".",F7)+1),'Not Req'!$D$4:$D$72,0)) -> 2. CDS | F7: zbs_r_cusactentitytp.ddls.asddls | G7: Custom Action | H7: 6 months ago | N7: zbp_bs_demo_custom_action
C8: =LEFT(F8,FIND(".",F8)-1) -> zbs_r_cusactentitytp | D8: {=INDEX('Not Req'!$E$4:$E$72,MATCH(MID(F8,FIND(".",F8)+1,LEN(F8)-FIND(".",F8)+1),'Not Req'!$D$4:$D$72,0))} -> Description : BDEF | E8: =INDEX('Not Req'!$F$4:$F$72,MATCH(MID(F8,FIND(".",F8)+1,LEN(F8)-FIND(".",F8)+1),'Not Req'!$D$4:$D$72,0)) -> 2. CDS | F8: zbs_r_cusactentitytp.bdef.xml | G8: Custom Action | H8: 6 months ago | N8: zcl_bs_demo_custom_action_qry
C9: =LEFT(F9,FIND(".",F9)-1) -> zbs_r_cusactentitytp | D9: {=INDEX('Not Req'!$E$4:$E$72,MATCH(MID(F9,FIND(".",F9)+1,LEN(F9)-FIND(".",F9)+1),'Not Req'!$D$4:$D$72,0))} -> Description : Data Definition | E9: =INDEX('Not Req'!$F$4:$F$72,MATCH(MID(F9,FIND(".",F9)+1,LEN(F9)-FIND(".",F9)+1),'Not Req'!$D$4:$D$72,0)) -> 2. CDS | F9: zbs_r_cusactentitytp.ddls.xml | G9: Custom Action | H9: 6 months ago | N9: zbs_custom_action
C10: =LEFT(F10,FIND(".",F10)-1) -> zbp_bs_demo_custom_action | D10: {=INDEX('Not Req'!$E$4:$E$72,MATCH(MID(F10,FIND(".",F10)+1,LEN(F10)-FIND(".",F10)+1),'Not Req'!$D$4:$D$72,0))} -> Classes | E10: =INDEX('Not Req'!$F$4:$F$72,MATCH(MID(F10,FIND(".",F10)+1,LEN(F10)-FIND(".",F10)+1),'Not Req'!$D$4:$D$72,0)) -> 3. Source Code Library | F10: zbp_bs_demo_custom_action.clas.abap | G10: Custom Action | H10: 6 months ago | N10: bee6b00074f6699624012d396997aaht
C11: =LEFT(F11,FIND(".",F11)-1) -> zcl_bs_demo_custom_action_qry | D11: {=INDEX('Not Req'!$E$4:$E$72,MATCH(MID(F11,FIND(".",F11)+1,LEN(F11)-FIND(".",F11)+1),'Not Req'!$D$4:$D$72,0))} -> Classes | E11: =INDEX('Not Req'!$F$4:$F$72,MATCH(MID(F11,FIND(".",F11)+1,LEN(F11)-FIND(".",F11)+1),'Not Req'!$D$4:$D$72,0)) -> 3. Source Code Library | F11: zcl_bs_demo_custom_action_qry.clas.abap | G11: Custom Action | H11: 6 months ago | N11: fb1872bf9b30d1c7c1e4e51bc7fc70ht
C12: =LEFT(F12,FIND(".",F12)-1) -> zbp_bs_demo_custom_action | D12: {=INDEX('Not Req'!$E$4:$E$72,MATCH(MID(F12,FIND(".",F12)+1,LEN(F12)-FIND(".",F12)+1),'Not Req'!$D$4:$D$72,0))} -> Classes Local | E12: =INDEX('Not Req'!$F$4:$F$72,MATCH(MID(F12,FIND(".",F12)+1,LEN(F12)-FIND(".",F12)+1),'Not Req'!$D$4:$D$72,0)) -> 3. Source Code Library | F12: zbp_bs_demo_custom_action.clas.locals_imp.abap | G12: Custom Action | H12: 6 months ago | N12: zbs_ui_custom_action_o2
C13: =LEFT(F13,FIND(".",F13)-1) -> zbp_bs_demo_custom_action | D13: {=INDEX('Not Req'!$E$4:$E$72,MATCH(MID(F13,FIND(".",F13)+1,LEN(F13)-FIND(".",F13)+1),'Not Req'!$D$4:$D$72,0))} -> Description : Classes | E13: =INDEX('Not Req'!$F$4:$F$72,MATCH(MID(F13,FIND(".",F13)+1,LEN(F13)-FIND(".",F13)+1),'Not Req'!$D$4:$D$72,0)) -> 3. Source Code Library | F13: zbp_bs_demo_custom_action.clas.xml | G13: Custom Action | H13: 6 months ago | N13: zbs_ui_custom_action_o2_iwsg
C14: =LEFT(F14,FIND(".",F14)-1) -> zcl_bs_demo_custom_action_qry | D14: {=INDEX('Not Req'!$E$4:$E$72,MATCH(MID(F14,FIND(".",F14)+1,LEN(F14)-FIND(".",F14)+1),'Not Req'!$D$4:$D$72,0))} -> Description : Classes | E14: =INDEX('Not Req'!$F$4:$F$72,MATCH(MID(F14,FIND(".",F14)+1,LEN(F14)-FIND(".",F14)+1),'Not Req'!$D$4:$D$72,0)) -> 3. Source Code Library | F14: zcl_bs_demo_custom_action_qry.clas.xml | G14: Custom Action | H14: 6 months ago
C15: =LEFT(F15,FIND(".",F15)-1) -> zbs_custom_action | D15: {=INDEX('Not Req'!$E$4:$E$72,MATCH(MID(F15,FIND(".",F15)+1,LEN(F15)-FIND(".",F15)+1),'Not Req'!$D$4:$D$72,0))} -> Service Definition | E15: =INDEX('Not Req'!$F$4:$F$72,MATCH(MID(F15,FIND(".",F15)+1,LEN(F15)-FIND(".",F15)+1),'Not Req'!$D$4:$D$72,0)) -> Business Services | F15: zbs_custom_action.srvd.srvdsrv | G15: Custom Action | H15: 6 months ago
C16: =LEFT(F16,FIND(".",F16)-1) -> bee6b00074f6699624012d396997aaht | D16: {=INDEX('Not Req'!$E$4:$E$72,MATCH(MID(F16,FIND(".",F16)+1,LEN(F16)-FIND(".",F16)+1),'Not Req'!$D$4:$D$72,0))} -> Internal (Not Req) | E16: =INDEX('Not Req'!$F$4:$F$72,MATCH(MID(F16,FIND(".",F16)+1,LEN(F16)-FIND(".",F16)+1),'Not Req'!$D$4:$D$72,0)) -> Internal (Not Req) | F16: bee6b00074f6699624012d396997aaht.sush.xml | G16: Custom Action | H16: 6 months ago
C17: =LEFT(F17,FIND(".",F17)-1) -> fb1872bf9b30d1c7c1e4e51bc7fc70ht | D17: {=INDEX('Not Req'!$E$4:$E$72,MATCH(MID(F17,FIND(".",F17)+1,LEN(F17)-FIND(".",F17)+1),'Not Req'!$D$4:$D$72,0))} -> Internal (Not Req) | E17: =INDEX('Not Req'!$F$4:$F$72,MATCH(MID(F17,FIND(".",F17)+1,LEN(F17)-FIND(".",F17)+1),'Not Req'!$D$4:$D$72,0)) -> Internal (Not Req) | F17: fb1872bf9b30d1c7c1e4e51bc7fc70ht.sush.xml | G17: Custom Action | H17: 6 months ago
C18: =LEFT(F18,FIND(".",F18)-1) -> zbs_custom_action | D18: {=INDEX('Not Req'!$E$4:$E$72,MATCH(MID(F18,FIND(".",F18)+1,LEN(F18)-FIND(".",F18)+1),'Not Req'!$D$4:$D$72,0))} -> Internal (Not Req) | E18: =INDEX('Not Req'!$F$4:$F$72,MATCH(MID(F18,FIND(".",F18)+1,LEN(F18)-FIND(".",F18)+1),'Not Req'!$D$4:$D$72,0)) -> Internal (Not Req) | F18: zbs_custom_action.srvd.xml | G18: Custom Action | H18: 6 months ago
C19: =LEFT(F19,FIND(".",F19)-1) -> zbs_r_cusactentitytp | D19: {=INDEX('Not Req'!$E$4:$E$72,MATCH(MID(F19,FIND(".",F19)+1,LEN(F19)-FIND(".",F19)+1),'Not Req'!$D$4:$D$72,0))} -> Internal (Not Req) | E19: =INDEX('Not Req'!$F$4:$F$72,MATCH(MID(F19,FIND(".",F19)+1,LEN(F19)-FIND(".",F19)+1),'Not Req'!$D$4:$D$72,0)) -> Internal (Not Req) | F19: zbs_r_cusactentitytp.ddls.baseinfo | G19: Custom Action | H19: 6 months ago
C20: =LEFT(F20,FIND(".",F20)-1) -> zbs_ui_custom_action_o2 | D20: {=INDEX('Not Req'!$E$4:$E$72,MATCH(MID(F20,FIND(".",F20)+1,LEN(F20)-FIND(".",F20)+1),'Not Req'!$D$4:$D$72,0))} -> Internal (Not Req) | E20: =INDEX('Not Req'!$F$4:$F$72,MATCH(MID(F20,FIND(".",F20)+1,LEN(F20)-FIND(".",F20)+1),'Not Req'!$D$4:$D$72,0)) -> Internal (Not Req) | F20: zbs_ui_custom_action_o2.srvb.xml | G20: Custom Action | H20: 6 months ago
C21: =LEFT(F21,FIND(".",F21)-1) -> zbs_ui_custom_action_o2_iwsg | D21: {=INDEX('Not Req'!$E$4:$E$72,MATCH(MID(F21,FIND(".",F21)+1,LEN(F21)-FIND(".",F21)+1),'Not Req'!$D$4:$D$72,0))} -> Internal (Not Req) | E21: =INDEX('Not Req'!$F$4:$F$72,MATCH(MID(F21,FIND(".",F21)+1,LEN(F21)-FIND(".",F21)+1),'Not Req'!$D$4:$D$72,0)) -> Internal (Not Req) | F21: zbs_ui_custom_action_o2_iwsg.sco2.xml | G21: Custom Action | H21: 6 months ago
A22: D | B22: D | C22: =LEFT(F22,FIND(".",F22)-1) -> zbs_ui_custom_action_o2_iwsg_ibs | D22: {=INDEX('Not Req'!$E$4:$E$72,MATCH(MID(F22,FIND(".",F22)+1,LEN(F22)-FIND(".",F22)+1),'Not Req'!$D$4:$D$72,0))} -> Internal (Not Req) | E22: =INDEX('Not Req'!$F$4:$F$72,MATCH(MID(F22,FIND(".",F22)+1,LEN(F22)-FIND(".",F22)+1),'Not Req'!$D$4:$D$72,0)) -> Internal (Not Req) | F22: zbs_ui_custom_action_o2_iwsg_ibs.sia6.xml | G22: Custom Action | H22: 6 months ago

Sheet RAP TREE
B2: d | C2: Object | D2: Type | E2: Category | F2: Github Object | G2: Github Type | H2: Version
B4: 1 | C4: =LEFT(F4,FIND(".",F4)-1) -> package | D4: {=INDEX('Not Req'!$E$4:$E$72,MATCH(MID(F4,FIND(".",F4)+1,LEN(F4)-FIND(".",F4)+1),'Not Req'!$D$4:$D$72,0))} -> Description : Package | E4: =INDEX('Not Req'!$F$4:$F$72,MATCH(MID(F4,FIND(".",F4)+1,LEN(F4)-FIND(".",F4)+1),'Not Req'!$D$4:$D$72,0)) -> 0. Package | F4: package.devc.xml | G4: CDS Pattern | H4: 2 months ago | N4: {=_xlfn.UNIQUE(C4:C21)} -> package
C5: =LEFT(F5,FIND(".",F5)-1) -> zbs_dmo_team_d | D5: {=INDEX('Not Req'!$E$4:$E$72,MATCH(MID(F5,FIND(".",F5)+1,LEN(F5)-FIND(".",F5)+1),'Not Req'!$D$4:$D$72,0))} -> Table | E5: =INDEX('Not Req'!$F$4:$F$72,MATCH(MID(F5,FIND(".",F5)+1,LEN(F5)-FIND(".",F5)+1),'Not Req'!$D$4:$D$72,0)) -> 1. Dictionary | F5: zbs_dmo_team_d.tabl.xml | G5: Tree View | H5: 10 months ago | N5: zbs_dmo_team_d
C6: =LEFT(F6,FIND(".",F6)-1) -> zbs_c_dmotreeteam | D6: {=INDEX('Not Req'!$E$4:$E$72,MATCH(MID(F6,FIND(".",F6)+1,LEN(F6)-FIND(".",F6)+1),'Not Req'!$D$4:$D$72,0))} -> BDEF | E6: =INDEX('Not Req'!$F$4:$F$72,MATCH(MID(F6,FIND(".",F6)+1,LEN(F6)-FIND(".",F6)+1),'Not Req'!$D$4:$D$72,0)) -> 2. CDS | F6: zbs_c_dmotreeteam.bdef.asbdef | G6: Tree View | H6: 10 months ago | N6: zbs_c_dmotreeteam
C7: =LEFT(F7,FIND(".",F7)-1) -> zbs_r_dmotreeteam | D7: {=INDEX('Not Req'!$E$4:$E$72,MATCH(MID(F7,FIND(".",F7)+1,LEN(F7)-FIND(".",F7)+1),'Not Req'!$D$4:$D$72,0))} -> BDEF | E7: =INDEX('Not Req'!$F$4:$F$72,MATCH(MID(F7,FIND(".",F7)+1,LEN(F7)-FIND(".",F7)+1),'Not Req'!$D$4:$D$72,0)) -> 2. CDS | F7: zbs_r_dmotreeteam.bdef.asbdef | G7: Tree Deletion | H7: 9 months ago | N7: zbs_r_dmotreeteam
C8: =LEFT(F8,FIND(".",F8)-1) -> zbs_c_dmotreeteam | D8: {=INDEX('Not Req'!$E$4:$E$72,MATCH(MID(F8,FIND(".",F8)+1,LEN(F8)-FIND(".",F8)+1),'Not Req'!$D$4:$D$72,0))} -> Data Definition | E8: =INDEX('Not Req'!$F$4:$F$72,MATCH(MID(F8,FIND(".",F8)+1,LEN(F8)-FIND(".",F8)+1),'Not Req'!$D$4:$D$72,0)) -> 2. CDS | F8: zbs_c_dmotreeteam.ddls.asddls | G8: Tree View | H8: 10 months ago | N8: zbs_i_dmotreeteamhr
C9: =LEFT(F9,FIND(".",F9)-1) -> zbs_i_dmotreeteamhr | D9: {=INDEX('Not Req'!$E$4:$E$72,MATCH(MID(F9,FIND(".",F9)+1,LEN(F9)-FIND(".",F9)+1),'Not Req'!$D$4:$D$72,0))} -> Data Definition | E9: =INDEX('Not Req'!$F$4:$F$72,MATCH(MID(F9,FIND(".",F9)+1,LEN(F9)-FIND(".",F9)+1),'Not Req'!$D$4:$D$72,0)) -> 2. CDS | F9: zbs_i_dmotreeteamhr.ddls.asddls | G9: Tree View | H9: 10 months ago | N9: zbp_bs_demo_tree_team
C10: =LEFT(F10,FIND(".",F10)-1) -> zbs_r_dmotreeteam | D10: {=INDEX('Not Req'!$E$4:$E$72,MATCH(MID(F10,FIND(".",F10)+1,LEN(F10)-FIND(".",F10)+1),'Not Req'!$D$4:$D$72,0))} -> Data Definition | E10: =INDEX('Not Req'!$F$4:$F$72,MATCH(MID(F10,FIND(".",F10)+1,LEN(F10)-FIND(".",F10)+1),'Not Req'!$D$4:$D$72,0)) -> 2. CDS | F10: zbs_r_dmotreeteam.ddls.asddls | G10: Tree View | H10: 10 months ago | N10: zbp_bs_demo_tree_teamc
C11: =LEFT(F11,FIND(".",F11)-1) -> zbs_c_dmotreeteam | D11: {=INDEX('Not Req'!$E$4:$E$72,MATCH(MID(F11,FIND(".",F11)+1,LEN(F11)-FIND(".",F11)+1),'Not Req'!$D$4:$D$72,0))} -> Description : BDEF | E11: =INDEX('Not Req'!$F$4:$F$72,MATCH(MID(F11,FIND(".",F11)+1,LEN(F11)-FIND(".",F11)+1),'Not Req'!$D$4:$D$72,0)) -> 2. CDS | F11: zbs_c_dmotreeteam.bdef.xml | G11: Tree View | H11: 10 months ago
C12: =LEFT(F12,FIND(".",F12)-1) -> zbs_r_dmotreeteam | D12: {=INDEX('Not Req'!$E$4:$E$72,MATCH(MID(F12,FIND(".",F12)+1,LEN(F12)-FIND(".",F12)+1),'Not Req'!$D$4:$D$72,0))} -> Description : BDEF | E12: =INDEX('Not Req'!$F$4:$F$72,MATCH(MID(F12,FIND(".",F12)+1,LEN(F12)-FIND(".",F12)+1),'Not Req'!$D$4:$D$72,0)) -> 2. CDS | F12: zbs_r_dmotreeteam.bdef.xml | G12: Tree View | H12: 10 months ago
C13: =LEFT(F13,FIND(".",F13)-1) -> zbs_c_dmotreeteam | D13: {=INDEX('Not Req'!$E$4:$E$72,MATCH(MID(F13,FIND(".",F13)+1,LEN(F13)-FIND(".",F13)+1),'Not Req'!$D$4:$D$72,0))} -> Description : Data Definition | E13: =INDEX('Not Req'!$F$4:$F$72,MATCH(MID(F13,FIND(".",F13)+1,LEN(F13)-FIND(".",F13)+1),'Not Req'!$D$4:$D$72,0)) -> 2. CDS | F13: zbs_c_dmotreeteam.ddls.xml | G13: Tree View | H13: 10 months ago
C14: =LEFT(F14,FIND(".",F14)-1) -> zbs_i_dmotreeteamhr | D14: {=INDEX('Not Req'!$E$4:$E$72,MATCH(MID(F14,FIND(".",F14)+1,LEN(F14)-FIND(".",F14)+1),'Not Req'!$D$4:$D$72,0))} -> Description : Data Definition | E14: =INDEX('Not Req'!$F$4:$F$72,MATCH(MID(F14,FIND(".",F14)+1,LEN(F14)-FIND(".",F14)+1),'Not Req'!$D$4:$D$72,0)) -> 2. CDS | F14: zbs_i_dmotreeteamhr.ddls.xml | G14: Tree View | H14: 10 months ago
C15: =LEFT(F15,FIND(".",F15)-1) -> zbs_r_dmotreeteam | D15: {=INDEX('Not Req'!$E$4:$E$72,MATCH(MID(F15,FIND(".",F15)+1,LEN(F15)-FIND(".",F15)+1),'Not Req'!$D$4:$D$72,0))} -> Description : Data Definition | E15: =INDEX('Not Req'!$F$4:$F$72,MATCH(MID(F15,FIND(".",F15)+1,LEN(F15)-FIND(".",F15)+1),'Not Req'!$D$4:$D$72,0)) -> 2. CDS | F15: zbs_r_dmotreeteam.ddls.xml | G15: Tree View | H15: 10 months ago
C16: =LEFT(F16,FIND(".",F16)-1) -> zbs_c_dmotreeteam | D16: {=INDEX('Not Req'!$E$4:$E$72,MATCH(MID(F16,FIND(".",F16)+1,LEN(F16)-FIND(".",F16)+1),'Not Req'!$D$4:$D$72,0))} -> Description : Metadata | E16: =INDEX('Not Req'!$F$4:$F$72,MATCH(MID(F16,FIND(".",F16)+1,LEN(F16)-FIND(".",F16)+1),'Not Req'!$D$4:$D$72,0)) -> 2. CDS | F16: zbs_c_dmotreeteam.ddlx.xml | G16: Tree View | H16: 10 months ago
C17: =LEFT(F17,FIND(".",F17)-1) -> zbs_c_dmotreeteam | D17: {=INDEX('Not Req'!$E$4:$E$72,MATCH(MID(F17,FIND(".",F17)+1,LEN(F17)-FIND(".",F17)+1),'Not Req'!$D$4:$D$72,0))} -> Metadata | E17: =INDEX('Not Req'!$F$4:$F$72,MATCH(MID(F17,FIND(".",F17)+1,LEN(F17)-FIND(".",F17)+1),'Not Req'!$D$4:$D$72,0)) -> 2. CDS | F17: zbs_c_dmotreeteam.ddlx.asddlxs | G17: Tree View | H17: 10 months ago
C18: =LEFT(F18,FIND(".",F18)-1) -> zbp_bs_demo_tree_team | D18: {=INDEX('Not Req'!$E$4:$E$72,MATCH(MID(F18,FIND(".",F18)+1,LEN(F18)-FIND(".",F18)+1),'Not Req'!$D$4:$D$72,0))} -> Classes | E18: =INDEX('Not Req'!$F$4:$F$72,MATCH(MID(F18,FIND(".",F18)+1,LEN(F18)-FIND(".",F18)+1),'Not Req'!$D$4:$D$72,0)) -> 3. Source Code Library | F18: zbp_bs_demo_tree_team.clas.abap | G18: Tree View | H18: 10 months ago
C19: =LEFT(F19,FIND(".",F19)-1) -> zbp_bs_demo_tree_teamc | D19: {=INDEX('Not Req'!$E$4:$E$72,MATCH(MID(F19,FIND(".",F19)+1,LEN(F19)-FIND(".",F19)+1),'Not Req'!$D$4:$D$72,0))} -> Classes | E19: =INDEX('Not Req'!$F$4:$F$72,MATCH(MID(F19,FIND(".",F19)+1,LEN(F19)-FIND(".",F19)+1),'Not Req'!$D$4:$D$72,0)) -> 3. Source Code Library | F19: zbp_bs_demo_tree_teamc.clas.abap | G19: Tree View | H19: 10 months ago
C20: =LEFT(F20,FIND(".",F20)-1) -> zbp_bs_demo_tree_team | D20: {=INDEX('Not Req'!$E$4:$E$72,MATCH(MID(F20,FIND(".",F20)+1,LEN(F20)-FIND(".",F20)+1),'Not Req'!$D$4:$D$72,0))} -> Classes Local | E20: =INDEX('Not Req'!$F$4:$F$72,MATCH(MID(F20,FIND(".",F20)+1,LEN(F20)-FIND(".",F20)+1),'Not Req'!$D$4:$D$72,0)) -> 3. Source Code Library | F20: zbp_bs_demo_tree_team.clas.locals_imp.abap | G20: Tree Deletion | H20: 9 months ago
C21: =LEFT(F21,FIND(".",F21)-1) -> zbp_bs_demo_tree_team | D21: {=INDEX('Not Req'!$E$4:$E$72,MATCH(MID(F21,FIND(".",F21)+1,LEN(F21)-FIND(".",F21)+1),'Not Req'!$D$4:$D$72,0))} -> Description : Classes | E21: =INDEX('Not Req'!$F$4:$F$72,MATCH(MID(F21,FIND(".",F21)+1,LEN(F21)-FIND(".",F21)+1),'Not Req'!$D$4:$D$72,0)) -> 3. Source Code Library | F21: zbp_bs_demo_tree_team.clas.xml | G21: Tree View | H21: 10 months ago
A22: D | B22: D | C22: =LEFT(F22,FIND(".",F22)-1) -> zbp_bs_demo_tree_teamc | D22: {=INDEX('Not Req'!$E$4:$E$72,MATCH(MID(F22,FIND(".",F22)+1,LEN(F22)-FIND(".",F22)+1),'Not Req'!$D$4:$D$72,0))} -> Description : Classes | E22: =INDEX('Not Req'!$F$4:$F$72,MATCH(MID(F22,FIND(".",F22)+1,LEN(F22)-FIND(".",F22)+1),'Not Req'!$D$4:$D$72,0)) -> 3. Source Code Library | F22: zbp_bs_demo_tree_teamc.clas.xml | G22: Tree View | H22: 10 months ago
C23: =LEFT(F23,FIND(".",F23)-1) -> zbs_demo_tree_team | D23: {=INDEX('Not Req'!$E$4:$E$72,MATCH(MID(F23,FIND(".",F23)+1,LEN(F23)-FIND(".",F23)+1),'Not Req'!$D$4:$D$72,0))} -> Service Definition | E23: =INDEX('Not Req'!$F$4:$F$72,MATCH(MID(F23,FIND(".",F23)+1,LEN(F23)-FIND(".",F23)+1),'Not Req'!$D$4:$D$72,0)) -> Business Services | F23: zbs_demo_tree_team.srvd.srvdsrv | G23: Tree View | H23: 10 months ago
C24: =LEFT(F24,FIND(".",F24)-1) -> 04b39c4b139bc1cc065f421ae4eb0dht | D24: {=INDEX('Not Req'!$E$4:$E$72,MATCH(MID(F24,FIND(".",F24)+1,LEN(F24)-FIND(".",F24)+1),'Not Req'!$D$4:$D$72,0))} -> Internal (Not Req) | E24: =INDEX('Not Req'!$F$4:$F$72,MATCH(MID(F24,FIND(".",F24)+1,LEN(F24)-FIND(".",F24)+1),'Not Req'!$D$4:$D$72,0)) -> Internal (Not Req) | F24: 04b39c4b139bc1cc065f421ae4eb0dht.sush.xml | G24: Tree View | H24: 10 months ago
C25: =LEFT(F25,FIND(".",F25)-1) -> zbs_c_dmotreeteam | D25: {=INDEX('Not Req'!$E$4:$E$72,MATCH(MID(F25,FIND(".",F25)+1,LEN(F25)-FIND(".",F25)+1),'Not Req'!$D$4:$D$72,0))} -> Internal (Not Req) | E25: =INDEX('Not Req'!$F$4:$F$72,MATCH(MID(F25,FIND(".",F25)+1,LEN(F25)-FIND(".",F25)+1),'Not Req'!$D$4:$D$72,0)) -> Internal (Not Req) | F25: zbs_c_dmotreeteam.ddls.baseinfo | G25: Tree View | H25: 10 months ago
C26: =LEFT(F26,FIND(".",F26)-1) -> zbs_demo_tree_team | D26: {=INDEX('Not Req'!$E$4:$E$72,MATCH(MID(F26,FIND(".",F26)+1,LEN(F26)-FIND(".",F26)+1),'Not Req'!$D$4:$D$72,0))} -> Internal (Not Req) | E26: =INDEX('Not Req'!$F$4:$F$72,MATCH(MID(F26,FIND(".",F26)+1,LEN(F26)-FIND(".",F26)+1),'Not Req'!$D$4:$D$72,0)) -> Internal (Not Req) | F26: zbs_demo_tree_team.srvd.xml | G26: Tree View | H26: 10 months ago
C27: =LEFT(F27,FIND(".",F27)-1) -> zbs_i_dmotreeteamhr | D27: {=INDEX('Not Req'!$E$4:$E$72,MATCH(MID(F27,FIND(".",F27)+1,LEN(F27)-FIND(".",F27)+1),'Not Req'!$D$4:$D$72,0))} -> Internal (Not Req) | E27: =INDEX('Not Req'!$F$4:$F$72,MATCH(MID(F27,FIND(".",F27)+1,LEN(F27)-FIND(".",F27)+1),'Not Req'!$D$4:$D$72,0)) -> Internal (Not Req) | F27: zbs_i_dmotreeteamhr.ddls.baseinfo | G27: Tree View | H27: 10 months ago
C28: =LEFT(F28,FIND(".",F28)-1) -> zbs_r_dmotreeteam | D28: {=INDEX('Not Req'!$E$4:$E$72,MATCH(MID(F28,FIND(".",F28)+1,LEN(F28)-FIND(".",F28)+1),'Not Req'!$D$4:$D$72,0))} -> Internal (Not Req) | E28: =INDEX('Not Req'!$F$4:$F$72,MATCH(MID(F28,FIND(".",F28)+1,LEN(F28)-FIND(".",F28)+1),'Not Req'!$D$4:$D$72,0)) -> Internal (Not Req) | F28: zbs_r_dmotreeteam.ddls.baseinfo | G28: Tree View | H28: 10 months ago
C29: =LEFT(F29,FIND(".",F29)-1) -> zbs_ui_demo_tree_team_o4 | D29: {=INDEX('Not Req'!$E$4:$E$72,MATCH(MID(F29,FIND(".",F29)+1,LEN(F29)-FIND(".",F29)+1),'Not Req'!$D$4:$D$72,0))} -> Internal (Not Req) | E29: =INDEX('Not Req'!$F$4:$F$72,MATCH(MID(F29,FIND(".",F29)+1,LEN(F29)-FIND(".",F29)+1),'Not Req'!$D$4:$D$72,0)) -> Internal (Not Req) | F29: zbs_ui_demo_tree_team_o4.srvb.xml | G29: Tree View | H29: 10 months ago
C30: =LEFT(F30,FIND(".",F30)-1) -> zbs_ui_demo_tree_team_o4_0001_g4ba | D30: {=INDEX('Not Req'!$E$4:$E$72,MATCH(MID(F30,FIND(".",F30)+1,LEN(F30)-FIND(".",F30)+1),'Not Req'!$D$4:$D$72,0))} -> Internal (Not Req) | E30: =INDEX('Not Req'!$F$4:$F$72,MATCH(MID(F30,FIND(".",F30)+1,LEN(F30)-FIND(".",F30)+1),'Not Req'!$D$4:$D$72,0)) -> Internal (Not Req) | F30: zbs_ui_demo_tree_team_o4_0001_g4ba.sco2.xml | G30: Tree View | H30: 10 months ago
A31: d | B31: d | C31: =LEFT(F31,FIND(".",F31)-1) -> zbs_ui_demo_tree_team_o4__00001_ibs | D31: {=INDEX('Not Req'!$E$4:$E$72,MATCH(MID(F31,FIND(".",F31)+1,LEN(F31)-FIND(".",F31)+1),'Not Req'!$D$4:$D$72,0))} -> Internal (Not Req) | E31: =INDEX('Not Req'!$F$4:$F$72,MATCH(MID(F31,FIND(".",F31)+1,LEN(F31)-FIND(".",F31)+1),'Not Req'!$D$4:$D$72,0)) -> Internal (Not Req) | F31: zbs_ui_demo_tree_team_o4__00001_ibs.sia6.xml | G31: Tree View | H31: 10 months ago

Sheet PATTERN CDS
B2: d | C2: Object | D2: Type | E2: Category | F2: Github Object | G2: Github Type | H2: Version
B4: 1 | C4: =LEFT(F4,FIND(".",F4)-1) -> package | D4: {=INDEX('Not Req'!$E$4:$E$72,MATCH(MID(F4,FIND(".",F4)+1,LEN(F4)-FIND(".",F4)+1),'Not Req'!$D$4:$D$72,0))} -> Description : Package | E4: =INDEX('Not Req'!$F$4:$F$72,MATCH(MID(F4,FIND(".",F4)+1,LEN(F4)-FIND(".",F4)+1),'Not Req'!$D$4:$D$72,0)) -> 0. Package | F4: package.devc.xml | G4: CDS Pattern | H4: 2 months ago | N4: {=_xlfn.UNIQUE(C4:C21)} -> package
C5: =LEFT(F5,FIND(".",F5)-1) -> zbs_cp_invoice_d | D5: {=INDEX('Not Req'!$E$4:$E$72,MATCH(MID(F5,FIND(".",F5)+1,LEN(F5)-FIND(".",F5)+1),'Not Req'!$D$4:$D$72,0))} -> Table | E5: =INDEX('Not Req'!$F$4:$F$72,MATCH(MID(F5,FIND(".",F5)+1,LEN(F5)-FIND(".",F5)+1),'Not Req'!$D$4:$D$72,0)) -> 1. Dictionary | F5: zbs_cp_invoice_d.tabl.xml | G5: CDS Pattern | H5: 2 months ago | N5: zbs_cp_invoice_d
C6: =LEFT(F6,FIND(".",F6)-1) -> zbs_cp_pos_d | D6: {=INDEX('Not Req'!$E$4:$E$72,MATCH(MID(F6,FIND(".",F6)+1,LEN(F6)-FIND(".",F6)+1),'Not Req'!$D$4:$D$72,0))} -> Table | E6: =INDEX('Not Req'!$F$4:$F$72,MATCH(MID(F6,FIND(".",F6)+1,LEN(F6)-FIND(".",F6)+1),'Not Req'!$D$4:$D$72,0)) -> 1. Dictionary | F6: zbs_cp_pos_d.tabl.xml | G6: CDS Pattern | H6: 2 months ago | N6: zbs_cp_pos_d
C7: =LEFT(F7,FIND(".",F7)-1) -> zbs_c_cdspatterninvoice | D7: {=INDEX('Not Req'!$E$4:$E$72,MATCH(MID(F7,FIND(".",F7)+1,LEN(F7)-FIND(".",F7)+1),'Not Req'!$D$4:$D$72,0))} -> BDEF | E7: =INDEX('Not Req'!$F$4:$F$72,MATCH(MID(F7,FIND(".",F7)+1,LEN(F7)-FIND(".",F7)+1),'Not Req'!$D$4:$D$72,0)) -> 2. CDS | F7: zbs_c_cdspatterninvoice.bdef.asbdef | G7: CDS Pattern | H7: 2 months ago | N7: zbs_c_cdspatterninvoice
C8: =LEFT(F8,FIND(".",F8)-1) -> zbs_t_cdspatterninvoice | D8: {=INDEX('Not Req'!$E$4:$E$72,MATCH(MID(F8,FIND(".",F8)+1,LEN(F8)-FIND(".",F8)+1),'Not Req'!$D$4:$D$72,0))} -> BDEF | E8: =INDEX('Not Req'!$F$4:$F$72,MATCH(MID(F8,FIND(".",F8)+1,LEN(F8)-FIND(".",F8)+1),'Not Req'!$D$4:$D$72,0)) -> 2. CDS | F8: zbs_t_cdspatterninvoice.bdef.asbdef | G8: CDS Pattern | H8: 2 months ago | N8: zbs_t_cdspatterninvoice
C9: =LEFT(F9,FIND(".",F9)-1) -> zbs_c_cdspatterninvoice | D9: {=INDEX('Not Req'!$E$4:$E$72,MATCH(MID(F9,FIND(".",F9)+1,LEN(F9)-FIND(".",F9)+1),'Not Req'!$D$4:$D$72,0))} -> Data Definition | E9: =INDEX('Not Req'!$F$4:$F$72,MATCH(MID(F9,FIND(".",F9)+1,LEN(F9)-FIND(".",F9)+1),'Not Req'!$D$4:$D$72,0)) -> 2. CDS | F9: zbs_c_cdspatterninvoice.ddls.asddls | G9: CDS Pattern | H9: 2 months ago | N9: zbs_c_cdspatternposition
C10: =LEFT(F10,FIND(".",F10)-1) -> zbs_c_cdspatternposition | D10: {=INDEX('Not Req'!$E$4:$E$72,MATCH(MID(F10,FIND(".",F10)+1,LEN(F10)-FIND(".",F10)+1),'Not Req'!$D$4:$D$72,0))} -> Data Definition | E10: =INDEX('Not Req'!$F$4:$F$72,MATCH(MID(F10,FIND(".",F10)+1,LEN(F10)-FIND(".",F10)+1),'Not Req'!$D$4:$D$72,0)) -> 2. CDS | F10: zbs_c_cdspatternposition.ddls.asddls | G10: CDS Pattern | H10: 2 months ago | N10: zbs_t_cdspatternposition
C11: =LEFT(F11,FIND(".",F11)-1) -> zbs_t_cdspatterninvoice | D11: {=INDEX('Not Req'!$E$4:$E$72,MATCH(MID(F11,FIND(".",F11)+1,LEN(F11)-FIND(".",F11)+1),'Not Req'!$D$4:$D$72,0))} -> Data Definition | E11: =INDEX('Not Req'!$F$4:$F$72,MATCH(MID(F11,FIND(".",F11)+1,LEN(F11)-FIND(".",F11)+1),'Not Req'!$D$4:$D$72,0)) -> 2. CDS | F11: zbs_t_cdspatterninvoice.ddls.asddls | G11: CDS Pattern | H11: 2 months ago
C12: =LEFT(F12,FIND(".",F12)-1) -> zbs_t_cdspatternposition | D12: {=INDEX('Not Req'!$E$4:$E$72,MATCH(MID(F12,FIND(".",F12)+1,LEN(F12)-FIND(".",F12)+1),'Not Req'!$D$4:$D$72,0))} -> Data Definition | E12: =INDEX('Not Req'!$F$4:$F$72,MATCH(MID(F12,FIND(".",F12)+1,LEN(F12)-FIND(".",F12)+1),'Not Req'!$D$4:$D$72,0)) -> 2. CDS | F12: zbs_t_cdspatternposition.ddls.asddls | G12: CDS Pattern | H12: 2 months ago
C13: =LEFT(F13,FIND(".",F13)-1) -> zbs_c_cdspatterninvoice | D13: {=INDEX('Not Req'!$E$4:$E$72,MATCH(MID(F13,FIND(".",F13)+1,LEN(F13)-FIND(".",F13)+1),'Not Req'!$D$4:$D$72,0))} -> Description : BDEF | E13: =INDEX('Not Req'!$F$4:$F$72,MATCH(MID(F13,FIND(".",F13)+1,LEN(F13)-FIND(".",F13)+1),'Not Req'!$D$4:$D$72,0)) -> 2. CDS | F13: zbs_c_cdspatterninvoice.bdef.xml | G13: CDS Pattern | H13: 2 months ago
C14: =LEFT(F14,FIND(".",F14)-1) -> zbs_t_cdspatterninvoice | D14: {=INDEX('Not Req'!$E$4:$E$72,MATCH(MID(F14,FIND(".",F14)+1,LEN(F14)-FIND(".",F14)+1),'Not Req'!$D$4:$D$72,0))} -> Description : BDEF | E14: =INDEX('Not Req'!$F$4:$F$72,MATCH(MID(F14,FIND(".",F14)+1,LEN(F14)-FIND(".",F14)+1),'Not Req'!$D$4:$D$72,0)) -> 2. CDS | F14: zbs_t_cdspatterninvoice.bdef.xml | G14: CDS Pattern | H14: 2 months ago
C15: =LEFT(F15,FIND(".",F15)-1) -> zbs_c_cdspatterninvoice | D15: {=INDEX('Not Req'!$E$4:$E$72,MATCH(MID(F15,FIND(".",F15)+1,LEN(F15)-FIND(".",F15)+1),'Not Req'!$D$4:$D$72,0))} -> Description : Data Definition | E15: =INDEX('Not Req'!$F$4:$F$72,MATCH(MID(F15,FIND(".",F15)+1,LEN(F15)-FIND(".",F15)+1),'Not Req'!$D$4:$D$72,0)) -> 2. CDS | F15: zbs_c_cdspatterninvoice.ddls.xml | G15: CDS Pattern | H15: 2 months ago
C16: =LEFT(F16,FIND(".",F16)-1) -> zbs_c_cdspatternposition | D16: {=INDEX('Not Req'!$E$4:$E$72,MATCH(MID(F16,FIND(".",F16)+1,LEN(F16)-FIND(".",F16)+1),'Not Req'!$D$4:$D$72,0))} -> Description : Data Definition | E16: =INDEX('Not Req'!$F$4:$F$72,MATCH(MID(F16,FIND(".",F16)+1,LEN(F16)-FIND(".",F16)+1),'Not Req'!$D$4:$D$72,0)) -> 2. CDS | F16: zbs_c_cdspatternposition.ddls.xml | G16: CDS Pattern | H16: 2 months ago
C17: =LEFT(F17,FIND(".",F17)-1) -> zbs_t_cdspatterninvoice | D17: {=INDEX('Not Req'!$E$4:$E$72,MATCH(MID(F17,FIND(".",F17)+1,LEN(F17)-FIND(".",F17)+1),'Not Req'!$D$4:$D$72,0))} -> Description : Data Definition | E17: =INDEX('Not Req'!$F$4:$F$72,MATCH(MID(F17,FIND(".",F17)+1,LEN(F17)-FIND(".",F17)+1),'Not Req'!$D$4:$D$72,0)) -> 2. CDS | F17: zbs_t_cdspatterninvoice.ddls.xml | G17: CDS Pattern | H17: 2 months ago
C18: =LEFT(F18,FIND(".",F18)-1) -> zbs_t_cdspatternposition | D18: {=INDEX('Not Req'!$E$4:$E$72,MATCH(MID(F18,FIND(".",F18)+1,LEN(F18)-FIND(".",F18)+1),'Not Req'!$D$4:$D$72,0))} -> Description : Data Definition | E18: =INDEX('Not Req'!$F$4:$F$72,MATCH(MID(F18,FIND(".",F18)+1,LEN(F18)-FIND(".",F18)+1),'Not Req'!$D$4:$D$72,0)) -> 2. CDS | F18: zbs_t_cdspatternposition.ddls.xml | G18: CDS Pattern | H18: 2 months ago
C19: =LEFT(F19,FIND(".",F19)-1) -> zbs_c_cdspatterninvoice | D19: {=INDEX('Not Req'!$E$4:$E$72,MATCH(MID(F19,FIND(".",F19)+1,LEN(F19)-FIND(".",F19)+1),'Not Req'!$D$4:$D$72,0))} -> Description : Metadata | E19: =INDEX('Not Req'!$F$4:$F$72,MATCH(MID(F19,FIND(".",F19)+1,LEN(F19)-FIND(".",F19)+1),'Not Req'!$D$4:$D$72,0)) -> 2. CDS | F19: zbs_c_cdspatterninvoice.ddlx.xml | G19: CDS Pattern | H19: 2 months ago
C20: =LEFT(F20,FIND(".",F20)-1) -> zbs_c_cdspatternposition | D20: {=INDEX('Not Req'!$E$4:$E$72,MATCH(MID(F20,FIND(".",F20)+1,LEN(F20)-FIND(".",F20)+1),'Not Req'!$D$4:$D$72,0))} -> Description : Metadata | E20: =INDEX('Not Req'!$F$4:$F$72,MATCH(MID(F20,FIND(".",F20)+1,LEN(F20)-FIND(".",F20)+1),'Not Req'!$D$4:$D$72,0)) -> 2. CDS | F20: zbs_c_cdspatternposition.ddlx.xml | G20: CDS Pattern | H20: 2 months ago
C21: =LEFT(F21,FIND(".",F21)-1) -> zbs_c_cdspatterninvoice | D21: {=INDEX('Not Req'!$E$4:$E$72,MATCH(MID(F21,FIND(".",F21)+1,LEN(F21)-FIND(".",F21)+1),'Not Req'!$D$4:$D$72,0))} -> Metadata | E21: =INDEX('Not Req'!$F$4:$F$72,MATCH(MID(F21,FIND(".",F21)+1,LEN(F21)-FIND(".",F21)+1),'Not Req'!$D$4:$D$72,0)) -> 2. CDS | F21: zbs_c_cdspatterninvoice.ddlx.asddlxs | G21: CDS Pattern | H21: 2 months ago
A22: D | B22: D | C22: =LEFT(F22,FIND(".",F22)-1) -> zbs_c_cdspatternposition | D22: {=INDEX('Not Req'!$E$4:$E$72,MATCH(MID(F22,FIND(".",F22)+1,LEN(F22)-FIND(".",F22)+1),'Not Req'!$D$4:$D$72,0))} -> Metadata | E22: =INDEX('Not Req'!$F$4:$F$72,MATCH(MID(F22,FIND(".",F22)+1,LEN(F22)-FIND(".",F22)+1),'Not Req'!$D$4:$D$72,0)) -> 2. CDS | F22: zbs_c_cdspatternposition.ddlx.asddlxs | G22: CDS Pattern | H22: 2 months ago
C23: =LEFT(F23,FIND(".",F23)-1) -> zbp_bs_cdspattern_invoice | D23: {=INDEX('Not Req'!$E$4:$E$72,MATCH(MID(F23,FIND(".",F23)+1,LEN(F23)-FIND(".",F23)+1),'Not Req'!$D$4:$D$72,0))} -> Classes | E23: =INDEX('Not Req'!$F$4:$F$72,MATCH(MID(F23,FIND(".",F23)+1,LEN(F23)-FIND(".",F23)+1),'Not Req'!$D$4:$D$72,0)) -> 3. Source Code Library | F23: zbp_bs_cdspattern_invoice.clas.abap | G23: CDS Pattern | H23: 2 months ago
C24: =LEFT(F24,FIND(".",F24)-1) -> zbp_bs_cdspattern_invoice | D24: {=INDEX('Not Req'!$E$4:$E$72,MATCH(MID(F24,FIND(".",F24)+1,LEN(F24)-FIND(".",F24)+1),'Not Req'!$D$4:$D$72,0))} -> Classes Local | E24: =INDEX('Not Req'!$F$4:$F$72,MATCH(MID(F24,FIND(".",F24)+1,LEN(F24)-FIND(".",F24)+1),'Not Req'!$D$4:$D$72,0)) -> 3. Source Code Library | F24: zbp_bs_cdspattern_invoice.clas.locals_imp.abap | G24: CDS Pattern | H24: 2 months ago
C25: =LEFT(F25,FIND(".",F25)-1) -> zbp_bs_cdspattern_invoice | D25: {=INDEX('Not Req'!$E$4:$E$72,MATCH(MID(F25,FIND(".",F25)+1,LEN(F25)-FIND(".",F25)+1),'Not Req'!$D$4:$D$72,0))} -> Description : Classes | E25: =INDEX('Not Req'!$F$4:$F$72,MATCH(MID(F25,FIND(".",F25)+1,LEN(F25)-FIND(".",F25)+1),'Not Req'!$D$4:$D$72,0)) -> 3. Source Code Library | F25: zbp_bs_cdspattern_invoice.clas.xml | G25: CDS Pattern | H25: 2 months ago
C26: =LEFT(F26,FIND(".",F26)-1) -> zbs_demo_pattern_cds | D26: {=INDEX('Not Req'!$E$4:$E$72,MATCH(MID(F26,FIND(".",F26)+1,LEN(F26)-FIND(".",F26)+1),'Not Req'!$D$4:$D$72,0))} -> Service Definition | E26: =INDEX('Not Req'!$F$4:$F$72,MATCH(MID(F26,FIND(".",F26)+1,LEN(F26)-FIND(".",F26)+1),'Not Req'!$D$4:$D$72,0)) -> Business Services | F26: zbs_demo_pattern_cds.srvd.srvdsrv | G26: CDS Pattern | H26: 2 months ago
C27: =LEFT(F27,FIND(".",F27)-1) -> 12de3d43ab9bc726d7070e59867b1eht | D27: {=INDEX('Not Req'!$E$4:$E$72,MATCH(MID(F27,FIND(".",F27)+1,LEN(F27)-FIND(".",F27)+1),'Not Req'!$D$4:$D$72,0))} -> Internal (Not Req) | E27: =INDEX('Not Req'!$F$4:$F$72,MATCH(MID(F27,FIND(".",F27)+1,LEN(F27)-FIND(".",F27)+1),'Not Req'!$D$4:$D$72,0)) -> Internal (Not Req) | F27: 12de3d43ab9bc726d7070e59867b1eht.sush.xml | G27: CDS Pattern | H27: 2 months ago
C28: =LEFT(F28,FIND(".",F28)-1) -> zbs_c_cdspatterninvoice | D28: {=INDEX('Not Req'!$E$4:$E$72,MATCH(MID(F28,FIND(".",F28)+1,LEN(F28)-FIND(".",F28)+1),'Not Req'!$D$4:$D$72,0))} -> Internal (Not Req) | E28: =INDEX('Not Req'!$F$4:$F$72,MATCH(MID(F28,FIND(".",F28)+1,LEN(F28)-FIND(".",F28)+1),'Not Req'!$D$4:$D$72,0)) -> Internal (Not Req) | F28: zbs_c_cdspatterninvoice.ddls.baseinfo | G28: CDS Pattern | H28: 2 months ago
C29: =LEFT(F29,FIND(".",F29)-1) -> zbs_c_cdspatternposition | D29: {=INDEX('Not Req'!$E$4:$E$72,MATCH(MID(F29,FIND(".",F29)+1,LEN(F29)-FIND(".",F29)+1),'Not Req'!$D$4:$D$72,0))} -> Internal (Not Req) | E29: =INDEX('Not Req'!$F$4:$F$72,MATCH(MID(F29,FIND(".",F29)+1,LEN(F29)-FIND(".",F29)+1),'Not Req'!$D$4:$D$72,0)) -> Internal (Not Req) | F29: zbs_c_cdspatternposition.ddls.baseinfo | G29: CDS Pattern | H29: 2 months ago
C30: =LEFT(F30,FIND(".",F30)-1) -> zbs_demo_pattern_cds | D30: {=INDEX('Not Req'!$E$4:$E$72,MATCH(MID(F30,FIND(".",F30)+1,LEN(F30)-FIND(".",F30)+1),'Not Req'!$D$4:$D$72,0))} -> Internal (Not Req) | E30: =INDEX('Not Req'!$F$4:$F$72,MATCH(MID(F30,FIND(".",F30)+1,LEN(F30)-FIND(".",F30)+1),'Not Req'!$D$4:$D$72,0)) -> Internal (Not Req) | F30: zbs_demo_pattern_cds.srvd.xml | G30: CDS Pattern | H30: 2 months ago
C31: =LEFT(F31,FIND(".",F31)-1) -> zbs_t_cdspatterninvoice | D31: {=INDEX('Not Req'!$E$4:$E$72,MATCH(MID(F31,FIND(".",F31)+1,LEN(F31)-FIND(".",F31)+1),'Not Req'!$D$4:$D$72,0))} -> Internal (Not Req) | E31: =INDEX('Not Req'!$F$4:$F$72,MATCH(MID(F31,FIND(".",F31)+1,LEN(F31)-FIND(".",F31)+1),'Not Req'!$D$4:$D$72,0)) -> Internal (Not Req) | F31: zbs_t_cdspatterninvoice.ddls.baseinfo | G31: CDS Pattern | H31: 2 months ago
C32: =LEFT(F32,FIND(".",F32)-1) -> zbs_t_cdspatternposition | D32: {=INDEX('Not Req'!$E$4:$E$72,MATCH(MID(F32,FIND(".",F32)+1,LEN(F32)-FIND(".",F32)+1),'Not Req'!$D$4:$D$72,0))} -> Internal (Not Req) | E32: =INDEX('Not Req'!$F$4:$F$72,MATCH(MID(F32,FIND(".",F32)+1,LEN(F32)-FIND(".",F32)+1),'Not Req'!$D$4:$D$72,0)) -> Internal (Not Req) | F32: zbs_t_cdspatternposition.ddls.baseinfo | G32: CDS Pattern | H32: 2 months ago
C33: =LEFT(F33,FIND(".",F33)-1) -> zbs_ui_demo_pattern_cds_o4 | D33: {=INDEX('Not Req'!$E$4:$E$72,MATCH(MID(F33,FIND(".",F33)+1,LEN(F33)-FIND(".",F33)+1),'Not Req'!$D$4:$D$72,0))} -> Internal (Not Req) | E33: =INDEX('Not Req'!$F$4:$F$72,MATCH(MID(F33,FIND(".",F33)+1,LEN(F33)-FIND(".",F33)+1),'Not Req'!$D$4:$D$72,0)) -> Internal (Not Req) | F33: zbs_ui_demo_pattern_cds_o4.srvb.xml | G33: CDS Pattern | H33: 2 months ago
A34: DD | B34: DD | C34: =LEFT(F34,FIND(".",F34)-1) -> zbs_ui_demo_pattern_cds_o4_0001_g4ba | D34: {=INDEX('Not Req'!$E$4:$E$72,MATCH(MID(F34,FIND(".",F34)+1,LEN(F34)-FIND(".",F34)+1),'Not Req'!$D$4:$D$72,0))} -> Internal (Not Req) | E34: =INDEX('Not Req'!$F$4:$F$72,MATCH(MID(F34,FIND(".",F34)+1,LEN(F34)-FIND(".",F34)+1),'Not Req'!$D$4:$D$72,0)) -> Internal (Not Req) | F34: zbs_ui_demo_pattern_cds_o4_0001_g4ba.sco2.xml | G34: CDS Pattern | H34: 2 months ago

Sheet PATTERN API
B2: d | C2: Object | D2: Type | E2: Category | F2: Github Object | G2: Github Type | H2: Version
B4: 1 | C4: =LEFT(F4,FIND(".",F4)-1) -> package | D4: {=INDEX('Not Req'!$E$4:$E$72,MATCH(MID(F4,FIND(".",F4)+1,LEN(F4)-FIND(".",F4)+1),'Not Req'!$D$4:$D$72,0))} -> Description : Package | E4: =INDEX('Not Req'!$F$4:$F$72,MATCH(MID(F4,FIND(".",F4)+1,LEN(F4)-FIND(".",F4)+1),'Not Req'!$D$4:$D$72,0)) -> 0. Package | F4: package.devc.xml | G4: CDS Pattern | H4: 2 months ago | N4: {=_xlfn.UNIQUE(C4:C21)} -> package
C5: =LEFT(F5,FIND(".",F5)-1) -> zbs_api_target | D5: {=INDEX('Not Req'!$E$4:$E$72,MATCH(MID(F5,FIND(".",F5)+1,LEN(F5)-FIND(".",F5)+1),'Not Req'!$D$4:$D$72,0))} -> Table | E5: =INDEX('Not Req'!$F$4:$F$72,MATCH(MID(F5,FIND(".",F5)+1,LEN(F5)-FIND(".",F5)+1),'Not Req'!$D$4:$D$72,0)) -> 1. Dictionary | F5: zbs_api_target.tabl.xml | G5: API Pattern | H5: 7 months ago | N5: zbs_api_target
C6: =LEFT(F6,FIND(".",F6)-1) -> zbs_r_apilocation | D6: {=INDEX('Not Req'!$E$4:$E$72,MATCH(MID(F6,FIND(".",F6)+1,LEN(F6)-FIND(".",F6)+1),'Not Req'!$D$4:$D$72,0))} -> BDEF | E6: =INDEX('Not Req'!$F$4:$F$72,MATCH(MID(F6,FIND(".",F6)+1,LEN(F6)-FIND(".",F6)+1),'Not Req'!$D$4:$D$72,0)) -> 2. CDS | F6: zbs_r_apilocation.bdef.asbdef | G6: API Pattern | H6: 7 months ago | N6: zbs_r_apilocation
C7: =LEFT(F7,FIND(".",F7)-1) -> zbs_r_apilocation | D7: {=INDEX('Not Req'!$E$4:$E$72,MATCH(MID(F7,FIND(".",F7)+1,LEN(F7)-FIND(".",F7)+1),'Not Req'!$D$4:$D$72,0))} -> Data Definition | E7: =INDEX('Not Req'!$F$4:$F$72,MATCH(MID(F7,FIND(".",F7)+1,LEN(F7)-FIND(".",F7)+1),'Not Req'!$D$4:$D$72,0)) -> 2. CDS | F7: zbs_r_apilocation.ddls.asddls | G7: API Pattern | H7: 7 months ago | N7: zbp_bs_api_location
C8: =LEFT(F8,FIND(".",F8)-1) -> zbs_r_apilocation | D8: {=INDEX('Not Req'!$E$4:$E$72,MATCH(MID(F8,FIND(".",F8)+1,LEN(F8)-FIND(".",F8)+1),'Not Req'!$D$4:$D$72,0))} -> Description : BDEF | E8: =INDEX('Not Req'!$F$4:$F$72,MATCH(MID(F8,FIND(".",F8)+1,LEN(F8)-FIND(".",F8)+1),'Not Req'!$D$4:$D$72,0)) -> 2. CDS | F8: zbs_r_apilocation.bdef.xml | G8: API Pattern | H8: 7 months ago | N8: zcl_bs_api_target
C9: =LEFT(F9,FIND(".",F9)-1) -> zbs_r_apilocation | D9: {=INDEX('Not Req'!$E$4:$E$72,MATCH(MID(F9,FIND(".",F9)+1,LEN(F9)-FIND(".",F9)+1),'Not Req'!$D$4:$D$72,0))} -> Description : Data Definition | E9: =INDEX('Not Req'!$F$4:$F$72,MATCH(MID(F9,FIND(".",F9)+1,LEN(F9)-FIND(".",F9)+1),'Not Req'!$D$4:$D$72,0)) -> 2. CDS | F9: zbs_r_apilocation.ddls.xml | G9: API Pattern | H9: 7 months ago | N9: zbs_api_location_endpoint
C10: =LEFT(F10,FIND(".",F10)-1) -> zbp_bs_api_location | D10: {=INDEX('Not Req'!$E$4:$E$72,MATCH(MID(F10,FIND(".",F10)+1,LEN(F10)-FIND(".",F10)+1),'Not Req'!$D$4:$D$72,0))} -> Classes | E10: =INDEX('Not Req'!$F$4:$F$72,MATCH(MID(F10,FIND(".",F10)+1,LEN(F10)-FIND(".",F10)+1),'Not Req'!$D$4:$D$72,0)) -> 3. Source Code Library | F10: zbp_bs_api_location.clas.abap | G10: API Pattern | H10: 7 months ago | N10: 710df9f0500c0069d677cc915293cbht
C11: =LEFT(F11,FIND(".",F11)-1) -> zcl_bs_api_target | D11: {=INDEX('Not Req'!$E$4:$E$72,MATCH(MID(F11,FIND(".",F11)+1,LEN(F11)-FIND(".",F11)+1),'Not Req'!$D$4:$D$72,0))} -> Classes | E11: =INDEX('Not Req'!$F$4:$F$72,MATCH(MID(F11,FIND(".",F11)+1,LEN(F11)-FIND(".",F11)+1),'Not Req'!$D$4:$D$72,0)) -> 3. Source Code Library | F11: zcl_bs_api_target.clas.abap | G11: API Pattern | H11: 7 months ago | N11: 782ebdfdd92774c39297d4948c3981ht
C12: =LEFT(F12,FIND(".",F12)-1) -> zbp_bs_api_location | D12: {=INDEX('Not Req'!$E$4:$E$72,MATCH(MID(F12,FIND(".",F12)+1,LEN(F12)-FIND(".",F12)+1),'Not Req'!$D$4:$D$72,0))} -> Classes Local | E12: =INDEX('Not Req'!$F$4:$F$72,MATCH(MID(F12,FIND(".",F12)+1,LEN(F12)-FIND(".",F12)+1),'Not Req'!$D$4:$D$72,0)) -> 3. Source Code Library | F12: zbp_bs_api_location.clas.locals_imp.abap | G12: API Pattern | H12: 7 months ago | N12: zbs_api_location_endp_o2
C13: =LEFT(F13,FIND(".",F13)-1) -> zbp_bs_api_location | D13: {=INDEX('Not Req'!$E$4:$E$72,MATCH(MID(F13,FIND(".",F13)+1,LEN(F13)-FIND(".",F13)+1),'Not Req'!$D$4:$D$72,0))} -> Description : Classes | E13: =INDEX('Not Req'!$F$4:$F$72,MATCH(MID(F13,FIND(".",F13)+1,LEN(F13)-FIND(".",F13)+1),'Not Req'!$D$4:$D$72,0)) -> 3. Source Code Library | F13: zbp_bs_api_location.clas.xml | G13: API Pattern | H13: 7 months ago | N13: zbs_api_location_endp_o2_iwsg
C14: =LEFT(F14,FIND(".",F14)-1) -> zcl_bs_api_target | D14: {=INDEX('Not Req'!$E$4:$E$72,MATCH(MID(F14,FIND(".",F14)+1,LEN(F14)-FIND(".",F14)+1),'Not Req'!$D$4:$D$72,0))} -> Description : Classes | E14: =INDEX('Not Req'!$F$4:$F$72,MATCH(MID(F14,FIND(".",F14)+1,LEN(F14)-FIND(".",F14)+1),'Not Req'!$D$4:$D$72,0)) -> 3. Source Code Library | F14: zcl_bs_api_target.clas.xml | G14: API Pattern | H14: 7 months ago | N14: zbs_api_location_endp_o2_iwsg_ibs
C15: =LEFT(F15,FIND(".",F15)-1) -> zbs_api_location_endpoint | D15: {=INDEX('Not Req'!$E$4:$E$72,MATCH(MID(F15,FIND(".",F15)+1,LEN(F15)-FIND(".",F15)+1),'Not Req'!$D$4:$D$72,0))} -> Service Definition | E15: =INDEX('Not Req'!$F$4:$F$72,MATCH(MID(F15,FIND(".",F15)+1,LEN(F15)-FIND(".",F15)+1),'Not Req'!$D$4:$D$72,0)) -> Business Services | F15: zbs_api_location_endpoint.srvd.srvdsrv | G15: API Pattern | H15: 7 months ago
C16: =LEFT(F16,FIND(".",F16)-1) -> 710df9f0500c0069d677cc915293cbht | D16: {=INDEX('Not Req'!$E$4:$E$72,MATCH(MID(F16,FIND(".",F16)+1,LEN(F16)-FIND(".",F16)+1),'Not Req'!$D$4:$D$72,0))} -> Internal (Not Req) | E16: =INDEX('Not Req'!$F$4:$F$72,MATCH(MID(F16,FIND(".",F16)+1,LEN(F16)-FIND(".",F16)+1),'Not Req'!$D$4:$D$72,0)) -> Internal (Not Req) | F16: 710df9f0500c0069d677cc915293cbht.sush.xml | G16: API Pattern | H16: 7 months ago
C17: =LEFT(F17,FIND(".",F17)-1) -> 782ebdfdd92774c39297d4948c3981ht | D17: {=INDEX('Not Req'!$E$4:$E$72,MATCH(MID(F17,FIND(".",F17)+1,LEN(F17)-FIND(".",F17)+1),'Not Req'!$D$4:$D$72,0))} -> Internal (Not Req) | E17: =INDEX('Not Req'!$F$4:$F$72,MATCH(MID(F17,FIND(".",F17)+1,LEN(F17)-FIND(".",F17)+1),'Not Req'!$D$4:$D$72,0)) -> Internal (Not Req) | F17: 782ebdfdd92774c39297d4948c3981ht.sush.xml | G17: API Pattern | H17: 7 months ago
C18: =LEFT(F18,FIND(".",F18)-1) -> zbs_api_location_endp_o2 | D18: {=INDEX('Not Req'!$E$4:$E$72,MATCH(MID(F18,FIND(".",F18)+1,LEN(F18)-FIND(".",F18)+1),'Not Req'!$D$4:$D$72,0))} -> Internal (Not Req) | E18: =INDEX('Not Req'!$F$4:$F$72,MATCH(MID(F18,FIND(".",F18)+1,LEN(F18)-FIND(".",F18)+1),'Not Req'!$D$4:$D$72,0)) -> Internal (Not Req) | F18: zbs_api_location_endp_o2.srvb.xml | G18: API Pattern | H18: 7 months ago
C19: =LEFT(F19,FIND(".",F19)-1) -> zbs_api_location_endp_o2_iwsg | D19: {=INDEX('Not Req'!$E$4:$E$72,MATCH(MID(F19,FIND(".",F19)+1,LEN(F19)-FIND(".",F19)+1),'Not Req'!$D$4:$D$72,0))} -> Internal (Not Req) | E19: =INDEX('Not Req'!$F$4:$F$72,MATCH(MID(F19,FIND(".",F19)+1,LEN(F19)-FIND(".",F19)+1),'Not Req'!$D$4:$D$72,0)) -> Internal (Not Req) | F19: zbs_api_location_endp_o2_iwsg.sco2.xml | G19: API Pattern | H19: 7 months ago
C20: =LEFT(F20,FIND(".",F20)-1) -> zbs_api_location_endp_o2_iwsg_ibs | D20: {=INDEX('Not Req'!$E$4:$E$72,MATCH(MID(F20,FIND(".",F20)+1,LEN(F20)-FIND(".",F20)+1),'Not Req'!$D$4:$D$72,0))} -> Internal (Not Req) | E20: =INDEX('Not Req'!$F$4:$F$72,MATCH(MID(F20,FIND(".",F20)+1,LEN(F20)-FIND(".",F20)+1),'Not Req'!$D$4:$D$72,0)) -> Internal (Not Req) | F20: zbs_api_location_endp_o2_iwsg_ibs.sia6.xml | G20: API Pattern | H20: 7 months ago
C21: =LEFT(F21,FIND(".",F21)-1) -> zbs_api_location_endpoint | D21: {=INDEX('Not Req'!$E$4:$E$72,MATCH(MID(F21,FIND(".",F21)+1,LEN(F21)-FIND(".",F21)+1),'Not Req'!$D$4:$D$72,0))} -> Internal (Not Req) | E21: =INDEX('Not Req'!$F$4:$F$72,MATCH(MID(F21,FIND(".",F21)+1,LEN(F21)-FIND(".",F21)+1),'Not Req'!$D$4:$D$72,0)) -> Internal (Not Req) | F21: zbs_api_location_endpoint.srvd.xml | G21: API Pattern | H21: 7 months ago
A22: D | B22: D | C22: =LEFT(F22,FIND(".",F22)-1) -> zbs_r_apilocation | D22: {=INDEX('Not Req'!$E$4:$E$72,MATCH(MID(F22,FIND(".",F22)+1,LEN(F22)-FIND(".",F22)+1),'Not Req'!$D$4:$D$72,0))} -> Internal (Not Req) | E22: =INDEX('Not Req'!$F$4:$F$72,MATCH(MID(F22,FIND(".",F22)+1,LEN(F22)-FIND(".",F22)+1),'Not Req'!$D$4:$D$72,0)) -> Internal (Not Req) | F22: zbs_r_apilocation.ddls.baseinfo | G22: API Pattern | H22: 7 months ago

Sheet PATTERN CUSTOM
B2: d | C2: Object | D2: Type | E2: Category | F2: Github Object | G2: Github Type | H2: Version
B4: 1 | C4: =LEFT(F4,FIND(".",F4)-1) -> package | D4: {=INDEX('Not Req'!$E$4:$E$72,MATCH(MID(F4,FIND(".",F4)+1,LEN(F4)-FIND(".",F4)+1),'Not Req'!$D$4:$D$72,0))} -> Description : Package | E4: =INDEX('Not Req'!$F$4:$F$72,MATCH(MID(F4,FIND(".",F4)+1,LEN(F4)-FIND(".",F4)+1),'Not Req'!$D$4:$D$72,0)) -> 0. Package | F4: package.devc.xml | G4: CDS Pattern | H4: 2 months ago | N4: {=_xlfn.UNIQUE(C4:C21)} -> package
C5: =LEFT(F5,FIND(".",F5)-1) -> zbs_demo_dcp_appl | D5: {=INDEX('Not Req'!$E$4:$E$72,MATCH(MID(F5,FIND(".",F5)+1,LEN(F5)-FIND(".",F5)+1),'Not Req'!$D$4:$D$72,0))} -> Data Element | E5: =INDEX('Not Req'!$F$4:$F$72,MATCH(MID(F5,FIND(".",F5)+1,LEN(F5)-FIND(".",F5)+1),'Not Req'!$D$4:$D$72,0)) -> 1. Dictionary | F5: zbs_demo_dcp_appl.dtel.xml | G5: Custom Pattern (Behavior) | H5: 9 months ago | N5: zbs_demo_dcp_appl
C6: =LEFT(F6,FIND(".",F6)-1) -> zbs_demo_dcp_staging | D6: {=INDEX('Not Req'!$E$4:$E$72,MATCH(MID(F6,FIND(".",F6)+1,LEN(F6)-FIND(".",F6)+1),'Not Req'!$D$4:$D$72,0))} -> Data Element | E6: =INDEX('Not Req'!$F$4:$F$72,MATCH(MID(F6,FIND(".",F6)+1,LEN(F6)-FIND(".",F6)+1),'Not Req'!$D$4:$D$72,0)) -> 1. Dictionary | F6: zbs_demo_dcp_staging.dtel.xml | G6: Custom Pattern (Behavior) | H6: 9 months ago | N6: zbs_demo_dcp_staging
C7: =LEFT(F7,FIND(".",F7)-1) -> zbs_demo_dcp_team | D7: {=INDEX('Not Req'!$E$4:$E$72,MATCH(MID(F7,FIND(".",F7)+1,LEN(F7)-FIND(".",F7)+1),'Not Req'!$D$4:$D$72,0))} -> Data Element | E7: =INDEX('Not Req'!$F$4:$F$72,MATCH(MID(F7,FIND(".",F7)+1,LEN(F7)-FIND(".",F7)+1),'Not Req'!$D$4:$D$72,0)) -> 1. Dictionary | F7: zbs_demo_dcp_team.dtel.xml | G7: Custom Pattern (Behavior) | H7: 9 months ago | N7: zbs_demo_dcp_team
C8: =LEFT(F8,FIND(".",F8)-1) -> zbs_demo_dcp_text | D8: {=INDEX('Not Req'!$E$4:$E$72,MATCH(MID(F8,FIND(".",F8)+1,LEN(F8)-FIND(".",F8)+1),'Not Req'!$D$4:$D$72,0))} -> Data Element | E8: =INDEX('Not Req'!$F$4:$F$72,MATCH(MID(F8,FIND(".",F8)+1,LEN(F8)-FIND(".",F8)+1),'Not Req'!$D$4:$D$72,0)) -> 1. Dictionary | F8: zbs_demo_dcp_text.dtel.xml | G8: Custom Pattern (Behavior) | H8: 9 months ago | N8: zbs_demo_dcp_text
C9: =LEFT(F9,FIND(".",F9)-1) -> zbs_demo_dcp_staging | D9: {=INDEX('Not Req'!$E$4:$E$72,MATCH(MID(F9,FIND(".",F9)+1,LEN(F9)-FIND(".",F9)+1),'Not Req'!$D$4:$D$72,0))} -> Domain | E9: =INDEX('Not Req'!$F$4:$F$72,MATCH(MID(F9,FIND(".",F9)+1,LEN(F9)-FIND(".",F9)+1),'Not Req'!$D$4:$D$72,0)) -> 1. Dictionary | F9: zbs_demo_dcp_staging.doma.xml | G9: Custom Pattern (Behavior) | H9: 9 months ago | N9: zbs_dcp
C10: =LEFT(F10,FIND(".",F10)-1) -> zbs_demo_dcp_text | D10: {=INDEX('Not Req'!$E$4:$E$72,MATCH(MID(F10,FIND(".",F10)+1,LEN(F10)-FIND(".",F10)+1),'Not Req'!$D$4:$D$72,0))} -> Domain | E10: =INDEX('Not Req'!$F$4:$F$72,MATCH(MID(F10,FIND(".",F10)+1,LEN(F10)-FIND(".",F10)+1),'Not Req'!$D$4:$D$72,0)) -> 1. Dictionary | F10: zbs_demo_dcp_text.doma.xml | G10: Custom Pattern (Behavior) | H10: 9 months ago | N10: zbs_dcp_appl
C11: =LEFT(F11,FIND(".",F11)-1) -> zbs_dcp | D11: {=INDEX('Not Req'!$E$4:$E$72,MATCH(MID(F11,FIND(".",F11)+1,LEN(F11)-FIND(".",F11)+1),'Not Req'!$D$4:$D$72,0))} -> Table | E11: =INDEX('Not Req'!$F$4:$F$72,MATCH(MID(F11,FIND(".",F11)+1,LEN(F11)-FIND(".",F11)+1),'Not Req'!$D$4:$D$72,0)) -> 1. Dictionary | F11: zbs_dcp.tabl.xml | G11: Custom Pattern (Behavior) | H11: 9 months ago | N11: zbs_dcp_team
C12: =LEFT(F12,FIND(".",F12)-1) -> zbs_dcp_appl | D12: {=INDEX('Not Req'!$E$4:$E$72,MATCH(MID(F12,FIND(".",F12)+1,LEN(F12)-FIND(".",F12)+1),'Not Req'!$D$4:$D$72,0))} -> Table | E12: =INDEX('Not Req'!$F$4:$F$72,MATCH(MID(F12,FIND(".",F12)+1,LEN(F12)-FIND(".",F12)+1),'Not Req'!$D$4:$D$72,0)) -> 1. Dictionary | F12: zbs_dcp_appl.tabl.xml | G12: Optimize search | H12: 9 months ago | N12: zbs_r_dcpsoftwarecomponent
C13: =LEFT(F13,FIND(".",F13)-1) -> zbs_dcp_team | D13: {=INDEX('Not Req'!$E$4:$E$72,MATCH(MID(F13,FIND(".",F13)+1,LEN(F13)-FIND(".",F13)+1),'Not Req'!$D$4:$D$72,0))} -> Table | E13: =INDEX('Not Req'!$F$4:$F$72,MATCH(MID(F13,FIND(".",F13)+1,LEN(F13)-FIND(".",F13)+1),'Not Req'!$D$4:$D$72,0)) -> 1. Dictionary | F13: zbs_dcp_team.tabl.xml | G13: Optimize search | H13: 9 months ago | N13: zbs_i_cpstagingvh
C14: =LEFT(F14,FIND(".",F14)-1) -> zbs_r_dcpsoftwarecomponent | D14: {=INDEX('Not Req'!$E$4:$E$72,MATCH(MID(F14,FIND(".",F14)+1,LEN(F14)-FIND(".",F14)+1),'Not Req'!$D$4:$D$72,0))} -> BDEF | E14: =INDEX('Not Req'!$F$4:$F$72,MATCH(MID(F14,FIND(".",F14)+1,LEN(F14)-FIND(".",F14)+1),'Not Req'!$D$4:$D$72,0)) -> 2. CDS | F14: zbs_r_dcpsoftwarecomponent.bdef.asbdef | G14: Message length | H14: 9 months ago | N14: zbs_i_dcpapplicationvh
C15: =LEFT(F15,FIND(".",F15)-1) -> zbs_i_cpstagingvh | D15: {=INDEX('Not Req'!$E$4:$E$72,MATCH(MID(F15,FIND(".",F15)+1,LEN(F15)-FIND(".",F15)+1),'Not Req'!$D$4:$D$72,0))} -> Data Definition | E15: =INDEX('Not Req'!$F$4:$F$72,MATCH(MID(F15,FIND(".",F15)+1,LEN(F15)-FIND(".",F15)+1),'Not Req'!$D$4:$D$72,0)) -> 2. CDS | F15: zbs_i_cpstagingvh.ddls.asddls | G15: Fixed Value Help | H15: 9 months ago | N15: zbs_i_dcpteamvh
C16: =LEFT(F16,FIND(".",F16)-1) -> zbs_i_dcpapplicationvh | D16: {=INDEX('Not Req'!$E$4:$E$72,MATCH(MID(F16,FIND(".",F16)+1,LEN(F16)-FIND(".",F16)+1),'Not Req'!$D$4:$D$72,0))} -> Data Definition | E16: =INDEX('Not Req'!$F$4:$F$72,MATCH(MID(F16,FIND(".",F16)+1,LEN(F16)-FIND(".",F16)+1),'Not Req'!$D$4:$D$72,0)) -> 2. CDS | F16: zbs_i_dcpapplicationvh.ddls.asddls | G16: Optimize search | H16: 9 months ago
C17: =LEFT(F17,FIND(".",F17)-1) -> zbs_i_dcpteamvh | D17: {=INDEX('Not Req'!$E$4:$E$72,MATCH(MID(F17,FIND(".",F17)+1,LEN(F17)-FIND(".",F17)+1),'Not Req'!$D$4:$D$72,0))} -> Data Definition | E17: =INDEX('Not Req'!$F$4:$F$72,MATCH(MID(F17,FIND(".",F17)+1,LEN(F17)-FIND(".",F17)+1),'Not Req'!$D$4:$D$72,0)) -> 2. CDS | F17: zbs_i_dcpteamvh.ddls.asddls | G17: Optimize search | H17: 9 months ago
C18: =LEFT(F18,FIND(".",F18)-1) -> zbs_r_dcpsoftwarecomponent | D18: {=INDEX('Not Req'!$E$4:$E$72,MATCH(MID(F18,FIND(".",F18)+1,LEN(F18)-FIND(".",F18)+1),'Not Req'!$D$4:$D$72,0))} -> Data Definition | E18: =INDEX('Not Req'!$F$4:$F$72,MATCH(MID(F18,FIND(".",F18)+1,LEN(F18)-FIND(".",F18)+1),'Not Req'!$D$4:$D$72,0)) -> 2. CDS | F18: zbs_r_dcpsoftwarecomponent.ddls.asddls | G18: Message length | H18: 9 months ago
C19: =LEFT(F19,FIND(".",F19)-1) -> zbs_r_dcpsoftwarecomponent | D19: {=INDEX('Not Req'!$E$4:$E$72,MATCH(MID(F19,FIND(".",F19)+1,LEN(F19)-FIND(".",F19)+1),'Not Req'!$D$4:$D$72,0))} -> Description : BDEF | E19: =INDEX('Not Req'!$F$4:$F$72,MATCH(MID(F19,FIND(".",F19)+1,LEN(F19)-FIND(".",F19)+1),'Not Req'!$D$4:$D$72,0)) -> 2. CDS | F19: zbs_r_dcpsoftwarecomponent.bdef.xml | G19: Custom Pattern (Behavior) | H19: 9 months ago
C20: =LEFT(F20,FIND(".",F20)-1) -> zbs_i_cpstagingvh | D20: {=INDEX('Not Req'!$E$4:$E$72,MATCH(MID(F20,FIND(".",F20)+1,LEN(F20)-FIND(".",F20)+1),'Not Req'!$D$4:$D$72,0))} -> Description : Data Definition | E20: =INDEX('Not Req'!$F$4:$F$72,MATCH(MID(F20,FIND(".",F20)+1,LEN(F20)-FIND(".",F20)+1),'Not Req'!$D$4:$D$72,0)) -> 2. CDS | F20: zbs_i_cpstagingvh.ddls.xml | G20: Fixed Value Help | H20: 9 months ago
C21: =LEFT(F21,FIND(".",F21)-1) -> zbs_i_dcpapplicationvh | D21: {=INDEX('Not Req'!$E$4:$E$72,MATCH(MID(F21,FIND(".",F21)+1,LEN(F21)-FIND(".",F21)+1),'Not Req'!$D$4:$D$72,0))} -> Description : Data Definition | E21: =INDEX('Not Req'!$F$4:$F$72,MATCH(MID(F21,FIND(".",F21)+1,LEN(F21)-FIND(".",F21)+1),'Not Req'!$D$4:$D$72,0)) -> 2. CDS | F21: zbs_i_dcpapplicationvh.ddls.xml | G21: Optimize search | H21: 9 months ago
C22: =LEFT(F22,FIND(".",F22)-1) -> zbs_i_dcpteamvh | D22: {=INDEX('Not Req'!$E$4:$E$72,MATCH(MID(F22,FIND(".",F22)+1,LEN(F22)-FIND(".",F22)+1),'Not Req'!$D$4:$D$72,0))} -> Description : Data Definition | E22: =INDEX('Not Req'!$F$4:$F$72,MATCH(MID(F22,FIND(".",F22)+1,LEN(F22)-FIND(".",F22)+1),'Not Req'!$D$4:$D$72,0)) -> 2. CDS | F22: zbs_i_dcpteamvh.ddls.xml | G22: Optimize search | H22: 9 months ago
