Workbook

Sheet zmm_t_dc_iut
C4: @EndUserText.label : 'DC details IUT Item'
C5: @AbapCatalog.enhancement.category : #NOT_EXTENSIBLE
C6: @AbapCatalog.tableCategory : #TRANSPARENT
C7: @AbapCatalog.deliveryClass : #A
C8: @AbapCatalog.dataMaintenance : #ALLOWED
C9: define table zmm_t_dc_iut {
C11: key mandt : mandt not null; | K11: =IFERROR(TRIM(MID(C11,1,FIND(":",C11)-1)),"") -> key mandt
C12: key dc_num : zdc_num not null; | K12: =IFERROR(TRIM(MID(C12,1,FIND(":",C12)-1)),"") -> key dc_num
C13: key dc_item : zdc_item not null; | K13: =IFERROR(TRIM(MID(C13,1,FIND(":",C13)-1)),"") -> key dc_item
C14: dc_type : zdc_type; | K14: =IFERROR(TRIM(MID(C14,1,FIND(":",C14)-1)),"") -> dc_type
C15: from_plant : zfrom_plant; | K15: =IFERROR(TRIM(MID(C15,1,FIND(":",C15)-1)),"") -> from_plant
C16: to_plant : zto_plant; | K16: =IFERROR(TRIM(MID(C16,1,FIND(":",C16)-1)),"") -> to_plant
C17: plant : werks_d; | K17: =IFERROR(TRIM(MID(C17,1,FIND(":",C17)-1)),"") -> plant
C18: to_vend : zvend; | K18: =IFERROR(TRIM(MID(C18,1,FIND(":",C18)-1)),"") -> to_vend
C19: matnr : matnr; | K19: =IFERROR(TRIM(MID(C19,1,FIND(":",C19)-1)),"") -> matnr
C20: mat_desc : maktx; | K20: =IFERROR(TRIM(MID(C20,1,FIND(":",C20)-1)),"") -> mat_desc
C21: vrkme : vrkme; | K21: =IFERROR(TRIM(MID(C21,1,FIND(":",C21)-1)),"") -> vrkme
C22: @Semantics.quantity.unitOfMeasure : 'vbrp.vrkme' | K22: =IFERROR(TRIM(MID(C22,1,FIND(":",C22)-1)),"") -> @Semantics.quantity.unitOfMeasure
... C69: taxval : ztax_value; | K69: =IFERROR(TRIM(MID(C69,1,FIND(":",C69)-1)),"") -> taxval
K70: =IFERROR(TRIM(MID(C70,1,FIND(":",C70)-1)),"")
C71: } | K71: =IFERROR(TRIM(MID(C71,1,FIND(":",C71)-1)),"")
C72: ------------------------------------- | K72: =IFERROR(TRIM(MID(C72,1,FIND(":",C72)-1)),"")
C73: @EndUserText.label : 'DC deatils header table IUT' | K73: =IFERROR(TRIM(MID(C73,1,FIND(":",C73)-1)),"") -> @EndUserText.label
C74: @AbapCatalog.enhancement.category : #NOT_EXTENSIBLE | K74: =IFERROR(TRIM(MID(C74,1,FIND(":",C74)-1)),"") -> @AbapCatalog.enhancement.category
C75: @AbapCatalog.tableCategory : #TRANSPARENT | K75: =IFERROR(TRIM(MID(C75,1,FIND(":",C75)-1)),"") -> @AbapCatalog.tableCategory
C76: @AbapCatalog.deliveryClass : #A | K76: =IFERROR(TRIM(MID(C76,1,FIND(":",C76)-1)),"") -> @AbapCatalog.deliveryClass
C77: @AbapCatalog.dataMaintenance : #ALLOWED | K77: =IFERROR(TRIM(MID(C77,1,FIND(":",C77)-1)),"") -> @AbapCatalog.dataMaintenance
C78: define table zmm_t_dc_iut_hd { | K78: =IFERROR(TRIM(MID(C78,1,FIND(":",C78)-1)),"")
K79: =IFERROR(TRIM(MID(C79,1,FIND(":",C79)-1)),"")
C80: key mandt : mandt not null; | K80: =IFERROR(TRIM(MID(C80,1,FIND(":",C80)-1)),"") -> key mandt
C81: key dc_num : zdc_num not null; | K81: =IFERROR(TRIM(MID(C81,1,FIND(":",C81)-1)),"") -> key dc_num
C82: to_vend : zvend; | K82: =IFERROR(TRIM(MID(C82,1,FIND(":",C82)-1)),"") -> to_vend
C83: @Semantics.amount.currencyCode : 'vbak.waerk' | K83: =IFERROR(TRIM(MID(C83,1,FIND(":",C83)-1)),"") -> @Semantics.amount.currencyCode
C84: grand_total : zgrand_tot; | K84: =IFERROR(TRIM(MID(C84,1,FIND(":",C84)-1)),"") -> grand_total
C85: @Semantics.amount.currencyCode : 'vbak.waerk' | K85: =IFERROR(TRIM(MID(C85,1,FIND(":",C85)-1)),"") -> @Semantics.amount.currencyCode
C86: total_tax : ztax_value; | K86: =IFERROR(TRIM(MID(C86,1,FIND(":",C86)-1)),"") -> total_tax
C87: @Semantics.quantity.unitOfMeasure : 'vbrp.vrkme' | K87: =IFERROR(TRIM(MID(C87,1,FIND(":",C87)-1)),"") -> @Semantics.quantity.unitOfMeasure
C88: total_qty : zbundle_qty; | K88: =IFERROR(TRIM(MID(C88,1,FIND(":",C88)-1)),"") -> total_qty
C89: @Semantics.amount.currencyCode : 'vbak.waerk' | K89: =IFERROR(TRIM(MID(C89,1,FIND(":",C89)-1)),"") -> @Semantics.amount.currencyCode
C90: taxable_amount : ztax_value; | K90: =IFERROR(TRIM(MID(C90,1,FIND(":",C90)-1)),"") -> taxable_amount
...

Sheet Sheet1
B1: LocationGstin | C1: Pass the DC number and Item to ZMM_T_DC_IUT & get FROM_GSTIN | E1: ZMM_T_DC_IUT | F1: FROM_GSTIN | G1: =MATCH(B1,ZSD_S_GLOBAL_ST!$I$9:$I$239,0) -> #N/A
B2: Purpose | C2: EWB | G2: =MATCH(B2,ZSD_S_GLOBAL_ST!$I$9:$I$239,0) -> #N/A
B3: SupplyType | C3: S | G3: =MATCH(B3,ZSD_S_GLOBAL_ST!$I$9:$I$239,0) -> #N/A
B4: DocumentType | C4: CHL | G4: =MATCH(B4,ZSD_S_GLOBAL_ST!$I$9:$I$239,0) -> #N/A
B5: TransactionType | C5: OWN | G5: =MATCH(B5,ZSD_S_GLOBAL_ST!$I$9:$I$239,0) -> #N/A
B6: DocumentNumber | C6: Pass dc number input screen | G6: =MATCH(B6,ZSD_S_GLOBAL_ST!$I$9:$I$239,0) -> #N/A
B7: DocumentDate | C7: Pass the DC number and Item to ZMM_T_DC_IUT_HD & get CREATED_AT | E7: ZMM_T_DC_IUT_HD | F7: CREATED_AT | G7: =MATCH(B7,ZSD_S_GLOBAL_ST!$I$9:$I$239,0) -> #N/A
B8: BillFromGstin | C8: Pass the DC number and Item to ZMM_T_DC_IUT & get FROM_GSTIN | E8: ZMM_T_DC_IUT | F8: FROM_GSTIN | G8: =MATCH(B8,ZSD_S_GLOBAL_ST!$I$9:$I$239,0) -> #N/A
B9: BillFromAddress1 | C9: Pass the DC number and Item to ZMM_T_DC_IUT & get FROM_ADDRESS | E9: ZMM_T_DC_IUT | F9: FROM_ADDRESS | G9: =MATCH(B9,ZSD_S_GLOBAL_ST!$I$9:$I$239,0) -> #N/A
B10: BillFromStateCode | C10: Pass the DC number and Item to ZMM_T_DC_IUT & get FROM_PLANT pass to LFA1 & get REGIO | E10: ZMM_T_DC_IUT | F10: FROM_PLANT | G10: =MATCH(B10,ZSD_S_GLOBAL_ST!$I$9:$I$239,0) -> #N/A
B11: BillFromPincode | C11: Pass the DC number and Item to ZMM_T_DC_IUT & get FROM_PLANT pass to LFA1 & get PSTLZ | E11: ZMM_T_DC_IUT | F11: FROM_PLANT | G11: =MATCH(B11,ZSD_S_GLOBAL_ST!$I$9:$I$239,0) -> #N/A
B12: BillToGstin | C12: Pass the DC number and Item to ZMM_T_DC_IUT & get TO_GSTIN | E12: ZMM_T_DC_IUT | F12: TO_GSTIN | G12: =MATCH(B12,ZSD_S_GLOBAL_ST!$I$9:$I$239,0) -> #N/A
B13: BillToTradeName | C13: Pass the DC number and Item to ZMM_T_DC_IUT & get VENDOR_NAME | E13: ZMM_T_DC_IUT | F13: VENDOR_NAME | G13: =MATCH(B13,ZSD_S_GLOBAL_ST!$I$9:$I$239,0) -> #N/A
B14: BillToAddress1 | C14: Pass the DC number and Item to ZMM_T_DC_IUT & get TO_ADDRESS | E14: ZMM_T_DC_IUT | F14: TO_ADDRESS | G14: =MATCH(B14,ZSD_S_GLOBAL_ST!$I$9:$I$239,0) -> #N/A
B15: BillToStateCode | C15: Pass the DC number and Item to ZMM_T_DC_IUT & get TO_PLANT pass to LFA1 & get REGIO | E15: ZMM_T_DC_IUT | F15: TO_PLANT | G15: =MATCH(B15,ZSD_S_GLOBAL_ST!$I$9:$I$239,0) -> #N/A
B16: BillToPincode | C16: Pass the DC number and Item to ZMM_T_DC_IUT & get TO_PLANT pass to LFA1 & get PSTLZ | E16: ZMM_T_DC_IUT | F16: TO_PLANT | G16: =MATCH(B16,ZSD_S_GLOBAL_ST!$I$9:$I$239,0) -> #N/A
B17: DocumentValue | C17: Pass the DC number to ZMM_T_DC_IUT_HD & get TAXABLE_AMOUNT | E17: ZMM_T_DC_IUT_HD | F17: TAXABLE_AMOUNT | G17: =MATCH(B17,ZSD_S_GLOBAL_ST!$I$9:$I$239,0) -> #N/A
B18: Hsn | C18: Pass the DC number and Item to ZMM_T_DC_IUT & get HSN | E18: ZMM_T_DC_IUT | F18: HSN | G18: =MATCH(B18,ZSD_S_GLOBAL_ST!$I$9:$I$239,0) -> #N/A
... B25: SgstAmount | C25: Pass the DC number and Item to ZMM_T_DC_IUT & get SGST_PERCENT | E25: ZMM_T_DC_IUT | F25: SGST_PERCENT | G25: =MATCH(B25,ZSD_S_GLOBAL_ST!$I$9:$I$239,0) -> #N/A

Sheet Sheet2

Sheet Required OBJ
E2: Availability | F2: Data Elements | K2: CDS & Tables
E3: =MATCH(F3,'Resolved Data Elem'!$D$4:$D$774,0) -> 227 | F3: zde_pos | G3: abap.char(2); | I3: Done | K3: zsd_c_condition_type | L3: Done
E4: =MATCH(F4,'Resolved Data Elem'!$D$4:$D$774,0) -> 268 | F4: zde_hsn | G4: abap.char(16); | I4: Done | K4: zsd_c_einv_uom | L4: Done
E5: =MATCH(F5,'Resolved Data Elem'!$D$4:$D$774,0) -> 269 | F5: zde_itemname | G5: abap.char(100); | I5: Done | K5: zsd_c_billtype | L5: Done
E6: =MATCH(F6,'Resolved Data Elem'!$D$4:$D$774,0) -> 270 | F6: zde_item_description | G6: abap.char(200); | I6: Done | K6: zsd_c_supply_detail | L6: Done
E7: =MATCH(F7,'Resolved Data Elem'!$D$4:$D$774,0) -> 275 | F7: zde_uqc | G7: abap.char(3); | I7: Done | K7: zsd_c_einv | L7: Done
E8: =MATCH(F8,'Resolved Data Elem'!$D$4:$D$774,0) -> 279 | F8: zde_rate11 | G8: abap.char(18); | I8: Done | K8: zsd_s_global_st | L8: Done | N8: In progress
K9: zsd_t_einv | L9: Done
E10: =MATCH(F10,'Resolved Data Elem'!$D$4:$D$774,0) -> 67 | F10: zde_transporter_id | G10: abap.char(20); | I10: Done | K10: zfi_t_doctype | L10: Done
E11: =MATCH(F11,'Resolved Data Elem'!$D$4:$D$774,0) -> 68 | F11: zde_transporter_name | G11: abap.char(100); | I11: Done
E12: =MATCH(F12,'Resolved Data Elem'!$D$4:$D$774,0) -> 69 | F12: zde_tranport_mode | G12: abap.char(10); | I12: Done
E13: =MATCH(F13,'Resolved Data Elem'!$D$4:$D$774,0) -> 70 | F13: zde_transporter_doc_num | G13: abap.char(20); | I13: Done
E14: =MATCH(F14,'Resolved Data Elem'!$D$4:$D$774,0) -> 72 | F14: zde_vehicle_number | G14: abap.char(10); | I14: Done
E15: =MATCH(F15,'Resolved Data Elem'!$D$4:$D$774,0) -> 73 | F15: zde_vehicle_type | G15: abap.char(1); | I15: Done

Sheet Resolved Data Elem
C2: First Ref Obj | D2: Data Element | E2: Type
C4: ZSD_T_EINV_LOG | D4: mandt | E4: mandt not null;
C5: ZSD_T_EINV_LOG | D5: xblnr | E5: xblnr not null;
C6: ZSD_T_EINV_LOG | D6: zde_document_date | E6: abap.dats not null;
C7: ZSD_T_EINV_LOG | D7: zde_company_code | E7: abap.char(4) not null;
C8: ZSD_T_EINV_LOG | D8: zde_fiscal_year | E8: abap.numc(4);
C9: ZSD_T_EINV_LOG | D9: zde_location_gstin | E9: abap.char(20);
C10: ZSD_T_EINV_LOG | D10: zde_billfromgstin | E10: abap.char(100);
C11: ZSD_T_EINV_LOG | D11: zde_billfromname | E11: abap.char(100);
C12: ZSD_T_EINV_LOG | D12: zde_billfromadd1 | E12: abap.char(100);
C13: ZSD_T_EINV_LOG | D13: zde_billfromadd2 | E13: abap.char(100);
C14: ZSD_T_EINV_LOG | D14: zde_billfrompincode | E14: abap.char(100);
... C279: ZSD_S_GLOBAL_ST | D279: abap.string(0) | E279: abap.string(0);
C280: ZSD_S_GLOBAL_ST | E280: 'vbrp.meins'
C281: ZSD_S_GLOBAL_ST | D281: menge_d | E281: menge_d;
C282: ZSD_S_GLOBAL_ST | D282: zde_rate11 | E282: abap.char(18);
C283: ZSD_S_GLOBAL_ST | D283: zde_cess_rate | E283: abap.char(20);
C284: ZSD_S_GLOBAL_ST | D284: zde_cess_state_cess_rate | E284: abap.char(20);
C285: ZSD_S_GLOBAL_ST | D285: zde_cess_non_advalorem_rat | E285: abap.char(20);
C286: ZSD_S_GLOBAL_ST | D286: zde_price_per_quantity | E286: abap.char(20);
C287: ZSD_S_GLOBAL_ST | D287: zde_discount_amount | E287: abap.char(20);
C288: ZSD_S_GLOBAL_ST | D288: zde_gross_amount | E288: abap.char(20);
C289: ZSD_S_GLOBAL_ST | D289: zde_other_charges | E289: abap.char(20);
C290: ZSD_S_GLOBAL_ST | D290: zde_taxable_value | E290: abap.char(20);
C291: ZSD_S_GLOBAL_ST | D291: zde_assessable_value | E291: abap.char(15);
C292: ZSD_S_GLOBAL_ST | D292: zde_pretax_value | E292: abap.char(20);
... C320: ZSD_S_GLOBAL_ST | D320: zde_custom_item9 | E320: abap.char(40);
C321: ZSD_S_GLOBAL_ST | E321: 'CUSTOM ITEM10'
C322: ZSD_S_GLOBAL_ST | D322: abap.char(200) | E322: abap.char(200);
C323: ZSD_S_GLOBAL_ST | D323: zde_invoice_no | E323: abap.char(32);
C324: ZSD_S_GLOBAL_ST | D324: abap.string(0) | E324: abap.string(0);
C325: ZSD_S_GLOBAL_ST | D325: zde_invoice_date | E325: abap.char(10);
C326: ZSD_S_GLOBAL_ST | D326: zde_acknumber | E326: abap.char(15);
C327: ZSD_S_GLOBAL_ST | D327: zde_ackdate | E327: abap.char(10);
C328: ZSD_S_GLOBAL_ST | D328: zde_assessable_success | E328: abap.char(1);
C329: ZSD_S_GLOBAL_ST | D329: zde_assessable_fail | E329: abap.char(1);
C330: ZSD_S_GLOBAL_ST | D330: zde_assessable_pending | E330: abap.char(1);
C331: ZSD_S_GLOBAL_ST | D331: zde_assessable_reprocess | E331: abap.char(1);
C332: ZSD_S_GLOBAL_ST | D332: zde_error_des | E332: abap.char(200);
C333: ZSD_S_GLOBAL_ST | D333: zde_referenceid | E333: abap.char(50);
...

Sheet ZFI_T_DOCTYPE
A2: @EndUserText.label : 'FI Billtypes Maintenance Table'
A3: @AbapCatalog.enhancement.category : #NOT_EXTENSIBLE
A4: @AbapCatalog.tableCategory : #TRANSPARENT
A5: @AbapCatalog.deliveryClass : #A
A6: @AbapCatalog.dataMaintenance : #ALLOWED
A7: define table zfi_t_doctype {
A9: key mandt : mandt not null;
A10: key module_type : zde_module not null; | F10: char 10
A11: key blart : blart not null;
A12: doc_type : zde_invoice_subtyp; | F12: char 3
A14: }
J16: zgst_states
J17: ZSD_C_bkpf

Sheet Sheet6
C2: @EndUserText.label : 'GST E-Invoicing Status Maintenance' | K2: @EndUserText.label : 'GST States Codes' | Q2: @EndUserText.label : 'DC details IUT Item' | X2: @EndUserText.label : 'DC deatils header table IUT' | AE2: @EndUserText.label : 'ZMB1A 201 Cost Centre' | AL2: @EndUserText.label : 'E-Invoice Table to display data' | AT2: @EndUserText.label : 'Unit Order Type Master' | BA2: @AbapCatalog.viewEnhancementCategory: [#NONE] | BG2: @AbapCatalog.viewEnhancementCategory: [#NONE]
C3: @AbapCatalog.enhancement.category : #NOT_EXTENSIBLE | K3: @AbapCatalog.enhancement.category : #NOT_EXTENSIBLE | Q3: @AbapCatalog.enhancement.category : #NOT_EXTENSIBLE | X3: @AbapCatalog.enhancement.category : #NOT_EXTENSIBLE | AE3: @AbapCatalog.enhancement.category : #NOT_EXTENSIBLE | AL3: @AbapCatalog.enhancement.category : #NOT_EXTENSIBLE | AT3: @AbapCatalog.enhancement.category : #NOT_EXTENSIBLE | BA3: @AccessControl.authorizationCheck: #NOT_REQUIRED | BG3: @AccessControl.authorizationCheck: #NOT_REQUIRED
C4: @AbapCatalog.tableCategory : #TRANSPARENT | K4: @AbapCatalog.tableCategory : #TRANSPARENT | Q4: @AbapCatalog.tableCategory : #TRANSPARENT | X4: @AbapCatalog.tableCategory : #TRANSPARENT | AE4: @AbapCatalog.tableCategory : #TRANSPARENT | AL4: @AbapCatalog.tableCategory : #TRANSPARENT | AT4: @AbapCatalog.tableCategory : #TRANSPARENT | BA4: @EndUserText.label: 'View for BKPF' | BG4: @EndUserText.label: 'View for BSEG'
C5: @AbapCatalog.deliveryClass : #A | K5: @AbapCatalog.deliveryClass : #A | Q5: @AbapCatalog.deliveryClass : #A | X5: @AbapCatalog.deliveryClass : #A | AE5: @AbapCatalog.deliveryClass : #A | AL5: @AbapCatalog.deliveryClass : #A | AT5: @AbapCatalog.deliveryClass : #A | BA5: @Metadata.ignorePropagatedAnnotations: true | BG5: @Metadata.ignorePropagatedAnnotations: true
C6: @AbapCatalog.dataMaintenance : #ALLOWED | K6: @AbapCatalog.dataMaintenance : #ALLOWED | Q6: @AbapCatalog.dataMaintenance : #ALLOWED | X6: @AbapCatalog.dataMaintenance : #ALLOWED | AE6: @AbapCatalog.dataMaintenance : #ALLOWED | AL6: @AbapCatalog.dataMaintenance : #RESTRICTED | AT6: @AbapCatalog.dataMaintenance : #ALLOWED | BA6: define view entity ZSD_C_bkpf | BG6: define view entity ZSD_C_BSEG
C7: define table zeinv_status { | K7: define table zgst_states { | Q7: define table zmm_t_dc_iut { | X7: define table zmm_t_dc_iut_hd { | AE7: define table zsd_t_201costcnt { | AL7: define table zsd_t_einv { | AT7: define table zsd_t_unitotm { | BA7: as select from bkpf | BG7: as select from bseg
BA8: { | BG8: association to I_CompanyCode as _t001 on _t001.CompanyCode = $projection.Bukrs
C9: key mandt : mandt not null; | K9: key mandt : mandt not null; | Q9: key mandt : mandt not null; | X9: key mandt : mandt not null; | AE9: key mandt : mandt not null; | AL9: key mandt : mandt not null; | AT9: key mandt : mandt not null; | BA9: key bukrs as Bukrs,
C10: key inv_num : vbeln_vf not null; | K10: key region : regio not null; | Q10: key dc_num : abap.char(10) not null; | X10: key dc_num : abap.char(10) not null; | AE10: key kostl : kostl not null; | AL10: key documentnumber : xblnr not null; | AT10: key werks : werks_d not null; | BA10: key belnr as Belnr, | BG10: {
C11: key odn : xblnr not null; | K11: gst_state_code : regio; | Q11: key dc_item : abap.numc(5) not null; | X11: to_vend : abap.char(10); | AE11: key unit_id : abap.char(3) not null; | AL11: locationgstin : abap.char(15); | AT11: key unit_id : abap.char(3) not null; | BA11: key gjahr as Gjahr, | BG11: key bukrs as Bukrs,
C12: inv_date : fkdat; | K12: gst_state_desc : bezei20; | Q12: dc_type : abap.char(20); | X12: @Semantics.amount.currencyCode : 'vbak.waerk' | AE12: key unit_stxt : abap.char(15) not null; | AL12: documentdate : abap.dats not null; | AT12: key dauat : aufart not null; | BA12: blart as Blart, | BG12: key belnr as Belnr,
C13: irn : j_1ig_irn; | Q13: from_plant : abap.char(4); | X13: grand_total : abap.curr(15,2); | AL13: company_code : abap.char(4) not null; | AT13: key j_4kscat : abap.char(16) not null; | BA13: bldat as Bldat, | BG13: key gjahr as Gjahr,
C14: einv_module : abap.char(2); | K14: } | Q14: to_plant : abap.char(4); | X14: @Semantics.amount.currencyCode : 'vbak.waerk' | AE14: } | AL14: purpose : abap.char(13); | AT14: key lgort : lgort_d not null; | BA14: budat as Budat, | BG14: key buzei as Buzei,
C15: proxy_error : abap.char(1); | Q15: plant : werks_d; | X15: total_tax : abap.curr(11,2); | AL15: sapmodule : abap.char(2); | AT15: lgort_n : lgort_d; | BA15: monat as Monat, | BG15: buzid as Buzid,
C16: request_id : abap.int4; | Q16: to_vend : abap.char(10); | X16: @Semantics.quantity.unitOfMeasure : 'vbrp.vrkme' | AL16: fiscalyear : gjahr; | BA16: cpudt as Cpudt, | BG16: augdt as Augdt,
C17: message_type : bapi_mtype; | Q17: matnr : matnr; | X17: total_qty : abap.quan(13,3); | AL17: document : abap.char(12); | AT17: } | BA17: cputm as Cputm, | BG17: augcp as Augcp,
C18: message : zmsg; | Q18: mat_desc : maktx; | X18: @Semantics.amount.currencyCode : 'vbak.waerk' | AL18: branch : bupla; | BA18: aedat as Aedat, | BG18: augbl as Augbl,
C19: status_code : abap.char(10); | Q19: vrkme : vrkme; | X19: taxable_amount : abap.curr(11,2); | AL19: locationname : abap.char(50); | BA19: upddt as Upddt, | BG19: bschl as Bschl,
C20: status_message : abap.char(255); | Q20: @Semantics.quantity.unitOfMeasure : 'vbrp.vrkme' | X20: tot_no_bits_qty : char10; | AL20: returnperiod : abap.char(6); | BA20: wwert as Wwert, | BG20: koart as Koart,
C21: error_code : abap.char(10); | Q21: quantity : abap.quan(13,3); | X21: tot_qty_in_kg_pc : char10; | AL21: liabilitydischargereturnperiod : abap.char(20); | BA21: usnam as Usnam, | BG21: umskz as Umskz,
C22: error_msg : abap.char(255); | Q22: hsn : steuc; | X22: tot_bags_bin_cover : char10; | AL22: autopushorgenerate : abap.char(20); | BA22: tcode as Tcode, | BG22: umsks as Umsks,
C23: created_by : ernam; | Q23: uom : meins; | X23: waerk : waerk; | AL23: supplytype : abap.char(1); | BA23: bvorg as Bvorg, | BG23: zumsk as Zumsk,
C24: created_on : erdat; | Q24: waerk : waerk; | X24: vrkme : vrkme; | AL24: irn : abap.char(64); | BA24: xblnr as Xblnr, | BG24: shkzg as Shkzg,
C25: created_time : erzet; | Q25: @Semantics.amount.currencyCode : 'vbak.waerk' | X25: from_plant : abap.char(4); | AL25: documenttype : abap.char(3); | BA25: dbblg as Dbblg, | BG25: gsber as Gsber,
Q26: rate : abap.curr(11,2); | X26: to_plant : abap.char(4); | AL26: transactiontype : abap.char(6); | BA26: dbblg_gjahr as DbblgGjahr, | BG26: pargb as Pargb,
C27: } | Q27: @Semantics.amount.currencyCode : 'vbak.waerk' | X27: @Semantics.quantity.unitOfMeasure : 'vbrp.vrkme' | AL27: @EndUserText.label : 'DTA Transaction' | BA27: dbblg_bukrs as DbblgBukrs, | BG27: tax_country as TaxCountry,
Q28: taxable_value : abap.curr(11,2); | X28: tot_order_qty : abap.quan(13,3); | AL28: dtatransaction : abap.char(50); | BA28: stblg as Stblg, | BG28: mwskz as Mwskz,
Q29: @Semantics.amount.currencyCode : 'vbak.waerk' | X29: total_bias_weight : char10; | AL29: transactiontypedescription : abap.char(30); | BA29: stjah as Stjah, | BG29: txdat_from as TxdatFrom,
Q30: cgst_amount : abap.curr(15,2); | X30: @Semantics.quantity.unitOfMeasure : 'vbrp.vrkme' | AL30: seriescode : abap.char(15); | BA30: bktxt as Bktxt, | BG30: qsskz as Qsskz,
Q31: cgst_percent : char10; | X31: tot_bundle : abap.quan(13,3); | AL31: referencedocumentnumber : abap.char(16); | BA31: waers as Waers, | BG31: @Semantics.amount.currencyCode : 'waers'
Q32: @Semantics.amount.currencyCode : 'vbak.waerk' | X32: total_no_of_bias : char10; | AL32: referencedocumentdate : abap.char(10); | BA32: kursf as Kursf, | BG32: dmbtr as Dmbtr,
Q33: sgst_amount : abap.curr(15,2); | X33: tot_recut_bag_bins_cover : char10; | AL33: transactionmode : abap.char(20); | BA33: kzwrs as Kzwrs, | BG33: @Semantics.amount.currencyCode : 'waers'
Q34: sgst_percent : char10; | X34: created_by : ernam; | AL34: billfromgstin : abap.char(15); | BA34: kzkrs as Kzkrs, | BG34: wrbtr as Wrbtr,
Q35: @Semantics.amount.currencyCode : 'vbak.waerk' | X35: created_at : timestamp; | AL35: billfromlegalname : abap.char(50); | BA35: bstat as Bstat, | BG35: @Semantics.amount.currencyCode : 'waers'
Q36: grand_total : abap.curr(15,2); | AL36: billfromtradename : abap.char(30); | BA36: xnetb as Xnetb, | BG36: fcsl as Fcsl,
Q37: remarks : char50; | X37: } | AL37: billfrombuildingno : abap.char(60); | BA37: // frath as Frath, | BG37: rfccur as Rfccur,
Q38: to_address : char100; | AL38: billfrombuildingname : abap.char(60); | BA38: xrueb as Xrueb, | BG38: @Semantics.amount.currencyCode : 'waers'
Q39: from_address : char100; | AL39: billfromflatno : abap.char(10); | BA39: glvor as Glvor, | BG39: kzbtr as Kzbtr,
Q40: to_gstin : j_1bstains; | AL40: billfromaddress1 : abap.char(50); | BA40: grpid as Grpid, | BG40: @Semantics.amount.currencyCode : 'waers'
Q41: from_gstin : j_1bstains; | AL41: billfromaddress2 : abap.char(50); | BA41: dokid as Dokid, | BG41: pswbt as Pswbt,
...

Sheet Backup
C3: before added Include
C5: METHOD get_data_for_challan. | M5: lt_unit | O5: lv_total_dmbtr
C6: TYPES: BEGIN OF ty_t001w_rto_tmp, | M6: lt_cost
C7: werks TYPE werks, | M7: lt_twlad
C8: werks1 TYPE kunnr, | M8: lt_mkpf_rto
C9: name1 TYPE name1, | M9: lt_usr21
C10: name2 TYPE name2, | M10: lt_adr6
C11: pstlz TYPE pstlz, | M11: lt_mseg_rto
C12: ort01 TYPE ort01, | M12: lt_ekpo
C13: regio TYPE regio, | M13: lt_aufk
C14: j_1bbranch TYPE j_1bbranch, | M14: lt_t001w_ekko
C15: END OF ty_t001w_rto_tmp. | M15: lt_adrc_ekko | P15: 1 | Q15: Filling Internal Tables
C16: TYPES: BEGIN OF ty_eway_bill_s, | M16: lt_mara_uqc | P16: 2 | Q16: Our Code
C17: branch TYPE char100, | M17: lt_mbew
C18: fiscal_year TYPE char100, | M18: lt_marc_hsn | P18: 3 | Q18: lt_eb_eway_bill_s_disp_rto
C19: from_gstin TYPE char100, | M19: lt_t001_plant
C20: from_name TYPE char100, | M20: lt_adrc_mseg
C21: from_address1 TYPE char100, | M21: lt_branch_plant | P21: 0 | Q21: if_rap_query_provider~select
C22: from_address2 TYPE char100,
C23: from_place TYPE char100,
C24: from_state TYPE char100,
C25: return_period TYPE char100,
C26: actual_from_state TYPE char100,
C27: actual_from_gstin TYPE char100,
C28: act_frm_oth_prty TYPE char100,
C29: from_postal_code TYPE char100,
C30: supply_type TYPE char100,
C31: sub_supply_type TYPE char100,
C32: sub_supply_description TYPE char100,
C33: document_type TYPE char100,
... C1535: ENDIF.

Sheet ZEINV_STATUS
A2: @EndUserText.label : 'GST E-Invoicing Status Maintenance'
A3: @AbapCatalog.enhancement.category : #NOT_EXTENSIBLE
A4: @AbapCatalog.tableCategory : #TRANSPARENT
A5: @AbapCatalog.deliveryClass : #A
A6: @AbapCatalog.dataMaintenance : #ALLOWED
A7: define table zeinv_status { | H7: Field | I7: Data Element
A9: key mandt : mandt not null; | H9: =TRIM(MID(A9,1,FIND(":",A9)-1)) -> key mandt | I9: =IF(ISNUMBER(SEARCH("@",A9)),"",TRIM(SUBSTITUTE(SUBSTITUTE(TRIM(MID(A9,FIND(":",A9)+1,LEN(A9))),";",""),"not null",""))) -> mandt | K9: =MATCH(I9,'Resolved Data Elem'!$D$4:$D$341,0) -> 1
A10: key inv_num : vbeln_vf not null; | H10: =TRIM(MID(A10,1,FIND(":",A10)-1)) -> key inv_num | I10: =IF(ISNUMBER(SEARCH("@",A10)),"",TRIM(SUBSTITUTE(SUBSTITUTE(TRIM(MID(A10,FIND(":",A10)+1,LEN(A10))),";",""),"not null",""))) -> vbeln_vf | K10: =MATCH(I10,'Resolved Data Elem'!$D$4:$D$341,0) -> #N/A
A11: key odn : xblnr not null; | H11: =TRIM(MID(A11,1,FIND(":",A11)-1)) -> key odn | I11: =IF(ISNUMBER(SEARCH("@",A11)),"",TRIM(SUBSTITUTE(SUBSTITUTE(TRIM(MID(A11,FIND(":",A11)+1,LEN(A11))),";",""),"not null",""))) -> xblnr | K11: =MATCH(I11,'Resolved Data Elem'!$D$4:$D$341,0) -> 2
A12: inv_date : fkdat; | H12: =TRIM(MID(A12,1,FIND(":",A12)-1)) -> inv_date | I12: =IF(ISNUMBER(SEARCH("@",A12)),"",TRIM(SUBSTITUTE(SUBSTITUTE(TRIM(MID(A12,FIND(":",A12)+1,LEN(A12))),";",""),"not null",""))) -> fkdat | K12: =MATCH(I12,'Resolved Data Elem'!$D$4:$D$341,0) -> #N/A
A13: irn : j_1ig_irn; | H13: =TRIM(MID(A13,1,FIND(":",A13)-1)) -> irn | I13: =IF(ISNUMBER(SEARCH("@",A13)),"",TRIM(SUBSTITUTE(SUBSTITUTE(TRIM(MID(A13,FIND(":",A13)+1,LEN(A13))),";",""),"not null",""))) -> j_1ig_irn | K13: =MATCH(I13,'Resolved Data Elem'!$D$4:$D$341,0) -> #N/A
A14: einv_module : zeinv_module; | H14: =TRIM(MID(A14,1,FIND(":",A14)-1)) -> einv_module | I14: =IF(ISNUMBER(SEARCH("@",A14)),"",TRIM(SUBSTITUTE(SUBSTITUTE(TRIM(MID(A14,FIND(":",A14)+1,LEN(A14))),";",""),"not null",""))) -> zeinv_module | K14: char 2
A15: proxy_error : zzproxy_error; | H15: =TRIM(MID(A15,1,FIND(":",A15)-1)) -> proxy_error | I15: =IF(ISNUMBER(SEARCH("@",A15)),"",TRIM(SUBSTITUTE(SUBSTITUTE(TRIM(MID(A15,FIND(":",A15)+1,LEN(A15))),";",""),"not null",""))) -> zzproxy_error | K15: char 1
A16: request_id : zzrequest_id; | H16: =TRIM(MID(A16,1,FIND(":",A16)-1)) -> request_id | I16: =IF(ISNUMBER(SEARCH("@",A16)),"",TRIM(SUBSTITUTE(SUBSTITUTE(TRIM(MID(A16,FIND(":",A16)+1,LEN(A16))),";",""),"not null",""))) -> zzrequest_id | K16: int 4 , 10
A17: message_type : bapi_mtype; | H17: =TRIM(MID(A17,1,FIND(":",A17)-1)) -> message_type | I17: =IF(ISNUMBER(SEARCH("@",A17)),"",TRIM(SUBSTITUTE(SUBSTITUTE(TRIM(MID(A17,FIND(":",A17)+1,LEN(A17))),";",""),"not null",""))) -> bapi_mtype | K17: =MATCH(I17,'Resolved Data Elem'!$D$4:$D$341,0) -> #N/A
A18: message : zmsg; | H18: =TRIM(MID(A18,1,FIND(":",A18)-1)) -> message | I18: =IF(ISNUMBER(SEARCH("@",A18)),"",TRIM(SUBSTITUTE(SUBSTITUTE(TRIM(MID(A18,FIND(":",A18)+1,LEN(A18))),";",""),"not null",""))) -> zmsg | K18: char 255
A19: status_code : zstatus_code; | H19: =TRIM(MID(A19,1,FIND(":",A19)-1)) -> status_code | I19: =IF(ISNUMBER(SEARCH("@",A19)),"",TRIM(SUBSTITUTE(SUBSTITUTE(TRIM(MID(A19,FIND(":",A19)+1,LEN(A19))),";",""),"not null",""))) -> zstatus_code | K19: char 10
A20: status_message : zstatus_msg; | H20: =TRIM(MID(A20,1,FIND(":",A20)-1)) -> status_message | I20: =IF(ISNUMBER(SEARCH("@",A20)),"",TRIM(SUBSTITUTE(SUBSTITUTE(TRIM(MID(A20,FIND(":",A20)+1,LEN(A20))),";",""),"not null",""))) -> zstatus_msg | K20: char 255
A21: error_code : zerror_code_bolton; | H21: =TRIM(MID(A21,1,FIND(":",A21)-1)) -> error_code | I21: =IF(ISNUMBER(SEARCH("@",A21)),"",TRIM(SUBSTITUTE(SUBSTITUTE(TRIM(MID(A21,FIND(":",A21)+1,LEN(A21))),";",""),"not null",""))) -> zerror_code_bolton | K21: char 10
A22: error_msg : zerr_msg_bolton; | H22: =TRIM(MID(A22,1,FIND(":",A22)-1)) -> error_msg | I22: =IF(ISNUMBER(SEARCH("@",A22)),"",TRIM(SUBSTITUTE(SUBSTITUTE(TRIM(MID(A22,FIND(":",A22)+1,LEN(A22))),";",""),"not null",""))) -> zerr_msg_bolton | K22: char 255
A23: created_by : ernam; | H23: =TRIM(MID(A23,1,FIND(":",A23)-1)) -> created_by | I23: =IF(ISNUMBER(SEARCH("@",A23)),"",TRIM(SUBSTITUTE(SUBSTITUTE(TRIM(MID(A23,FIND(":",A23)+1,LEN(A23))),";",""),"not null",""))) -> ernam | K23: =MATCH(I23,'Resolved Data Elem'!$D$4:$D$341,0) -> #N/A
A24: created_on : erdat; | H24: =TRIM(MID(A24,1,FIND(":",A24)-1)) -> created_on | I24: =IF(ISNUMBER(SEARCH("@",A24)),"",TRIM(SUBSTITUTE(SUBSTITUTE(TRIM(MID(A24,FIND(":",A24)+1,LEN(A24))),";",""),"not null",""))) -> erdat | K24: =MATCH(I24,'Resolved Data Elem'!$D$4:$D$341,0) -> #N/A
A25: created_time : erzet; | H25: =TRIM(MID(A25,1,FIND(":",A25)-1)) -> created_time | I25: =IF(ISNUMBER(SEARCH("@",A25)),"",TRIM(SUBSTITUTE(SUBSTITUTE(TRIM(MID(A25,FIND(":",A25)+1,LEN(A25))),";",""),"not null",""))) -> erzet | K25: =MATCH(I25,'Resolved Data Elem'!$D$4:$D$341,0) -> #N/A
A27: }

Sheet ZSD_S_GLOBAL_ST
A4: @EndUserText.label : 'Global Structure For API'
A5: @AbapCatalog.enhancement.category : #NOT_EXTENSIBLE | K5: @EndUserText.label : 'Global Structure For API'
K6: @AbapCatalog.enhancement.category : #NOT_EXTENSIBLE
A7: define structure zsd_s_global_st { | H7: Field | I7: Data Element | K7: define structure zsd_s_global_st { | P7: Field | Q7: Data Type
A9: locationgstin : zde_locationgstin; | H9: =TRIM(MID(A9,1,FIND(":",A9)-1)) -> locationgstin | I9: =IF(ISNUMBER(SEARCH("@",A9)),"",TRIM(SUBSTITUTE(SUBSTITUTE(TRIM(MID(A9,FIND(":",A9)+1,LEN(A9))),";",""),"not null",""))) -> zde_locationgstin | K9: locationgstin : abap.char(15); | P9: =TRIM(SUBSTITUTE(MID(K9,1,FIND(":",K9)-1),"key","")) -> locationgstin | Q9: =TRIM(MID(K9,FIND(":",K9)+1,LEN(K9))) -> abap.char(15);
A10: company_code : zde_company_code; | H10: =TRIM(MID(A10,1,FIND(":",A10)-1)) -> company_code | I10: =IF(ISNUMBER(SEARCH("@",A10)),"",TRIM(SUBSTITUTE(SUBSTITUTE(TRIM(MID(A10,FIND(":",A10)+1,LEN(A10))),";",""),"not null",""))) -> zde_company_code | K10: company_code : abap.char(4); | P10: =TRIM(SUBSTITUTE(MID(K10,1,FIND(":",K10)-1),"key","")) -> company_code | Q10: =TRIM(MID(K10,FIND(":",K10)+1,LEN(K10))) -> abap.char(4);
A11: documentnumber : zde_documentnumber; | H11: =TRIM(MID(A11,1,FIND(":",A11)-1)) -> documentnumber | I11: =IF(ISNUMBER(SEARCH("@",A11)),"",TRIM(SUBSTITUTE(SUBSTITUTE(TRIM(MID(A11,FIND(":",A11)+1,LEN(A11))),";",""),"not null",""))) -> zde_documentnumber | K11: documentnumber : abap.char(16); | P11: =TRIM(SUBSTITUTE(MID(K11,1,FIND(":",K11)-1),"key","")) -> documentnumber | Q11: =TRIM(MID(K11,FIND(":",K11)+1,LEN(K11))) -> abap.char(16); | AC11: =IF(ISNUMBER(SEARCH("@",H9)),A9,H9&" : "&IF(AD11="",I9,AD11)&";") -> locationgstin : abap.char(15); | AD11: ="abap.char("&AE11&")" -> abap.char(15) | AE11: 15
A12: documentdate : zde_documentdate; | H12: =TRIM(MID(A12,1,FIND(":",A12)-1)) -> documentdate | I12: =IF(ISNUMBER(SEARCH("@",A12)),"",TRIM(SUBSTITUTE(SUBSTITUTE(TRIM(MID(A12,FIND(":",A12)+1,LEN(A12))),";",""),"not null",""))) -> zde_documentdate | K12: documentdate : abap.char(10); | P12: =TRIM(SUBSTITUTE(MID(K12,1,FIND(":",K12)-1),"key","")) -> documentdate | Q12: =TRIM(MID(K12,FIND(":",K12)+1,LEN(K12))) -> abap.char(10); | AC12: =IF(ISNUMBER(SEARCH("@",H10)),A10,H10&" : "&IF(AD12="",I10,AD12)&";") -> company_code : abap.char(4); | AD12: ="abap.char("&AE12&")" -> abap.char(4) | AE12: 4
A13: purpose : zde_purpose1; | H13: =TRIM(MID(A13,1,FIND(":",A13)-1)) -> purpose | I13: =IF(ISNUMBER(SEARCH("@",A13)),"",TRIM(SUBSTITUTE(SUBSTITUTE(TRIM(MID(A13,FIND(":",A13)+1,LEN(A13))),";",""),"not null",""))) -> zde_purpose1 | K13: purpose : abap.char(13); | P13: =TRIM(SUBSTITUTE(MID(K13,1,FIND(":",K13)-1),"key","")) -> purpose | Q13: =TRIM(MID(K13,FIND(":",K13)+1,LEN(K13))) -> abap.char(13); | AC13: =IF(ISNUMBER(SEARCH("@",H11)),A11,H11&" : "&IF(AD13="",I11,AD13)&";") -> documentnumber : abap.char(16); | AD13: ="abap.char("&AE13&")" -> abap.char(16) | AE13: 16
A14: sapmodule : zde_sapmodule; | H14: =TRIM(MID(A14,1,FIND(":",A14)-1)) -> sapmodule | I14: =IF(ISNUMBER(SEARCH("@",A14)),"",TRIM(SUBSTITUTE(SUBSTITUTE(TRIM(MID(A14,FIND(":",A14)+1,LEN(A14))),";",""),"not null",""))) -> zde_sapmodule | K14: sapmodule : abap.char(2); | P14: =TRIM(SUBSTITUTE(MID(K14,1,FIND(":",K14)-1),"key","")) -> sapmodule | Q14: =TRIM(MID(K14,FIND(":",K14)+1,LEN(K14))) -> abap.char(2); | AC14: =IF(ISNUMBER(SEARCH("@",H12)),A12,H12&" : "&IF(AD14="",I12,AD14)&";") -> documentdate : abap.char(10); | AD14: ="abap.char("&AE14&")" -> abap.char(10) | AE14: 10
A15: fiscalyear : gjahr; | H15: =TRIM(MID(A15,1,FIND(":",A15)-1)) -> fiscalyear | I15: =IF(ISNUMBER(SEARCH("@",A15)),"",TRIM(SUBSTITUTE(SUBSTITUTE(TRIM(MID(A15,FIND(":",A15)+1,LEN(A15))),";",""),"not null",""))) -> gjahr | K15: fiscalyear : gjahr; | P15: =TRIM(SUBSTITUTE(MID(K15,1,FIND(":",K15)-1),"key","")) -> fiscalyear | Q15: =TRIM(MID(K15,FIND(":",K15)+1,LEN(K15))) -> gjahr; | AC15: =IF(ISNUMBER(SEARCH("@",H13)),A13,H13&" : "&IF(AD15="",I13,AD15)&";") -> purpose : abap.char(13); | AD15: ="abap.char("&AE15&")" -> abap.char(13) | AE15: 13
A16: document : zde_document; | H16: =TRIM(MID(A16,1,FIND(":",A16)-1)) -> document | I16: =IF(ISNUMBER(SEARCH("@",A16)),"",TRIM(SUBSTITUTE(SUBSTITUTE(TRIM(MID(A16,FIND(":",A16)+1,LEN(A16))),";",""),"not null",""))) -> zde_document | K16: document : abap.char(12); | P16: =TRIM(SUBSTITUTE(MID(K16,1,FIND(":",K16)-1),"key","")) -> document | Q16: =TRIM(MID(K16,FIND(":",K16)+1,LEN(K16))) -> abap.char(12); | AC16: =IF(ISNUMBER(SEARCH("@",H14)),A14,H14&" : "&IF(AD16="",I14,AD16)&";") -> sapmodule : abap.char(2); | AD16: ="abap.char("&AE16&")" -> abap.char(2) | AE16: 2
A17: branch : bupla; | H17: =TRIM(MID(A17,1,FIND(":",A17)-1)) -> branch | I17: =IF(ISNUMBER(SEARCH("@",A17)),"",TRIM(SUBSTITUTE(SUBSTITUTE(TRIM(MID(A17,FIND(":",A17)+1,LEN(A17))),";",""),"not null",""))) -> bupla | K17: branch : bupla; | P17: =TRIM(SUBSTITUTE(MID(K17,1,FIND(":",K17)-1),"key","")) -> branch | Q17: =TRIM(MID(K17,FIND(":",K17)+1,LEN(K17))) -> bupla; | AC17: =IF(ISNUMBER(SEARCH("@",H15)),A15,H15&" : "&IF(AD17="",I15,AD17)&";") -> fiscalyear : gjahr;
A18: locationname : zde_locationlegalname; | H18: =TRIM(MID(A18,1,FIND(":",A18)-1)) -> locationname | I18: =IF(ISNUMBER(SEARCH("@",A18)),"",TRIM(SUBSTITUTE(SUBSTITUTE(TRIM(MID(A18,FIND(":",A18)+1,LEN(A18))),";",""),"not null",""))) -> zde_locationlegalname | K18: locationname : abap.char(50); | P18: =TRIM(SUBSTITUTE(MID(K18,1,FIND(":",K18)-1),"key","")) -> locationname | Q18: =TRIM(MID(K18,FIND(":",K18)+1,LEN(K18))) -> abap.char(50); | AC18: =IF(ISNUMBER(SEARCH("@",H16)),A16,H16&" : "&IF(AD18="",I16,AD18)&";") -> document : abap.char(12); | AD18: ="abap.char("&AE18&")" -> abap.char(12) | AE18: 12
A19: returnperiod : zde_returnperiod; | H19: =TRIM(MID(A19,1,FIND(":",A19)-1)) -> returnperiod | I19: =IF(ISNUMBER(SEARCH("@",A19)),"",TRIM(SUBSTITUTE(SUBSTITUTE(TRIM(MID(A19,FIND(":",A19)+1,LEN(A19))),";",""),"not null",""))) -> zde_returnperiod | K19: returnperiod : abap.char(6); | P19: =TRIM(SUBSTITUTE(MID(K19,1,FIND(":",K19)-1),"key","")) -> returnperiod | Q19: =TRIM(MID(K19,FIND(":",K19)+1,LEN(K19))) -> abap.char(6); | AC19: =IF(ISNUMBER(SEARCH("@",H17)),A17,H17&" : "&IF(AD19="",I17,AD19)&";") -> branch : bupla;
A20: liabilitydischargereturnperiod : zde_lie_dis_period; | H20: =TRIM(MID(A20,1,FIND(":",A20)-1)) -> liabilitydischargereturnperiod | I20: =IF(ISNUMBER(SEARCH("@",A20)),"",TRIM(SUBSTITUTE(SUBSTITUTE(TRIM(MID(A20,FIND(":",A20)+1,LEN(A20))),";",""),"not null",""))) -> zde_lie_dis_period | K20: liabilitydischargereturnperiod : abap.char(20); | P20: =TRIM(SUBSTITUTE(MID(K20,1,FIND(":",K20)-1),"key","")) -> liabilitydischargereturnperiod | Q20: =TRIM(MID(K20,FIND(":",K20)+1,LEN(K20))) -> abap.char(20); | AC20: =IF(ISNUMBER(SEARCH("@",H18)),A18,H18&" : "&IF(AD20="",I18,AD20)&";") -> locationname : abap.char(50); | AD20: ="abap.char("&AE20&")" -> abap.char(50) | AE20: 50
A21: autopushorgenerate : zde_auto_push_period; | H21: =TRIM(MID(A21,1,FIND(":",A21)-1)) -> autopushorgenerate | I21: =IF(ISNUMBER(SEARCH("@",A21)),"",TRIM(SUBSTITUTE(SUBSTITUTE(TRIM(MID(A21,FIND(":",A21)+1,LEN(A21))),";",""),"not null",""))) -> zde_auto_push_period | K21: autopushorgenerate : abap.char(20); | P21: =TRIM(SUBSTITUTE(MID(K21,1,FIND(":",K21)-1),"key","")) -> autopushorgenerate | Q21: =TRIM(MID(K21,FIND(":",K21)+1,LEN(K21))) -> abap.char(20); | AC21: =IF(ISNUMBER(SEARCH("@",H19)),A19,H19&" : "&IF(AD21="",I19,AD21)&";") -> returnperiod : abap.char(6); | AD21: ="abap.char("&AE21&")" -> abap.char(6) | AE21: 6
A22: supplytype : zde_supplytype; | H22: =TRIM(MID(A22,1,FIND(":",A22)-1)) -> supplytype | I22: =IF(ISNUMBER(SEARCH("@",A22)),"",TRIM(SUBSTITUTE(SUBSTITUTE(TRIM(MID(A22,FIND(":",A22)+1,LEN(A22))),";",""),"not null",""))) -> zde_supplytype | K22: supplytype : abap.char(1); | P22: =TRIM(SUBSTITUTE(MID(K22,1,FIND(":",K22)-1),"key","")) -> supplytype | Q22: =TRIM(MID(K22,FIND(":",K22)+1,LEN(K22))) -> abap.char(1); | AC22: =IF(ISNUMBER(SEARCH("@",H20)),A20,H20&" : "&IF(AD22="",I20,AD22)&";") -> liabilitydischargereturnperiod : abap.char(20); | AD22: ="abap.char("&AE22&")" -> abap.char(20) | AE22: 20
A23: irn : zde_irn1; | H23: =TRIM(MID(A23,1,FIND(":",A23)-1)) -> irn | I23: =IF(ISNUMBER(SEARCH("@",A23)),"",TRIM(SUBSTITUTE(SUBSTITUTE(TRIM(MID(A23,FIND(":",A23)+1,LEN(A23))),";",""),"not null",""))) -> zde_irn1 | K23: irn : abap.char(64); | P23: =TRIM(SUBSTITUTE(MID(K23,1,FIND(":",K23)-1),"key","")) -> irn | Q23: =TRIM(MID(K23,FIND(":",K23)+1,LEN(K23))) -> abap.char(64); | AC23: =IF(ISNUMBER(SEARCH("@",H21)),A21,H21&" : "&IF(AD23="",I21,AD23)&";") -> autopushorgenerate : abap.char(20); | AD23: ="abap.char("&AE23&")" -> abap.char(20) | AE23: 20
A24: documenttype : zde_documenttype; | H24: =TRIM(MID(A24,1,FIND(":",A24)-1)) -> documenttype | I24: =IF(ISNUMBER(SEARCH("@",A24)),"",TRIM(SUBSTITUTE(SUBSTITUTE(TRIM(MID(A24,FIND(":",A24)+1,LEN(A24))),";",""),"not null",""))) -> zde_documenttype | K24: documenttype : abap.char(3); | P24: =TRIM(SUBSTITUTE(MID(K24,1,FIND(":",K24)-1),"key","")) -> documenttype | Q24: =TRIM(MID(K24,FIND(":",K24)+1,LEN(K24))) -> abap.char(3); | AC24: =IF(ISNUMBER(SEARCH("@",H22)),A22,H22&" : "&IF(AD24="",I22,AD24)&";") -> supplytype : abap.char(1); | AD24: ="abap.char("&AE24&")" -> abap.char(1) | AE24: 1
A25: transactiontype : zde_transactiontype; | H25: =TRIM(MID(A25,1,FIND(":",A25)-1)) -> transactiontype | I25: =IF(ISNUMBER(SEARCH("@",A25)),"",TRIM(SUBSTITUTE(SUBSTITUTE(TRIM(MID(A25,FIND(":",A25)+1,LEN(A25))),";",""),"not null",""))) -> zde_transactiontype | K25: transactiontype : abap.char(6); | P25: =TRIM(SUBSTITUTE(MID(K25,1,FIND(":",K25)-1),"key","")) -> transactiontype | Q25: =TRIM(MID(K25,FIND(":",K25)+1,LEN(K25))) -> abap.char(6); | AC25: =IF(ISNUMBER(SEARCH("@",H23)),A23,H23&" : "&IF(AD25="",I23,AD25)&";") -> irn : abap.char(64); | AD25: ="abap.char("&AE25&")" -> abap.char(64) | AE25: 64
A26: dtatransaction : char50; | H26: =TRIM(MID(A26,1,FIND(":",A26)-1)) -> dtatransaction | I26: =IF(ISNUMBER(SEARCH("@",A26)),"",TRIM(SUBSTITUTE(SUBSTITUTE(TRIM(MID(A26,FIND(":",A26)+1,LEN(A26))),";",""),"not null",""))) -> char50 | K26: dtatransaction : char50; | P26: =TRIM(SUBSTITUTE(MID(K26,1,FIND(":",K26)-1),"key","")) -> dtatransaction | Q26: =TRIM(MID(K26,FIND(":",K26)+1,LEN(K26))) -> char50; | AC26: =IF(ISNUMBER(SEARCH("@",H24)),A24,H24&" : "&IF(AD26="",I24,AD26)&";") -> documenttype : abap.char(3); | AD26: ="abap.char("&AE26&")" -> abap.char(3) | AE26: 3
A27: transactiontypedescription : zde_transaction_type_des; | H27: =TRIM(MID(A27,1,FIND(":",A27)-1)) -> transactiontypedescription | I27: =IF(ISNUMBER(SEARCH("@",A27)),"",TRIM(SUBSTITUTE(SUBSTITUTE(TRIM(MID(A27,FIND(":",A27)+1,LEN(A27))),";",""),"not null",""))) -> zde_transaction_type_des | K27: transactiontypedescription : abap.char(30); | P27: =TRIM(SUBSTITUTE(MID(K27,1,FIND(":",K27)-1),"key","")) -> transactiontypedescription | Q27: =TRIM(MID(K27,FIND(":",K27)+1,LEN(K27))) -> abap.char(30); | AC27: =IF(ISNUMBER(SEARCH("@",H25)),A25,H25&" : "&IF(AD27="",I25,AD27)&";") -> transactiontype : abap.char(6); | AD27: ="abap.char("&AE27&")" -> abap.char(6) | AE27: 6
A28: seriescode : zde_seriescode; | H28: =TRIM(MID(A28,1,FIND(":",A28)-1)) -> seriescode | I28: =IF(ISNUMBER(SEARCH("@",A28)),"",TRIM(SUBSTITUTE(SUBSTITUTE(TRIM(MID(A28,FIND(":",A28)+1,LEN(A28))),";",""),"not null",""))) -> zde_seriescode | K28: seriescode : abap.char(15); | P28: =TRIM(SUBSTITUTE(MID(K28,1,FIND(":",K28)-1),"key","")) -> seriescode | Q28: =TRIM(MID(K28,FIND(":",K28)+1,LEN(K28))) -> abap.char(15); | AC28: =IF(ISNUMBER(SEARCH("@",H26)),A26,H26&" : "&IF(AD28="",I26,AD28)&";") -> dtatransaction : char50;
A29: referencedocumentnumber : zde_referencedocumentnumber; | H29: =TRIM(MID(A29,1,FIND(":",A29)-1)) -> referencedocumentnumber | I29: =IF(ISNUMBER(SEARCH("@",A29)),"",TRIM(SUBSTITUTE(SUBSTITUTE(TRIM(MID(A29,FIND(":",A29)+1,LEN(A29))),";",""),"not null",""))) -> zde_referencedocumentnumber | K29: referencedocumentnumber : abap.char(16); | P29: =TRIM(SUBSTITUTE(MID(K29,1,FIND(":",K29)-1),"key","")) -> referencedocumentnumber | Q29: =TRIM(MID(K29,FIND(":",K29)+1,LEN(K29))) -> abap.char(16); | AC29: =IF(ISNUMBER(SEARCH("@",H27)),A27,H27&" : "&IF(AD29="",I27,AD29)&";") -> transactiontypedescription : abap.char(30); | AD29: ="abap.char("&AE29&")" -> abap.char(30) | AE29: 30
A30: referencedocumentdate : zde_referencedocumentdate; | H30: =TRIM(MID(A30,1,FIND(":",A30)-1)) -> referencedocumentdate | I30: =IF(ISNUMBER(SEARCH("@",A30)),"",TRIM(SUBSTITUTE(SUBSTITUTE(TRIM(MID(A30,FIND(":",A30)+1,LEN(A30))),";",""),"not null",""))) -> zde_referencedocumentdate | K30: referencedocumentdate : abap.char(10); | P30: =TRIM(SUBSTITUTE(MID(K30,1,FIND(":",K30)-1),"key","")) -> referencedocumentdate | Q30: =TRIM(MID(K30,FIND(":",K30)+1,LEN(K30))) -> abap.char(10); | AC30: =IF(ISNUMBER(SEARCH("@",H28)),A28,H28&" : "&IF(AD30="",I28,AD30)&";") -> seriescode : abap.char();); | AD30: ="abap.char("&AE30&")" -> abap.char();) | AE30: =TRIM(IF(ISNUMBER(SEARCH("char",Q30)),RIGHT(Q30,2))) -> );
A31: transactionmode : zde_transactionmode; | H31: =TRIM(MID(A31,1,FIND(":",A31)-1)) -> transactionmode | I31: =IF(ISNUMBER(SEARCH("@",A31)),"",TRIM(SUBSTITUTE(SUBSTITUTE(TRIM(MID(A31,FIND(":",A31)+1,LEN(A31))),";",""),"not null",""))) -> zde_transactionmode | K31: transactionmode : abap.char(20); | P31: =TRIM(SUBSTITUTE(MID(K31,1,FIND(":",K31)-1),"key","")) -> transactionmode | Q31: =TRIM(MID(K31,FIND(":",K31)+1,LEN(K31))) -> abap.char(20); | AC31: =IF(ISNUMBER(SEARCH("@",H29)),A29,H29&" : "&IF(AD31="",I29,AD31)&";") -> referencedocumentnumber : abap.char();); | AD31: ="abap.char("&AE31&")" -> abap.char();) | AE31: =TRIM(IF(ISNUMBER(SEARCH("char",Q31)),RIGHT(Q31,2))) -> );
A32: billfromgstin : zde_billfromgstin1; | H32: =TRIM(MID(A32,1,FIND(":",A32)-1)) -> billfromgstin | I32: =IF(ISNUMBER(SEARCH("@",A32)),"",TRIM(SUBSTITUTE(SUBSTITUTE(TRIM(MID(A32,FIND(":",A32)+1,LEN(A32))),";",""),"not null",""))) -> zde_billfromgstin1 | K32: billfromgstin : abap.char(15); | P32: =TRIM(SUBSTITUTE(MID(K32,1,FIND(":",K32)-1),"key","")) -> billfromgstin | Q32: =TRIM(MID(K32,FIND(":",K32)+1,LEN(K32))) -> abap.char(15); | AC32: =IF(ISNUMBER(SEARCH("@",H30)),A30,H30&" : "&IF(AD32="",I30,AD32)&";") -> referencedocumentdate : abap.char();); | AD32: ="abap.char("&AE32&")" -> abap.char();) | AE32: =TRIM(IF(ISNUMBER(SEARCH("char",Q32)),RIGHT(Q32,2))) -> );
A33: billfromlegalname : zde_billfromlegalname; | H33: =TRIM(MID(A33,1,FIND(":",A33)-1)) -> billfromlegalname | I33: =IF(ISNUMBER(SEARCH("@",A33)),"",TRIM(SUBSTITUTE(SUBSTITUTE(TRIM(MID(A33,FIND(":",A33)+1,LEN(A33))),";",""),"not null",""))) -> zde_billfromlegalname | K33: billfromlegalname : abap.char(50); | P33: =TRIM(SUBSTITUTE(MID(K33,1,FIND(":",K33)-1),"key","")) -> billfromlegalname | Q33: =TRIM(MID(K33,FIND(":",K33)+1,LEN(K33))) -> abap.char(50); | AC33: =IF(ISNUMBER(SEARCH("@",H31)),A31,H31&" : "&IF(AD33="",I31,AD33)&";") -> transactionmode : abap.char();); | AD33: ="abap.char("&AE33&")" -> abap.char();) | AE33: =TRIM(IF(ISNUMBER(SEARCH("char",Q33)),RIGHT(Q33,2))) -> );
A34: billfromtradename : zde_billfromtradename; | H34: =TRIM(MID(A34,1,FIND(":",A34)-1)) -> billfromtradename | I34: =IF(ISNUMBER(SEARCH("@",A34)),"",TRIM(SUBSTITUTE(SUBSTITUTE(TRIM(MID(A34,FIND(":",A34)+1,LEN(A34))),";",""),"not null",""))) -> zde_billfromtradename | K34: billfromtradename : abap.char(30); | P34: =TRIM(SUBSTITUTE(MID(K34,1,FIND(":",K34)-1),"key","")) -> billfromtradename | Q34: =TRIM(MID(K34,FIND(":",K34)+1,LEN(K34))) -> abap.char(30); | AC34: =IF(ISNUMBER(SEARCH("@",H32)),A32,H32&" : "&IF(AD34="",I32,AD34)&";") -> billfromgstin : abap.char();); | AD34: ="abap.char("&AE34&")" -> abap.char();) | AE34: =TRIM(IF(ISNUMBER(SEARCH("char",Q34)),RIGHT(Q34,2))) -> );
A35: billfrombuildingno : zde_billfrombuildingno; | H35: =TRIM(MID(A35,1,FIND(":",A35)-1)) -> billfrombuildingno | I35: =IF(ISNUMBER(SEARCH("@",A35)),"",TRIM(SUBSTITUTE(SUBSTITUTE(TRIM(MID(A35,FIND(":",A35)+1,LEN(A35))),";",""),"not null",""))) -> zde_billfrombuildingno | K35: billfrombuildingno : abap.char(60); | P35: =TRIM(SUBSTITUTE(MID(K35,1,FIND(":",K35)-1),"key","")) -> billfrombuildingno | Q35: =TRIM(MID(K35,FIND(":",K35)+1,LEN(K35))) -> abap.char(60); | AC35: =IF(ISNUMBER(SEARCH("@",H33)),A33,H33&" : "&IF(AD35="",I33,AD35)&";") -> billfromlegalname : abap.char();); | AD35: ="abap.char("&AE35&")" -> abap.char();) | AE35: =TRIM(IF(ISNUMBER(SEARCH("char",Q35)),RIGHT(Q35,2))) -> );
A36: billfrombuildingname : zde_billfrombuildingname; | H36: =TRIM(MID(A36,1,FIND(":",A36)-1)) -> billfrombuildingname | I36: =IF(ISNUMBER(SEARCH("@",A36)),"",TRIM(SUBSTITUTE(SUBSTITUTE(TRIM(MID(A36,FIND(":",A36)+1,LEN(A36))),";",""),"not null",""))) -> zde_billfrombuildingname | K36: billfrombuildingname : abap.char(60); | P36: =TRIM(SUBSTITUTE(MID(K36,1,FIND(":",K36)-1),"key","")) -> billfrombuildingname | Q36: =TRIM(MID(K36,FIND(":",K36)+1,LEN(K36))) -> abap.char(60); | AC36: =IF(ISNUMBER(SEARCH("@",H34)),A34,H34&" : "&IF(AD36="",I34,AD36)&";") -> billfromtradename : abap.char();); | AD36: ="abap.char("&AE36&")" -> abap.char();) | AE36: =TRIM(IF(ISNUMBER(SEARCH("char",Q36)),RIGHT(Q36,2))) -> );
A37: billfromflatno : zde_billfromflatno; | H37: =TRIM(MID(A37,1,FIND(":",A37)-1)) -> billfromflatno | I37: =IF(ISNUMBER(SEARCH("@",A37)),"",TRIM(SUBSTITUTE(SUBSTITUTE(TRIM(MID(A37,FIND(":",A37)+1,LEN(A37))),";",""),"not null",""))) -> zde_billfromflatno | K37: billfromflatno : abap.char(10); | P37: =TRIM(SUBSTITUTE(MID(K37,1,FIND(":",K37)-1),"key","")) -> billfromflatno | Q37: =TRIM(MID(K37,FIND(":",K37)+1,LEN(K37))) -> abap.char(10); | AC37: =IF(ISNUMBER(SEARCH("@",H35)),A35,H35&" : "&IF(AD37="",I35,AD37)&";") -> billfrombuildingno : abap.char();); | AD37: ="abap.char("&AE37&")" -> abap.char();) | AE37: =TRIM(IF(ISNUMBER(SEARCH("char",Q37)),RIGHT(Q37,2))) -> );
A38: billfromaddress1 : zde_billfromaddress1; | H38: =TRIM(MID(A38,1,FIND(":",A38)-1)) -> billfromaddress1 | I38: =IF(ISNUMBER(SEARCH("@",A38)),"",TRIM(SUBSTITUTE(SUBSTITUTE(TRIM(MID(A38,FIND(":",A38)+1,LEN(A38))),";",""),"not null",""))) -> zde_billfromaddress1 | K38: billfromaddress1 : abap.char(50); | P38: =TRIM(SUBSTITUTE(MID(K38,1,FIND(":",K38)-1),"key","")) -> billfromaddress1 | Q38: =TRIM(MID(K38,FIND(":",K38)+1,LEN(K38))) -> abap.char(50); | AC38: =IF(ISNUMBER(SEARCH("@",H36)),A36,H36&" : "&IF(AD38="",I36,AD38)&";") -> billfrombuildingname : abap.char();); | AD38: ="abap.char("&AE38&")" -> abap.char();) | AE38: =TRIM(IF(ISNUMBER(SEARCH("char",Q38)),RIGHT(Q38,2))) -> );
A39: billfromaddress2 : zde_billfromaddress2; | H39: =TRIM(MID(A39,1,FIND(":",A39)-1)) -> billfromaddress2 | I39: =IF(ISNUMBER(SEARCH("@",A39)),"",TRIM(SUBSTITUTE(SUBSTITUTE(TRIM(MID(A39,FIND(":",A39)+1,LEN(A39))),";",""),"not null",""))) -> zde_billfromaddress2 | K39: billfromaddress2 : abap.char(50); | P39: =TRIM(SUBSTITUTE(MID(K39,1,FIND(":",K39)-1),"key","")) -> billfromaddress2 | Q39: =TRIM(MID(K39,FIND(":",K39)+1,LEN(K39))) -> abap.char(50); | AC39: =IF(ISNUMBER(SEARCH("@",H37)),A37,H37&" : "&IF(AD39="",I37,AD39)&";") -> billfromflatno : abap.char();); | AD39: ="abap.char("&AE39&")" -> abap.char();) | AE39: =TRIM(IF(ISNUMBER(SEARCH("char",Q39)),RIGHT(Q39,2))) -> );
A40: billfromcity : zde_billfromcity1; | H40: =TRIM(MID(A40,1,FIND(":",A40)-1)) -> billfromcity | I40: =IF(ISNUMBER(SEARCH("@",A40)),"",TRIM(SUBSTITUTE(SUBSTITUTE(TRIM(MID(A40,FIND(":",A40)+1,LEN(A40))),";",""),"not null",""))) -> zde_billfromcity1 | K40: billfromcity : abap.char(60); | P40: =TRIM(SUBSTITUTE(MID(K40,1,FIND(":",K40)-1),"key","")) -> billfromcity | Q40: =TRIM(MID(K40,FIND(":",K40)+1,LEN(K40))) -> abap.char(60); | AC40: =IF(ISNUMBER(SEARCH("@",H38)),A38,H38&" : "&IF(AD40="",I38,AD40)&";") -> billfromaddress1 : abap.char();); | AD40: ="abap.char("&AE40&")" -> abap.char();) | AE40: =TRIM(IF(ISNUMBER(SEARCH("char",Q40)),RIGHT(Q40,2))) -> );
A41: billfromdistrict : zde_billfromdistrict; | H41: =TRIM(MID(A41,1,FIND(":",A41)-1)) -> billfromdistrict | I41: =IF(ISNUMBER(SEARCH("@",A41)),"",TRIM(SUBSTITUTE(SUBSTITUTE(TRIM(MID(A41,FIND(":",A41)+1,LEN(A41))),";",""),"not null",""))) -> zde_billfromdistrict | K41: billfromdistrict : abap.char(60); | P41: =TRIM(SUBSTITUTE(MID(K41,1,FIND(":",K41)-1),"key","")) -> billfromdistrict | Q41: =TRIM(MID(K41,FIND(":",K41)+1,LEN(K41))) -> abap.char(60); | AC41: =IF(ISNUMBER(SEARCH("@",H39)),A39,H39&" : "&IF(AD41="",I39,AD41)&";") -> billfromaddress2 : abap.char();); | AD41: ="abap.char("&AE41&")" -> abap.char();) | AE41: =TRIM(IF(ISNUMBER(SEARCH("char",Q41)),RIGHT(Q41,2))) -> );
... A52: dispatchfromadd2 : zde_dispatch_from_address2; | H52: =TRIM(MID(A52,1,FIND(":",A52)-1)) -> dispatchfromadd2 | I52: =IF(ISNUMBER(SEARCH("@",A52)),"",TRIM(SUBSTITUTE(SUBSTITUTE(TRIM(MID(A52,FIND(":",A52)+1,LEN(A52))),";",""),"not null",""))) -> zde_dispatch_from_address2 | K52: dispatchfromadd2 : abap.char(100); | P52: =TRIM(SUBSTITUTE(MID(K52,1,FIND(":",K52)-1),"key","")) -> dispatchfromadd2 | Q52: =TRIM(MID(K52,FIND(":",K52)+1,LEN(K52))) -> abap.char(100); | AC52: =IF(ISNUMBER(SEARCH("@",H50)),A50,H50&" : "&IF(AD52="",I50,AD52)&";") -> dispatchfromflatnumber : abap.char();); | AD52: ="abap.char("&AE52&")" -> abap.char();) | AE52: =TRIM(IF(ISNUMBER(SEARCH("char",Q52)),RIGHT(Q52,2))) -> );
A53: dispatchfromcity : zde_dispatch_from_city; | H53: =TRIM(MID(A53,1,FIND(":",A53)-1)) -> dispatchfromcity | I53: =IF(ISNUMBER(SEARCH("@",A53)),"",TRIM(SUBSTITUTE(SUBSTITUTE(TRIM(MID(A53,FIND(":",A53)+1,LEN(A53))),";",""),"not null",""))) -> zde_dispatch_from_city | K53: dispatchfromcity : abap.char(50); | P53: =TRIM(SUBSTITUTE(MID(K53,1,FIND(":",K53)-1),"key","")) -> dispatchfromcity | Q53: =TRIM(MID(K53,FIND(":",K53)+1,LEN(K53))) -> abap.char(50); | AC53: =IF(ISNUMBER(SEARCH("@",H51)),A51,H51&" : "&IF(AD53="",I51,AD53)&";") -> dispatchfromadd1 : abap.char(100); | AD53: ="abap.char("&AE53&")" -> abap.char(100) | AE53: 100
A54: dispatchfromdistrict : zde_dis_from_district; | H54: =TRIM(MID(A54,1,FIND(":",A54)-1)) -> dispatchfromdistrict | I54: =IF(ISNUMBER(SEARCH("@",A54)),"",TRIM(SUBSTITUTE(SUBSTITUTE(TRIM(MID(A54,FIND(":",A54)+1,LEN(A54))),";",""),"not null",""))) -> zde_dis_from_district | K54: dispatchfromdistrict : abap.char(60); | P54: =TRIM(SUBSTITUTE(MID(K54,1,FIND(":",K54)-1),"key","")) -> dispatchfromdistrict | Q54: =TRIM(MID(K54,FIND(":",K54)+1,LEN(K54))) -> abap.char(60); | AC54: =IF(ISNUMBER(SEARCH("@",H52)),A52,H52&" : "&IF(AD54="",I52,AD54)&";") -> dispatchfromadd2 : abap.char(100); | AD54: ="abap.char("&AE54&")" -> abap.char(100) | AE54: 100
...

Sheet ZSD_T_EINV_LOG
A2: @EndUserText.label : 'Cygnet E-Invoice Log' | K2: @EndUserText.label : 'Cygnet E-Invoice Log'
A3: @AbapCatalog.enhancement.category : #NOT_EXTENSIBLE | K3: @AbapCatalog.enhancement.category : #NOT_EXTENSIBLE
A4: @AbapCatalog.tableCategory : #TRANSPARENT | K4: @AbapCatalog.tableCategory : #TRANSPARENT
A5: @AbapCatalog.deliveryClass : #A | K5: @AbapCatalog.deliveryClass : #A
A6: @AbapCatalog.dataMaintenance : #ALLOWED | K6: @AbapCatalog.dataMaintenance : #RESTRICTED
A7: define table zsd_t_einv_log { | H7: Field | I7: Data Element | K7: define table zsd_t_einv_log { | P7: Field | Q7: Data Type
A9: key client : mandt not null; | H9: =TRIM(MID(A9,1,FIND(":",A9)-1)) -> key client | I9: =TRIM(SUBSTITUTE(SUBSTITUTE(TRIM(MID(A9,FIND(":",A9)+1,LEN(A9))),";",""),"not null","")) -> mandt | K9: key client : mandt not null; | P9: =TRIM(SUBSTITUTE(MID(K9,1,FIND(":",K9)-1),"key","")) -> client | Q9: =TRIM(MID(K9,FIND(":",K9)+1,LEN(K9))) -> mandt not null;
A10: key document_number : xblnr not null; | H10: =TRIM(MID(A10,1,FIND(":",A10)-1)) -> key document_number | I10: =TRIM(SUBSTITUTE(SUBSTITUTE(TRIM(MID(A10,FIND(":",A10)+1,LEN(A10))),";",""),"not null","")) -> xblnr | K10: key document_number : xblnr not null; | P10: =TRIM(SUBSTITUTE(MID(K10,1,FIND(":",K10)-1),"key","")) -> document_number | Q10: =TRIM(MID(K10,FIND(":",K10)+1,LEN(K10))) -> xblnr not null;
A11: key document_date : zde_document_date not null; | H11: =TRIM(MID(A11,1,FIND(":",A11)-1)) -> key document_date | I11: =TRIM(SUBSTITUTE(SUBSTITUTE(TRIM(MID(A11,FIND(":",A11)+1,LEN(A11))),";",""),"not null","")) -> zde_document_date | K11: key document_date : abap.dats not null; | P11: =TRIM(SUBSTITUTE(MID(K11,1,FIND(":",K11)-1),"key","")) -> document_date | Q11: =TRIM(MID(K11,FIND(":",K11)+1,LEN(K11))) -> abap.dats not null;
A12: key company_code : zde_company_code not null; | H12: =TRIM(MID(A12,1,FIND(":",A12)-1)) -> key company_code | I12: =TRIM(SUBSTITUTE(SUBSTITUTE(TRIM(MID(A12,FIND(":",A12)+1,LEN(A12))),";",""),"not null","")) -> zde_company_code | K12: key company_code : abap.char(4) not null; | P12: =TRIM(SUBSTITUTE(MID(K12,1,FIND(":",K12)-1),"key","")) -> company_code | Q12: =TRIM(MID(K12,FIND(":",K12)+1,LEN(K12))) -> abap.char(4) not null;
A13: fiscal_year : zde_fiscal_year; | H13: =TRIM(MID(A13,1,FIND(":",A13)-1)) -> fiscal_year | I13: =TRIM(SUBSTITUTE(SUBSTITUTE(TRIM(MID(A13,FIND(":",A13)+1,LEN(A13))),";",""),"not null","")) -> zde_fiscal_year | K13: fiscal_year : abap.numc(4); | P13: =TRIM(SUBSTITUTE(MID(K13,1,FIND(":",K13)-1),"key","")) -> fiscal_year | Q13: =TRIM(MID(K13,FIND(":",K13)+1,LEN(K13))) -> abap.numc(4);
A14: location_gstin : zde_location_gstin; | H14: =TRIM(MID(A14,1,FIND(":",A14)-1)) -> location_gstin | I14: =TRIM(SUBSTITUTE(SUBSTITUTE(TRIM(MID(A14,FIND(":",A14)+1,LEN(A14))),";",""),"not null","")) -> zde_location_gstin | K14: location_gstin : abap.char(20); | P14: =TRIM(SUBSTITUTE(MID(K14,1,FIND(":",K14)-1),"key","")) -> location_gstin | Q14: =TRIM(MID(K14,FIND(":",K14)+1,LEN(K14))) -> abap.char(20);
A15: billfromgstin : zde_billfromgstin; | H15: =TRIM(MID(A15,1,FIND(":",A15)-1)) -> billfromgstin | I15: =TRIM(SUBSTITUTE(SUBSTITUTE(TRIM(MID(A15,FIND(":",A15)+1,LEN(A15))),";",""),"not null","")) -> zde_billfromgstin | K15: billfromgstin : abap.char(100); | P15: =TRIM(SUBSTITUTE(MID(K15,1,FIND(":",K15)-1),"key","")) -> billfromgstin | Q15: =TRIM(MID(K15,FIND(":",K15)+1,LEN(K15))) -> abap.char(100);
A16: billfromname : zde_billfromname; | H16: =TRIM(MID(A16,1,FIND(":",A16)-1)) -> billfromname | I16: =TRIM(SUBSTITUTE(SUBSTITUTE(TRIM(MID(A16,FIND(":",A16)+1,LEN(A16))),";",""),"not null","")) -> zde_billfromname | K16: billfromname : abap.char(100); | P16: =TRIM(SUBSTITUTE(MID(K16,1,FIND(":",K16)-1),"key","")) -> billfromname | Q16: =TRIM(MID(K16,FIND(":",K16)+1,LEN(K16))) -> abap.char(100);
A17: billfromadd1 : zde_billfromadd1; | H17: =TRIM(MID(A17,1,FIND(":",A17)-1)) -> billfromadd1 | I17: =TRIM(SUBSTITUTE(SUBSTITUTE(TRIM(MID(A17,FIND(":",A17)+1,LEN(A17))),";",""),"not null","")) -> zde_billfromadd1 | K17: billfromadd1 : abap.char(100); | P17: =TRIM(SUBSTITUTE(MID(K17,1,FIND(":",K17)-1),"key","")) -> billfromadd1 | Q17: =TRIM(MID(K17,FIND(":",K17)+1,LEN(K17))) -> abap.char(100);
A18: billfromadd2 : zde_billfromadd2; | H18: =TRIM(MID(A18,1,FIND(":",A18)-1)) -> billfromadd2 | I18: =TRIM(SUBSTITUTE(SUBSTITUTE(TRIM(MID(A18,FIND(":",A18)+1,LEN(A18))),";",""),"not null","")) -> zde_billfromadd2 | K18: billfromadd2 : abap.char(100); | P18: =TRIM(SUBSTITUTE(MID(K18,1,FIND(":",K18)-1),"key","")) -> billfromadd2 | Q18: =TRIM(MID(K18,FIND(":",K18)+1,LEN(K18))) -> abap.char(100);
A19: billfrompincode : zde_billfrompincode; | H19: =TRIM(MID(A19,1,FIND(":",A19)-1)) -> billfrompincode | I19: =TRIM(SUBSTITUTE(SUBSTITUTE(TRIM(MID(A19,FIND(":",A19)+1,LEN(A19))),";",""),"not null","")) -> zde_billfrompincode | K19: billfrompincode : abap.char(100); | P19: =TRIM(SUBSTITUTE(MID(K19,1,FIND(":",K19)-1),"key","")) -> billfrompincode | Q19: =TRIM(MID(K19,FIND(":",K19)+1,LEN(K19))) -> abap.char(100);
A20: billfromcity : zde_billfromcity; | H20: =TRIM(MID(A20,1,FIND(":",A20)-1)) -> billfromcity | I20: =TRIM(SUBSTITUTE(SUBSTITUTE(TRIM(MID(A20,FIND(":",A20)+1,LEN(A20))),";",""),"not null","")) -> zde_billfromcity | K20: billfromcity : abap.char(100); | P20: =TRIM(SUBSTITUTE(MID(K20,1,FIND(":",K20)-1),"key","")) -> billfromcity | Q20: =TRIM(MID(K20,FIND(":",K20)+1,LEN(K20))) -> abap.char(100);
... A103: local_last_changed_at : abp_locinst_lastchange_tstmpl; | H103: =TRIM(MID(A103,1,FIND(":",A103)-1)) -> local_last_changed_at | I103: =TRIM(SUBSTITUTE(SUBSTITUTE(TRIM(MID(A103,FIND(":",A103)+1,LEN(A103))),";",""),"not null","")) -> abp_locinst_lastchange_tstmpl | K103: local_last_changed_at : abp_locinst_lastchange_tstmpl; | P103: =TRIM(SUBSTITUTE(MID(K103,1,FIND(":",K103)-1),"key","")) -> local_last_changed_at | Q103: =TRIM(MID(K103,FIND(":",K103)+1,LEN(K103))) -> abp_locinst_lastchange_tstmpl;
A105: } | K105: }

Sheet ZSD_T_EINV
B2: @EndUserText.label : 'E-Invoice Table to display data' | I2: Field & Data Element Seprator For Mapping Data Type | L2: @EndUserText.label : 'E-Invoice Table to display data' | R2: Data Types After Corrected | V2: Extracting Data types from Already Created Data Types
B3: @AbapCatalog.enhancement.category : #NOT_EXTENSIBLE | L3: @AbapCatalog.enhancement.category : #NOT_EXTENSIBLE
B4: @AbapCatalog.tableCategory : #TRANSPARENT | L4: @AbapCatalog.tableCategory : #TRANSPARENT
B5: @AbapCatalog.deliveryClass : #A | L5: @AbapCatalog.deliveryClass : #A
B6: @AbapCatalog.dataMaintenance : #RESTRICTED | L6: @AbapCatalog.dataMaintenance : #RESTRICTED
B7: define table zsd_t_einv { | I7: Field | J7: Data Element | L7: define table zsd_t_einv { | R7: Field | S7: Data Type
B9: key mandt : mandt not null; | I9: =TRIM(MID(B9,1,FIND(":",B9)-1)) -> key mandt | J9: =TRIM(SUBSTITUTE(SUBSTITUTE(TRIM(MID(B9,FIND(":",B9)+1,LEN(B9))),";",""),"not null","")) -> mandt | L9: key mandt : mandt not null; | R9: =TRIM(SUBSTITUTE(MID(L9,1,FIND(":",L9)-1),"key","")) -> mandt | S9: =TRIM(MID(L9,FIND(":",L9)+1,LEN(L9))) -> mandt not null; | V9: =IF(OR(ISERROR(W9),W9="--"),B9,IF(ISNUMBER(SEARCH("@",I9)),B9,I9&" : "&IF(W9="",J9,W9))) -> key mandt : mandt not null; | W9: =IFERROR(INDEX('Resolved Data Elem'!$E$4:$E$1070,MATCH(J9,'Resolved Data Elem'!$D$4:$D$1070,0)),"--") -> mandt not null;
B10: key documentnumber : xblnr not null; | I10: =TRIM(MID(B10,1,FIND(":",B10)-1)) -> key documentnumber | J10: =TRIM(SUBSTITUTE(SUBSTITUTE(TRIM(MID(B10,FIND(":",B10)+1,LEN(B10))),";",""),"not null","")) -> xblnr | L10: key documentnumber : xblnr not null; | R10: =TRIM(SUBSTITUTE(MID(L10,1,FIND(":",L10)-1),"key","")) -> documentnumber | S10: =TRIM(MID(L10,FIND(":",L10)+1,LEN(L10))) -> xblnr not null; | V10: =IF(OR(ISERROR(W10),W10="--"),B10,IF(ISNUMBER(SEARCH("@",I10)),B10,I10&" : "&IF(W10="",J10,W10))) -> key documentnumber : xblnr not null; | W10: =IFERROR(INDEX('Resolved Data Elem'!$E$4:$E$1070,MATCH(J10,'Resolved Data Elem'!$D$4:$D$1070,0)),"--") -> xblnr not null;
B11: locationgstin : zde_locationgstin; | I11: =TRIM(MID(B11,1,FIND(":",B11)-1)) -> locationgstin | J11: =TRIM(SUBSTITUTE(SUBSTITUTE(TRIM(MID(B11,FIND(":",B11)+1,LEN(B11))),";",""),"not null","")) -> zde_locationgstin | L11: locationgstin : abap.char(15); | R11: =TRIM(SUBSTITUTE(MID(L11,1,FIND(":",L11)-1),"key","")) -> locationgstin | S11: =TRIM(MID(L11,FIND(":",L11)+1,LEN(L11))) -> abap.char(15); | V11: =IF(OR(ISERROR(W11),W11="--"),B11,IF(ISNUMBER(SEARCH("@",I11)),B11,I11&" : "&IF(W11="",J11,W11))) -> locationgstin : abap.char(15); | W11: =IFERROR(INDEX('Resolved Data Elem'!$E$4:$E$1070,MATCH(J11,'Resolved Data Elem'!$D$4:$D$1070,0)),"--") -> abap.char(15);
B12: documentdate : zde_document_date; | I12: =TRIM(MID(B12,1,FIND(":",B12)-1)) -> documentdate | J12: =TRIM(SUBSTITUTE(SUBSTITUTE(TRIM(MID(B12,FIND(":",B12)+1,LEN(B12))),";",""),"not null","")) -> zde_document_date | L12: documentdate : abap.dats not null; | R12: =TRIM(SUBSTITUTE(MID(L12,1,FIND(":",L12)-1),"key","")) -> documentdate | S12: =TRIM(MID(L12,FIND(":",L12)+1,LEN(L12))) -> abap.dats not null; | V12: =IF(OR(ISERROR(W12),W12="--"),B12,IF(ISNUMBER(SEARCH("@",I12)),B12,I12&" : "&IF(W12="",J12,W12))) -> documentdate : abap.dats not null; | W12: =IFERROR(INDEX('Resolved Data Elem'!$E$4:$E$1070,MATCH(J12,'Resolved Data Elem'!$D$4:$D$1070,0)),"--") -> abap.dats not null;
B13: company_code : zde_company_code; | I13: =TRIM(MID(B13,1,FIND(":",B13)-1)) -> company_code | J13: =TRIM(SUBSTITUTE(SUBSTITUTE(TRIM(MID(B13,FIND(":",B13)+1,LEN(B13))),";",""),"not null","")) -> zde_company_code | L13: company_code : abap.char(4) not null; | R13: =TRIM(SUBSTITUTE(MID(L13,1,FIND(":",L13)-1),"key","")) -> company_code | S13: =TRIM(MID(L13,FIND(":",L13)+1,LEN(L13))) -> abap.char(4) not null; | V13: =IF(OR(ISERROR(W13),W13="--"),B13,IF(ISNUMBER(SEARCH("@",I13)),B13,I13&" : "&IF(W13="",J13,W13))) -> company_code : abap.char(4) not null; | W13: =IFERROR(INDEX('Resolved Data Elem'!$E$4:$E$1070,MATCH(J13,'Resolved Data Elem'!$D$4:$D$1070,0)),"--") -> abap.char(4) not null;
